File: examples/data/rsm_1.xrdml
<?xml version="1.0" encoding="UTF-8"?>
<xrdMeasurements xmlns="http://www.xrdml.com/XRDMeasurement/1.3" xmlns:xsi="http://www.w3.org/2001/XMLSchema-instance" xsi:schemaLocation="http://www.xrdml.com/XRDMeasurement/1.3 http://www.xrdml.com/XRDMeasurement/1.3/XRDMeasurement.xsd" status="Completed">
	<comment>
		<entry>Configuration=Factory configuration, Owner=User-1, Creation date=6/4/2010 10:23:02 AM</entry>
		<entry>Goniometer=PW3050/65 (Theta/2Theta); Minimum step size 2Theta:0.0001; Minimum step size Omega:0.0001</entry>
		<entry>Sample stage=MRD XL Cradle; Minimum step size Phi:0.01; Minimum step size Psi:0.01; Minimum step size X:0.01; Minimum step size Y:0.01; Minimum step size Z:0.001</entry>
		<entry>Diffractometer system=XPERT-PRO</entry>
		<entry>Measurement program=GreenSi_map_2deg2s, Owner=tanja, Creation date=3/19/2012 10:07:21 AM</entry>
		<entry>Fine Calibration Offset for 2Theta = -0.0192 deg</entry>
		<entry>Fine Calibration Offset for Omega = 0.1691 deg</entry>
		<entry>Batch program=Rastelli_XRR_XRD_short_period_sample5, Owner=tanja, Creation date=6/15/2012 3:39:26 PM</entry>
	</comment>
	<sample type="To be analyzed">
		<id></id>
		<name></name>
		<preparedBy></preparedBy>
	</sample>
	<xrdMeasurement measurementType="Area measurement" status="Completed" measurementStepAxis="Omega" sampleMode="Reflection">
		<comment>
			<entry/>
		</comment>
		<usedWavelength intended="K-Alpha 1">
			<kAlpha1 unit="Angstrom">1.5405980</kAlpha1>
			<kAlpha2 unit="Angstrom">1.5444260</kAlpha2>
			<kBeta unit="Angstrom">1.3922500</kBeta>
			<ratioKAlpha2KAlpha1>0.5000</ratioKAlpha2KAlpha1>
		</usedWavelength>
		<incidentBeamPath>
			<radius unit="mm">420.00</radius>
			<xRayTube id="1010048" name="PW3373/10 Cu LFF DK394719">
				<tension unit="kV">45</tension>
				<current unit="mA">40</current>
				<anodeMaterial>Cu</anodeMaterial>
				<focus type="Line">
					<length unit="mm">12.0</length>
					<width unit="mm">0.4</width>
					<takeOffAngle unit="deg">3.7</takeOffAngle>
				</focus>
			</xRayTube>
			<xRayMirror id="27090001" name="Inc. Beam Cu W/Si (hybrid MRD)" hybrid="true">
				<crystal type="Graded" shape="Parabolic">W/Si</crystal>
				<acceptanceAngle unit="deg">0.8</acceptanceAngle>
				<length unit="mm">60.0</length>
			</xRayMirror>
			<monochromator id="23090002" name="Inc. Beam 2xGe220 Cu Asym. (hybrid)" hybrid="true">
				<crystal type="Asymmetric" shape="Flat">Ge</crystal>
				<numberOfReflections>2</numberOfReflections>
				<hkl>
					<h>2</h>
					<k>2</k>
					<l>0</l>
				</hkl>
			</monochromator>
			<divergenceSlit id="22010009" name="Slit Fixed 1/16Â°" xsi:type="fixedDivergenceSlitType">
				<distanceToSample unit="mm">320.00</distanceToSample>
				<height unit="mm">0.10</height>
			</divergenceSlit>
		</incidentBeamPath>
		<sampleOffset>
			<position axis="2Theta" unit="deg">0.0000</position>
			<position axis="Omega" unit="deg">0.0000</position>
		</sampleOffset>
		<diffractedBeamPath>
			<radius unit="mm">420.00</radius>
			<antiScatterSlit id="22090014" name="AS Slit 5.0 mm (PIXcel non-ambient &amp; MRD)" xsi:type="fixedAntiScatterSlitType">
				<height unit="mm">5.00</height>
			</antiScatterSlit>
			<detector id="7010015" name="PIXcel" xsi:type="rtmsDetectorType">
				<phd>
					<lowerLevel unit="%">25.5</lowerLevel>
					<upperLevel unit="%">100.0</upperLevel>
				</phd>
				<mode>Static</mode>
				<activeLength unit="deg">1.9131</activeLength>
			</detector>
		</diffractedBeamPath>
		<measurementStepAxisCenter>
			<position axis="Omega" unit="deg">34.0546</position>
		</measurementStepAxisCenter>
		<scan appendNumber="0" mode="Continuous" scanAxis="2Theta" status="Completed">
			<header>
				<startTimeStamp>2012-06-15T20:41:25+02:00</startTimeStamp>
				<endTimeStamp>2012-06-15T20:41:29+02:00</endTimeStamp>
				<author>
					<name>Johannes Kepler Univ</name>
				</author>
				<source>
					<applicationSoftware version="2.2i">X'Pert Data Collector</applicationSoftware>
					<instrumentControlSoftware version="2.1E">XPERT-PRO</instrumentControlSoftware>
					<instrumentID>0000000011071750</instrumentID>
				</source>
			</header>
			<scanAxisCenter>
				<position axis="2Theta" unit="deg">68.6283</position>
			</scanAxisCenter>
			<dataPoints>
				<positions axis="2Theta" unit="deg">
					<listPositions>67.67550446 67.68300542 67.69050642 67.69800744 67.70550850 67.71300959 67.72051070 67.72801186 67.73551304 67.74301425 67.75051549 67.75801677 67.76551807 67.77301940 67.78052076 67.78802215 67.79552357 67.80302502 67.81052650 67.81802800 67.82552953 67.83303109 67.84053268 67.84803429 67.85553593 67.86303760 67.87053929 67.87804101 67.88554276 67.89304453 67.90054633 67.90804815 67.91554999 67.92305186 67.93055376 67.93805567 67.94555761 67.95305958 67.96056157 67.96806358 67.97556561 67.98306767 67.99056975 67.99807185 68.00557397 68.01307611 68.02057828 68.02808046 68.03558267 68.04308489 68.05058714 68.05808940 68.06559169 68.07309399 68.08059632 68.08809866 68.09560102 68.10310340 68.11060580 68.11810821 68.12561065 68.13311310 68.14061556 68.14811805 68.15562055 68.16312306 68.17062559 68.17812814 68.18563070 68.19313328 68.20063588 68.20813848 68.21564111 68.22314374 68.23064639 68.23814906 68.24565174 68.25315443 68.26065713 68.26815985 68.27566257 68.28316531 68.29066807 68.29817083 68.30567361 68.31317639 68.32067919 68.32818200 68.33568481 68.34318764 68.35069048 68.35819333 68.36569618 68.37319905 68.38070192 68.38820481 68.39570770 68.40321060 68.41071350 68.41821642 68.42571934 68.43322227 68.44072520 68.44822814 68.45573109 68.46323405 68.47073700 68.47823997 68.48574294 68.49324591 68.50074889 68.50825188 68.51575486 68.52325786 68.53076085 68.53826385 68.54576685 68.55326986 68.56077286 68.56827587 68.57577888 68.58328190 68.59078491 68.59828793 68.60579095 68.61329396 68.62079698 68.62830000 68.63580302 68.64330604 68.65080905 68.65831207 68.66581509 68.67331810 68.68082112 68.68832413 68.69582714 68.70333014 68.71083315 68.71833615 68.72583915 68.73334214 68.74084514 68.74834812 68.75585111 68.76335409 68.77085706 68.77836003 68.78586300 68.79336595 68.80086891 68.80837186 68.81587480 68.82337773 68.83088066 68.83838358 68.84588650 68.85338940 68.86089230 68.86839519 68.87589808 68.88340095 68.89090382 68.89840667 68.90590952 68.91341236 68.92091519 68.92841800 68.93592081 68.94342361 68.95092639 68.95842917 68.96593193 68.97343469 68.98093743 68.98844015 68.99594287 69.00344557 69.01094826 69.01845094 69.02595361 69.03345626 69.04095889 69.04846152 69.05596412 69.06346672 69.07096930 69.07847186 69.08597441 69.09347694 69.10097945 69.10848195 69.11598444 69.12348690 69.13098935 69.13849179 69.14599420 69.15349660 69.16099898 69.16850134 69.17600368 69.18350601 69.19100831 69.19851060 69.20601286 69.21351511 69.22101733 69.22851954 69.23602172 69.24352389 69.25102603 69.25852815 69.26603025 69.27353233 69.28103439 69.28853642 69.29603843 69.30354042 69.31104239 69.31854433 69.32604624 69.33354814 69.34105001 69.34855185 69.35605367 69.36355547 69.37105724 69.37855899 69.38606071 69.39356240 69.40106407 69.40856571 69.41606732 69.42356891 69.43107047 69.43857200 69.44607350 69.45357498 69.46107643 69.46857785 69.47607924 69.48358060 69.49108193 69.49858323 69.50608451 69.51358575 69.52108696 69.52858814 69.53608930 69.54359041 69.55109150 69.55859256 69.56609358 69.57359458 69.58109554</listPositions>
				</positions>
				<positions axis="Omega" unit="deg">
					<commonPosition>33.0546</commonPosition>
				</positions>
				<positions axis="Phi" unit="deg">
					<commonPosition>-1.64</commonPosition>
				</positions>
				<positions axis="Psi" unit="deg">
					<commonPosition>0.12</commonPosition>
				</positions>
				<positions axis="X" unit="mm">
					<commonPosition>0.00</commonPosition>
				</positions>
				<positions axis="Y" unit="mm">
					<commonPosition>0.00</commonPosition>
				</positions>
				<positions axis="Z" unit="mm">
					<commonPosition>17.671</commonPosition>
				</positions>
				<commonCountingTime unit="seconds">2.00</commonCountingTime>
				<intensities unit="counts">0 2 1 1 5 2 2 2 0 3 3 1 3 2 1 1 2 2 2 2 1 1 1 1 2 0 3 3 6 7 1 3 3 5 0 2 0 0 0 2 1 2 0 2 2 2 3 5 2 3 2 3 2 3 2 2 3 1 4 2 2 2 1 0 2 1 4 2 1 3 6 3 0 3 3 1 0 1 3 5 5 3 0 1 6 3 1 1 3 4 3 3 4 3 4 4 2 2 2 2 0 2 5 2 5 4 1 3 2 1 2 0 0 3 1 6 3 4 2 2 2 3 2 2 3 1 3 1 0 2 2 5 1 1 1 1 0 2 2 1 1 1 1 1 2 3 2 0 4 2 1 2 0 2 1 1 5 4 2 0 4 0 2 1 0 1 1 0 2 3 1 3 3 3 0 2 0 0 3 0 3 4 4 4 1 0 2 1 3 1 0 4 6 1 1 1 3 1 2 1 0 1 1 1 1 1 4 3 2 0 0 0 0 1 1 0 0 1 2 1 3 1 1 4 0 1 0 0 4 1 1 0 0 2 4 2 1 1 3 2 1 2 1 1 0 0 0 1 2 0 2 1 1 3 2</intensities>
			</dataPoints>
		</scan>
		<scan appendNumber="0" mode="Continuous" scanAxis="2Theta" status="Completed">
			<header>
				<startTimeStamp>2012-06-15T20:41:33+02:00</startTimeStamp>
				<endTimeStamp>2012-06-15T20:41:36+02:00</endTimeStamp>
				<author>
					<name>Johannes Kepler Univ</name>
				</author>
				<source>
					<applicationSoftware version="2.2i">X'Pert Data Collector</applicationSoftware>
					<instrumentControlSoftware version="2.1E">XPERT-PRO</instrumentControlSoftware>
					<instrumentID>0000000011071750</instrumentID>
				</source>
			</header>
			<scanAxisCenter>
				<position axis="2Theta" unit="deg">68.6283</position>
			</scanAxisCenter>
			<dataPoints>
				<positions axis="2Theta" unit="deg">
					<listPositions>67.67550446 67.68300542 67.69050642 67.69800744 67.70550850 67.71300959 67.72051070 67.72801186 67.73551304 67.74301425 67.75051549 67.75801677 67.76551807 67.77301940 67.78052076 67.78802215 67.79552357 67.80302502 67.81052650 67.81802800 67.82552953 67.83303109 67.84053268 67.84803429 67.85553593 67.86303760 67.87053929 67.87804101 67.88554276 67.89304453 67.90054633 67.90804815 67.91554999 67.92305186 67.93055376 67.93805567 67.94555761 67.95305958 67.96056157 67.96806358 67.97556561 67.98306767 67.99056975 67.99807185 68.00557397 68.01307611 68.02057828 68.02808046 68.03558267 68.04308489 68.05058714 68.05808940 68.06559169 68.07309399 68.08059632 68.08809866 68.09560102 68.10310340 68.11060580 68.11810821 68.12561065 68.13311310 68.14061556 68.14811805 68.15562055 68.16312306 68.17062559 68.17812814 68.18563070 68.19313328 68.20063588 68.20813848 68.21564111 68.22314374 68.23064639 68.23814906 68.24565174 68.25315443 68.26065713 68.26815985 68.27566257 68.28316531 68.29066807 68.29817083 68.30567361 68.31317639 68.32067919 68.32818200 68.33568481 68.34318764 68.35069048 68.35819333 68.36569618 68.37319905 68.38070192 68.38820481 68.39570770 68.40321060 68.41071350 68.41821642 68.42571934 68.43322227 68.44072520 68.44822814 68.45573109 68.46323405 68.47073700 68.47823997 68.48574294 68.49324591 68.50074889 68.50825188 68.51575486 68.52325786 68.53076085 68.53826385 68.54576685 68.55326986 68.56077286 68.56827587 68.57577888 68.58328190 68.59078491 68.59828793 68.60579095 68.61329396 68.62079698 68.62830000 68.63580302 68.64330604 68.65080905 68.65831207 68.66581509 68.67331810 68.68082112 68.68832413 68.69582714 68.70333014 68.71083315 68.71833615 68.72583915 68.73334214 68.74084514 68.74834812 68.75585111 68.76335409 68.77085706 68.77836003 68.78586300 68.79336595 68.80086891 68.80837186 68.81587480 68.82337773 68.83088066 68.83838358 68.84588650 68.85338940 68.86089230 68.86839519 68.87589808 68.88340095 68.89090382 68.89840667 68.90590952 68.91341236 68.92091519 68.92841800 68.93592081 68.94342361 68.95092639 68.95842917 68.96593193 68.97343469 68.98093743 68.98844015 68.99594287 69.00344557 69.01094826 69.01845094 69.02595361 69.03345626 69.04095889 69.04846152 69.05596412 69.06346672 69.07096930 69.07847186 69.08597441 69.09347694 69.10097945 69.10848195 69.11598444 69.12348690 69.13098935 69.13849179 69.14599420 69.15349660 69.16099898 69.16850134 69.17600368 69.18350601 69.19100831 69.19851060 69.20601286 69.21351511 69.22101733 69.22851954 69.23602172 69.24352389 69.25102603 69.25852815 69.26603025 69.27353233 69.28103439 69.28853642 69.29603843 69.30354042 69.31104239 69.31854433 69.32604624 69.33354814 69.34105001 69.34855185 69.35605367 69.36355547 69.37105724 69.37855899 69.38606071 69.39356240 69.40106407 69.40856571 69.41606732 69.42356891 69.43107047 69.43857200 69.44607350 69.45357498 69.46107643 69.46857785 69.47607924 69.48358060 69.49108193 69.49858323 69.50608451 69.51358575 69.52108696 69.52858814 69.53608930 69.54359041 69.55109150 69.55859256 69.56609358 69.57359458 69.58109554</listPositions>
				</positions>
				<positions axis="Omega" unit="deg">
					<commonPosition>33.0596</commonPosition>
				</positions>
				<positions axis="Phi" unit="deg">
					<commonPosition>-1.64</commonPosition>
				</positions>
				<positions axis="Psi" unit="deg">
					<commonPosition>0.12</commonPosition>
				</positions>
				<positions axis="X" unit="mm">
					<commonPosition>0.00</commonPosition>
				</positions>
				<positions axis="Y" unit="mm">
					<commonPosition>0.00</commonPosition>
				</positions>
				<positions axis="Z" unit="mm">
					<commonPosition>17.671</commonPosition>
				</positions>
				<commonCountingTime unit="seconds">2.00</commonCountingTime>
				<intensities unit="counts">3 2 1 3 4 2 1 0 2 2 3 2 0 0 1 1 1 2 5 3 2 1 2 1 1 1 6 0 4 2 1 3 5 2 2 0 1 1 1 4 1 1 3 4 3 1 4 3 6 3 5 2 2 3 3 2 3 3 3 3 5 0 2 7 0 0 1 6 0 2 2 3 1 1 4 5 1 1 2 4 1 3 1 2 6 0 0 4 1 1 3 4 4 0 2 2 0 5 3 1 3 2 2 4 1 2 0 3 3 4 4 5 2 2 3 5 2 4 4 2 0 1 0 4 0 4 3 3 3 1 0 1 0 3 2 1 2 1 4 0 3 1 1 3 1 1 5 2 2 3 1 0 1 2 3 1 1 2 2 6 2 5 1 0 0 4 3 1 2 2 2 2 1 4 0 1 1 4 1 0 1 3 3 1 3 4 1 1 0 1 0 1 3 1 0 0 1 2 1 2 2 5 2 1 1 2 2 1 2 1 1 1 0 1 1 2 1 1 2 2 0 2 1 4 1 3 1 0 2 5 2 1 0 2 2 0 0 5 4 3 0 0 1 2 0 3 1 2 1 1 2 1 1 0 4</intensities>
			</dataPoints>
		</scan>
		<scan appendNumber="0" mode="Continuous" scanAxis="2Theta" status="Completed">
			<header>
				<startTimeStamp>2012-06-15T20:41:41+02:00</startTimeStamp>
				<endTimeStamp>2012-06-15T20:41:44+02:00</endTimeStamp>
				<author>
					<name>Johannes Kepler Univ</name>
				</author>
				<source>
					<applicationSoftware version="2.2i">X'Pert Data Collector</applicationSoftware>
					<instrumentControlSoftware version="2.1E">XPERT-PRO</instrumentControlSoftware>
					<instrumentID>0000000011071750</instrumentID>
				</source>
			</header>
			<scanAxisCenter>
				<position axis="2Theta" unit="deg">68.6283</position>
			</scanAxisCenter>
			<dataPoints>
				<positions axis="2Theta" unit="deg">
					<listPositions>67.67550446 67.68300542 67.69050642 67.69800744 67.70550850 67.71300959 67.72051070 67.72801186 67.73551304 67.74301425 67.75051549 67.75801677 67.76551807 67.77301940 67.78052076 67.78802215 67.79552357 67.80302502 67.81052650 67.81802800 67.82552953 67.83303109 67.84053268 67.84803429 67.85553593 67.86303760 67.87053929 67.87804101 67.88554276 67.89304453 67.90054633 67.90804815 67.91554999 67.92305186 67.93055376 67.93805567 67.94555761 67.95305958 67.96056157 67.96806358 67.97556561 67.98306767 67.99056975 67.99807185 68.00557397 68.01307611 68.02057828 68.02808046 68.03558267 68.04308489 68.05058714 68.05808940 68.06559169 68.07309399 68.08059632 68.08809866 68.09560102 68.10310340 68.11060580 68.11810821 68.12561065 68.13311310 68.14061556 68.14811805 68.15562055 68.16312306 68.17062559 68.17812814 68.18563070 68.19313328 68.20063588 68.20813848 68.21564111 68.22314374 68.23064639 68.23814906 68.24565174 68.25315443 68.26065713 68.26815985 68.27566257 68.28316531 68.29066807 68.29817083 68.30567361 68.31317639 68.32067919 68.32818200 68.33568481 68.34318764 68.35069048 68.35819333 68.36569618 68.37319905 68.38070192 68.38820481 68.39570770 68.40321060 68.41071350 68.41821642 68.42571934 68.43322227 68.44072520 68.44822814 68.45573109 68.46323405 68.47073700 68.47823997 68.48574294 68.49324591 68.50074889 68.50825188 68.51575486 68.52325786 68.53076085 68.53826385 68.54576685 68.55326986 68.56077286 68.56827587 68.57577888 68.58328190 68.59078491 68.59828793 68.60579095 68.61329396 68.62079698 68.62830000 68.63580302 68.64330604 68.65080905 68.65831207 68.66581509 68.67331810 68.68082112 68.68832413 68.69582714 68.70333014 68.71083315 68.71833615 68.72583915 68.73334214 68.74084514 68.74834812 68.75585111 68.76335409 68.77085706 68.77836003 68.78586300 68.79336595 68.80086891 68.80837186 68.81587480 68.82337773 68.83088066 68.83838358 68.84588650 68.85338940 68.86089230 68.86839519 68.87589808 68.88340095 68.89090382 68.89840667 68.90590952 68.91341236 68.92091519 68.92841800 68.93592081 68.94342361 68.95092639 68.95842917 68.96593193 68.97343469 68.98093743 68.98844015 68.99594287 69.00344557 69.01094826 69.01845094 69.02595361 69.03345626 69.04095889 69.04846152 69.05596412 69.06346672 69.07096930 69.07847186 69.08597441 69.09347694 69.10097945 69.10848195 69.11598444 69.12348690 69.13098935 69.13849179 69.14599420 69.15349660 69.16099898 69.16850134 69.17600368 69.18350601 69.19100831 69.19851060 69.20601286 69.21351511 69.22101733 69.22851954 69.23602172 69.24352389 69.25102603 69.25852815 69.26603025 69.27353233 69.28103439 69.28853642 69.29603843 69.30354042 69.31104239 69.31854433 69.32604624 69.33354814 69.34105001 69.34855185 69.35605367 69.36355547 69.37105724 69.37855899 69.38606071 69.39356240 69.40106407 69.40856571 69.41606732 69.42356891 69.43107047 69.43857200 69.44607350 69.45357498 69.46107643 69.46857785 69.47607924 69.48358060 69.49108193 69.49858323 69.50608451 69.51358575 69.52108696 69.52858814 69.53608930 69.54359041 69.55109150 69.55859256 69.56609358 69.57359458 69.58109554</listPositions>
				</positions>
				<positions axis="Omega" unit="deg">
					<commonPosition>33.0646</commonPosition>
				</positions>
				<positions axis="Phi" unit="deg">
					<commonPosition>-1.64</commonPosition>
				</positions>
				<positions axis="Psi" unit="deg">
					<commonPosition>0.12</commonPosition>
				</positions>
				<positions axis="X" unit="mm">
					<commonPosition>0.00</commonPosition>
				</positions>
				<positions axis="Y" unit="mm">
					<commonPosition>0.00</commonPosition>
				</positions>
				<positions axis="Z" unit="mm">
					<commonPosition>17.671</commonPosition>
				</positions>
				<commonCountingTime unit="seconds">2.00</commonCountingTime>
				<intensities unit="counts">5 0 0 0 1 2 0 2 1 1 0 1 3 3 2 0 0 2 2 1 1 4 1 1 3 4 2 3 4 0 4 1 2 2 1 1 4 1 2 4 3 3 0 4 0 1 1 1 2 2 1 4 2 5 4 3 3 2 3 1 2 5 2 2 4 4 2 5 2 1 2 5 1 4 2 1 2 1 0 3 2 3 4 2 3 1 1 1 4 3 0 5 2 3 0 2 3 1 5 1 1 1 1 1 2 4 1 3 1 3 2 2 2 2 2 0 2 2 3 3 1 2 0 3 1 2 1 4 1 0 1 3 0 3 1 2 2 4 3 1 1 1 1 4 4 2 0 4 1 1 1 0 4 4 3 7 2 2 5 2 3 2 0 1 2 0 1 4 4 1 2 2 0 3 1 0 0 3 2 1 3 3 2 0 3 3 4 1 1 0 2 1 2 0 2 4 4 2 1 1 1 1 3 0 4 0 2 0 2 3 4 1 3 3 0 1 1 2 3 1 1 3 1 3 0 2 2 3 1 1 2 2 1 2 2 2 0 1 1 1 2 3 4 4 2 1 1 2 0 1 0 2 3 1 0</intensities>
			</dataPoints>
		</scan>
		<scan appendNumber="0" mode="Continuous" scanAxis="2Theta" status="Completed">
			<header>
				<startTimeStamp>2012-06-15T20:41:49+02:00</startTimeStamp>
				<endTimeStamp>2012-06-15T20:41:52+02:00</endTimeStamp>
				<author>
					<name>Johannes Kepler Univ</name>
				</author>
				<source>
					<applicationSoftware version="2.2i">X'Pert Data Collector</applicationSoftware>
					<instrumentControlSoftware version="2.1E">XPERT-PRO</instrumentControlSoftware>
					<instrumentID>0000000011071750</instrumentID>
				</source>
			</header>
			<scanAxisCenter>
				<position axis="2Theta" unit="deg">68.6283</position>
			</scanAxisCenter>
			<dataPoints>
				<positions axis="2Theta" unit="deg">
					<listPositions>67.67550446 67.68300542 67.69050642 67.69800744 67.70550850 67.71300959 67.72051070 67.72801186 67.73551304 67.74301425 67.75051549 67.75801677 67.76551807 67.77301940 67.78052076 67.78802215 67.79552357 67.80302502 67.81052650 67.81802800 67.82552953 67.83303109 67.84053268 67.84803429 67.85553593 67.86303760 67.87053929 67.87804101 67.88554276 67.89304453 67.90054633 67.90804815 67.91554999 67.92305186 67.93055376 67.93805567 67.94555761 67.95305958 67.96056157 67.96806358 67.97556561 67.98306767 67.99056975 67.99807185 68.00557397 68.01307611 68.02057828 68.02808046 68.03558267 68.04308489 68.05058714 68.05808940 68.06559169 68.07309399 68.08059632 68.08809866 68.09560102 68.10310340 68.11060580 68.11810821 68.12561065 68.13311310 68.14061556 68.14811805 68.15562055 68.16312306 68.17062559 68.17812814 68.18563070 68.19313328 68.20063588 68.20813848 68.21564111 68.22314374 68.23064639 68.23814906 68.24565174 68.25315443 68.26065713 68.26815985 68.27566257 68.28316531 68.29066807 68.29817083 68.30567361 68.31317639 68.32067919 68.32818200 68.33568481 68.34318764 68.35069048 68.35819333 68.36569618 68.37319905 68.38070192 68.38820481 68.39570770 68.40321060 68.41071350 68.41821642 68.42571934 68.43322227 68.44072520 68.44822814 68.45573109 68.46323405 68.47073700 68.47823997 68.48574294 68.49324591 68.50074889 68.50825188 68.51575486 68.52325786 68.53076085 68.53826385 68.54576685 68.55326986 68.56077286 68.56827587 68.57577888 68.58328190 68.59078491 68.59828793 68.60579095 68.61329396 68.62079698 68.62830000 68.63580302 68.64330604 68.65080905 68.65831207 68.66581509 68.67331810 68.68082112 68.68832413 68.69582714 68.70333014 68.71083315 68.71833615 68.72583915 68.73334214 68.74084514 68.74834812 68.75585111 68.76335409 68.77085706 68.77836003 68.78586300 68.79336595 68.80086891 68.80837186 68.81587480 68.82337773 68.83088066 68.83838358 68.84588650 68.85338940 68.86089230 68.86839519 68.87589808 68.88340095 68.89090382 68.89840667 68.90590952 68.91341236 68.92091519 68.92841800 68.93592081 68.94342361 68.95092639 68.95842917 68.96593193 68.97343469 68.98093743 68.98844015 68.99594287 69.00344557 69.01094826 69.01845094 69.02595361 69.03345626 69.04095889 69.04846152 69.05596412 69.06346672 69.07096930 69.07847186 69.08597441 69.09347694 69.10097945 69.10848195 69.11598444 69.12348690 69.13098935 69.13849179 69.14599420 69.15349660 69.16099898 69.16850134 69.17600368 69.18350601 69.19100831 69.19851060 69.20601286 69.21351511 69.22101733 69.22851954 69.23602172 69.24352389 69.25102603 69.25852815 69.26603025 69.27353233 69.28103439 69.28853642 69.29603843 69.30354042 69.31104239 69.31854433 69.32604624 69.33354814 69.34105001 69.34855185 69.35605367 69.36355547 69.37105724 69.37855899 69.38606071 69.39356240 69.40106407 69.40856571 69.41606732 69.42356891 69.43107047 69.43857200 69.44607350 69.45357498 69.46107643 69.46857785 69.47607924 69.48358060 69.49108193 69.49858323 69.50608451 69.51358575 69.52108696 69.52858814 69.53608930 69.54359041 69.55109150 69.55859256 69.56609358 69.57359458 69.58109554</listPositions>
				</positions>
				<positions axis="Omega" unit="deg">
					<commonPosition>33.0696</commonPosition>
				</positions>
				<positions axis="Phi" unit="deg">
					<commonPosition>-1.64</commonPosition>
				</positions>
				<positions axis="Psi" unit="deg">
					<commonPosition>0.12</commonPosition>
				</positions>
				<positions axis="X" unit="mm">
					<commonPosition>0.00</commonPosition>
				</positions>
				<positions axis="Y" unit="mm">
					<commonPosition>0.00</commonPosition>
				</positions>
				<positions axis="Z" unit="mm">
					<commonPosition>17.671</commonPosition>
				</positions>
				<commonCountingTime unit="seconds">2.00</commonCountingTime>
				<intensities unit="counts">1 1 2 3 4 3 0 1 0 0 1 1 0 2 1 2 3 2 1 2 3 0 2 1 0 2 5 2 3 1 1 1 1 3 1 1 2 1 3 2 1 1 0 4 3 2 5 3 4 5 1 2 2 7 6 2 2 2 2 1 1 2 4 3 6 4 1 3 3 1 0 4 4 4 3 3 1 3 4 1 4 1 1 5 3 3 5 1 0 1 1 0 5 0 2 1 2 1 2 0 2 5 0 5 4 4 3 1 1 3 2 0 2 0 2 7 1 3 4 1 1 3 2 2 2 0 2 1 4 4 3 4 2 2 0 1 1 1 2 3 3 4 2 5 2 1 2 1 2 4 3 0 3 1 3 2 2 6 0 2 3 1 3 2 4 3 0 1 6 2 4 2 3 1 4 4 5 6 0 2 4 0 3 2 4 1 2 2 0 1 1 4 3 4 1 1 0 0 3 2 3 2 2 5 2 1 6 2 2 3 2 0 0 3 2 1 2 0 2 3 1 1 2 0 1 0 1 1 0 1 1 1 3 0 2 1 0 0 1 4 1 1 0 0 3 0 0 0 5 2 3 1 2 4 3</intensities>
			</dataPoints>
		</scan>
		<scan appendNumber="0" mode="Continuous" scanAxis="2Theta" status="Completed">
			<header>
				<startTimeStamp>2012-06-15T20:41:56+02:00</startTimeStamp>
				<endTimeStamp>2012-06-15T20:42:00+02:00</endTimeStamp>
				<author>
					<name>Johannes Kepler Univ</name>
				</author>
				<source>
					<applicationSoftware version="2.2i">X'Pert Data Collector</applicationSoftware>
					<instrumentControlSoftware version="2.1E">XPERT-PRO</instrumentControlSoftware>
					<instrumentID>0000000011071750</instrumentID>
				</source>
			</header>
			<scanAxisCenter>
				<position axis="2Theta" unit="deg">68.6283</position>
			</scanAxisCenter>
			<dataPoints>
				<positions axis="2Theta" unit="deg">
					<listPositions>67.67550446 67.68300542 67.69050642 67.69800744 67.70550850 67.71300959 67.72051070 67.72801186 67.73551304 67.74301425 67.75051549 67.75801677 67.76551807 67.77301940 67.78052076 67.78802215 67.79552357 67.80302502 67.81052650 67.81802800 67.82552953 67.83303109 67.84053268 67.84803429 67.85553593 67.86303760 67.87053929 67.87804101 67.88554276 67.89304453 67.90054633 67.90804815 67.91554999 67.92305186 67.93055376 67.93805567 67.94555761 67.95305958 67.96056157 67.96806358 67.97556561 67.98306767 67.99056975 67.99807185 68.00557397 68.01307611 68.02057828 68.02808046 68.03558267 68.04308489 68.05058714 68.05808940 68.06559169 68.07309399 68.08059632 68.08809866 68.09560102 68.10310340 68.11060580 68.11810821 68.12561065 68.13311310 68.14061556 68.14811805 68.15562055 68.16312306 68.17062559 68.17812814 68.18563070 68.19313328 68.20063588 68.20813848 68.21564111 68.22314374 68.23064639 68.23814906 68.24565174 68.25315443 68.26065713 68.26815985 68.27566257 68.28316531 68.29066807 68.29817083 68.30567361 68.31317639 68.32067919 68.32818200 68.33568481 68.34318764 68.35069048 68.35819333 68.36569618 68.37319905 68.38070192 68.38820481 68.39570770 68.40321060 68.41071350 68.41821642 68.42571934 68.43322227 68.44072520 68.44822814 68.45573109 68.46323405 68.47073700 68.47823997 68.48574294 68.49324591 68.50074889 68.50825188 68.51575486 68.52325786 68.53076085 68.53826385 68.54576685 68.55326986 68.56077286 68.56827587 68.57577888 68.58328190 68.59078491 68.59828793 68.60579095 68.61329396 68.62079698 68.62830000 68.63580302 68.64330604 68.65080905 68.65831207 68.66581509 68.67331810 68.68082112 68.68832413 68.69582714 68.70333014 68.71083315 68.71833615 68.72583915 68.73334214 68.74084514 68.74834812 68.75585111 68.76335409 68.77085706 68.77836003 68.78586300 68.79336595 68.80086891 68.80837186 68.81587480 68.82337773 68.83088066 68.83838358 68.84588650 68.85338940 68.86089230 68.86839519 68.87589808 68.88340095 68.89090382 68.89840667 68.90590952 68.91341236 68.92091519 68.92841800 68.93592081 68.94342361 68.95092639 68.95842917 68.96593193 68.97343469 68.98093743 68.98844015 68.99594287 69.00344557 69.01094826 69.01845094 69.02595361 69.03345626 69.04095889 69.04846152 69.05596412 69.06346672 69.07096930 69.07847186 69.08597441 69.09347694 69.10097945 69.10848195 69.11598444 69.12348690 69.13098935 69.13849179 69.14599420 69.15349660 69.16099898 69.16850134 69.17600368 69.18350601 69.19100831 69.19851060 69.20601286 69.21351511 69.22101733 69.22851954 69.23602172 69.24352389 69.25102603 69.25852815 69.26603025 69.27353233 69.28103439 69.28853642 69.29603843 69.30354042 69.31104239 69.31854433 69.32604624 69.33354814 69.34105001 69.34855185 69.35605367 69.36355547 69.37105724 69.37855899 69.38606071 69.39356240 69.40106407 69.40856571 69.41606732 69.42356891 69.43107047 69.43857200 69.44607350 69.45357498 69.46107643 69.46857785 69.47607924 69.48358060 69.49108193 69.49858323 69.50608451 69.51358575 69.52108696 69.52858814 69.53608930 69.54359041 69.55109150 69.55859256 69.56609358 69.57359458 69.58109554</listPositions>
				</positions>
				<positions axis="Omega" unit="deg">
					<commonPosition>33.0746</commonPosition>
				</positions>
				<positions axis="Phi" unit="deg">
					<commonPosition>-1.64</commonPosition>
				</positions>
				<positions axis="Psi" unit="deg">
					<commonPosition>0.12</commonPosition>
				</positions>
				<positions axis="X" unit="mm">
					<commonPosition>0.00</commonPosition>
				</positions>
				<positions axis="Y" unit="mm">
					<commonPosition>0.00</commonPosition>
				</positions>
				<positions axis="Z" unit="mm">
					<commonPosition>17.671</commonPosition>
				</positions>
				<commonCountingTime unit="seconds">2.00</commonCountingTime>
				<intensities unit="counts">3 1 1 2 4 2 1 4 4 4 1 3 1 0 5 0 1 0 0 4 1 3 3 2 0 2 0 3 3 4 0 1 1 3 0 1 2 1 1 6 3 4 1 2 0 4 2 5 2 1 3 4 2 3 5 1 3 1 3 3 2 3 0 1 1 2 2 1 3 3 2 2 2 2 3 2 3 5 1 0 3 2 1 3 5 0 1 2 2 3 3 3 2 3 2 1 1 2 4 3 0 1 3 2 1 6 3 3 2 3 4 2 2 2 1 1 3 1 2 5 2 1 4 2 5 4 3 3 2 2 10 6 0 1 1 1 2 5 4 2 2 1 2 2 0 1 2 3 6 3 3 4 1 3 1 2 2 1 2 1 8 2 2 3 2 0 3 2 3 1 0 1 0 0 2 0 1 2 2 0 0 3 3 1 0 5 3 2 3 1 5 0 4 1 4 1 1 2 0 4 3 2 1 0 0 1 0 2 2 4 1 2 4 3 2 5 0 0 1 2 4 2 2 2 3 1 2 2 2 1 1 0 2 1 3 1 1 2 1 2 1 1 5 0 3 3 3 4 2 2 2 2 2 0 1</intensities>
			</dataPoints>
		</scan>
		<scan appendNumber="0" mode="Continuous" scanAxis="2Theta" status="Completed">
			<header>
				<startTimeStamp>2012-06-15T20:42:04+02:00</startTimeStamp>
				<endTimeStamp>2012-06-15T20:42:08+02:00</endTimeStamp>
				<author>
					<name>Johannes Kepler Univ</name>
				</author>
				<source>
					<applicationSoftware version="2.2i">X'Pert Data Collector</applicationSoftware>
					<instrumentControlSoftware version="2.1E">XPERT-PRO</instrumentControlSoftware>
					<instrumentID>0000000011071750</instrumentID>
				</source>
			</header>
			<scanAxisCenter>
				<position axis="2Theta" unit="deg">68.6283</position>
			</scanAxisCenter>
			<dataPoints>
				<positions axis="2Theta" unit="deg">
					<listPositions>67.67550446 67.68300542 67.69050642 67.69800744 67.70550850 67.71300959 67.72051070 67.72801186 67.73551304 67.74301425 67.75051549 67.75801677 67.76551807 67.77301940 67.78052076 67.78802215 67.79552357 67.80302502 67.81052650 67.81802800 67.82552953 67.83303109 67.84053268 67.84803429 67.85553593 67.86303760 67.87053929 67.87804101 67.88554276 67.89304453 67.90054633 67.90804815 67.91554999 67.92305186 67.93055376 67.93805567 67.94555761 67.95305958 67.96056157 67.96806358 67.97556561 67.98306767 67.99056975 67.99807185 68.00557397 68.01307611 68.02057828 68.02808046 68.03558267 68.04308489 68.05058714 68.05808940 68.06559169 68.07309399 68.08059632 68.08809866 68.09560102 68.10310340 68.11060580 68.11810821 68.12561065 68.13311310 68.14061556 68.14811805 68.15562055 68.16312306 68.17062559 68.17812814 68.18563070 68.19313328 68.20063588 68.20813848 68.21564111 68.22314374 68.23064639 68.23814906 68.24565174 68.25315443 68.26065713 68.26815985 68.27566257 68.28316531 68.29066807 68.29817083 68.30567361 68.31317639 68.32067919 68.32818200 68.33568481 68.34318764 68.35069048 68.35819333 68.36569618 68.37319905 68.38070192 68.38820481 68.39570770 68.40321060 68.41071350 68.41821642 68.42571934 68.43322227 68.44072520 68.44822814 68.45573109 68.46323405 68.47073700 68.47823997 68.48574294 68.49324591 68.50074889 68.50825188 68.51575486 68.52325786 68.53076085 68.53826385 68.54576685 68.55326986 68.56077286 68.56827587 68.57577888 68.58328190 68.59078491 68.59828793 68.60579095 68.61329396 68.62079698 68.62830000 68.63580302 68.64330604 68.65080905 68.65831207 68.66581509 68.67331810 68.68082112 68.68832413 68.69582714 68.70333014 68.71083315 68.71833615 68.72583915 68.73334214 68.74084514 68.74834812 68.75585111 68.76335409 68.77085706 68.77836003 68.78586300 68.79336595 68.80086891 68.80837186 68.81587480 68.82337773 68.83088066 68.83838358 68.84588650 68.85338940 68.86089230 68.86839519 68.87589808 68.88340095 68.89090382 68.89840667 68.90590952 68.91341236 68.92091519 68.92841800 68.93592081 68.94342361 68.95092639 68.95842917 68.96593193 68.97343469 68.98093743 68.98844015 68.99594287 69.00344557 69.01094826 69.01845094 69.02595361 69.03345626 69.04095889 69.04846152 69.05596412 69.06346672 69.07096930 69.07847186 69.08597441 69.09347694 69.10097945 69.10848195 69.11598444 69.12348690 69.13098935 69.13849179 69.14599420 69.15349660 69.16099898 69.16850134 69.17600368 69.18350601 69.19100831 69.19851060 69.20601286 69.21351511 69.22101733 69.22851954 69.23602172 69.24352389 69.25102603 69.25852815 69.26603025 69.27353233 69.28103439 69.28853642 69.29603843 69.30354042 69.31104239 69.31854433 69.32604624 69.33354814 69.34105001 69.34855185 69.35605367 69.36355547 69.37105724 69.37855899 69.38606071 69.39356240 69.40106407 69.40856571 69.41606732 69.42356891 69.43107047 69.43857200 69.44607350 69.45357498 69.46107643 69.46857785 69.47607924 69.48358060 69.49108193 69.49858323 69.50608451 69.51358575 69.52108696 69.52858814 69.53608930 69.54359041 69.55109150 69.55859256 69.56609358 69.57359458 69.58109554</listPositions>
				</positions>
				<positions axis="Omega" unit="deg">
					<commonPosition>33.0796</commonPosition>
				</positions>
				<positions axis="Phi" unit="deg">
					<commonPosition>-1.64</commonPosition>
				</positions>
				<positions axis="Psi" unit="deg">
					<commonPosition>0.12</commonPosition>
				</positions>
				<positions axis="X" unit="mm">
					<commonPosition>0.00</commonPosition>
				</positions>
				<positions axis="Y" unit="mm">
					<commonPosition>0.00</commonPosition>
				</positions>
				<positions axis="Z" unit="mm">
					<commonPosition>17.671</commonPosition>
				</positions>
				<commonCountingTime unit="seconds">2.00</commonCountingTime>
				<intensities unit="counts">4 2 0 0 1 1 2 2 1 2 1 2 8 4 4 5 1 0 1 3 4 2 1 3 3 1 1 3 2 5 2 1 4 2 2 1 1 2 2 0 2 1 1 1 1 1 4 0 4 1 3 1 1 4 3 1 0 4 3 2 2 0 4 3 3 5 4 1 4 2 2 2 6 3 0 3 6 0 3 3 2 1 3 0 3 3 2 1 2 0 2 5 1 3 1 3 1 2 1 3 2 2 3 5 3 3 3 3 4 1 6 0 2 1 6 4 3 2 2 1 2 4 4 4 8 2 2 2 0 1 2 0 2 1 4 4 1 2 3 1 2 1 2 1 5 3 2 5 2 3 1 3 2 0 1 2 2 2 2 2 4 1 2 4 2 2 3 1 1 4 2 2 2 1 0 3 3 2 0 2 0 1 1 1 0 3 2 2 4 2 4 1 0 1 1 2 0 2 1 3 5 1 1 1 2 0 0 0 3 1 3 2 0 0 3 1 1 1 0 3 0 1 2 2 3 1 0 2 2 1 0 2 1 2 1 3 0 0 2 1 1 3 0 2 0 1 0 1 1 2 4 2 2 4 1</intensities>
			</dataPoints>
		</scan>
		<scan appendNumber="0" mode="Continuous" scanAxis="2Theta" status="Completed">
			<header>
				<startTimeStamp>2012-06-15T20:42:12+02:00</startTimeStamp>
				<endTimeStamp>2012-06-15T20:42:16+02:00</endTimeStamp>
				<author>
					<name>Johannes Kepler Univ</name>
				</author>
				<source>
					<applicationSoftware version="2.2i">X'Pert Data Collector</applicationSoftware>
					<instrumentControlSoftware version="2.1E">XPERT-PRO</instrumentControlSoftware>
					<instrumentID>0000000011071750</instrumentID>
				</source>
			</header>
			<scanAxisCenter>
				<position axis="2Theta" unit="deg">68.6283</position>
			</scanAxisCenter>
			<dataPoints>
				<positions axis="2Theta" unit="deg">
					<listPositions>67.67550446 67.68300542 67.69050642 67.69800744 67.70550850 67.71300959 67.72051070 67.72801186 67.73551304 67.74301425 67.75051549 67.75801677 67.76551807 67.77301940 67.78052076 67.78802215 67.79552357 67.80302502 67.81052650 67.81802800 67.82552953 67.83303109 67.84053268 67.84803429 67.85553593 67.86303760 67.87053929 67.87804101 67.88554276 67.89304453 67.90054633 67.90804815 67.91554999 67.92305186 67.93055376 67.93805567 67.94555761 67.95305958 67.96056157 67.96806358 67.97556561 67.98306767 67.99056975 67.99807185 68.00557397 68.01307611 68.02057828 68.02808046 68.03558267 68.04308489 68.05058714 68.05808940 68.06559169 68.07309399 68.08059632 68.08809866 68.09560102 68.10310340 68.11060580 68.11810821 68.12561065 68.13311310 68.14061556 68.14811805 68.15562055 68.16312306 68.17062559 68.17812814 68.18563070 68.19313328 68.20063588 68.20813848 68.21564111 68.22314374 68.23064639 68.23814906 68.24565174 68.25315443 68.26065713 68.26815985 68.27566257 68.28316531 68.29066807 68.29817083 68.30567361 68.31317639 68.32067919 68.32818200 68.33568481 68.34318764 68.35069048 68.35819333 68.36569618 68.37319905 68.38070192 68.38820481 68.39570770 68.40321060 68.41071350 68.41821642 68.42571934 68.43322227 68.44072520 68.44822814 68.45573109 68.46323405 68.47073700 68.47823997 68.48574294 68.49324591 68.50074889 68.50825188 68.51575486 68.52325786 68.53076085 68.53826385 68.54576685 68.55326986 68.56077286 68.56827587 68.57577888 68.58328190 68.59078491 68.59828793 68.60579095 68.61329396 68.62079698 68.62830000 68.63580302 68.64330604 68.65080905 68.65831207 68.66581509 68.67331810 68.68082112 68.68832413 68.69582714 68.70333014 68.71083315 68.71833615 68.72583915 68.73334214 68.74084514 68.74834812 68.75585111 68.76335409 68.77085706 68.77836003 68.78586300 68.79336595 68.80086891 68.80837186 68.81587480 68.82337773 68.83088066 68.83838358 68.84588650 68.85338940 68.86089230 68.86839519 68.87589808 68.88340095 68.89090382 68.89840667 68.90590952 68.91341236 68.92091519 68.92841800 68.93592081 68.94342361 68.95092639 68.95842917 68.96593193 68.97343469 68.98093743 68.98844015 68.99594287 69.00344557 69.01094826 69.01845094 69.02595361 69.03345626 69.04095889 69.04846152 69.05596412 69.06346672 69.07096930 69.07847186 69.08597441 69.09347694 69.10097945 69.10848195 69.11598444 69.12348690 69.13098935 69.13849179 69.14599420 69.15349660 69.16099898 69.16850134 69.17600368 69.18350601 69.19100831 69.19851060 69.20601286 69.21351511 69.22101733 69.22851954 69.23602172 69.24352389 69.25102603 69.25852815 69.26603025 69.27353233 69.28103439 69.28853642 69.29603843 69.30354042 69.31104239 69.31854433 69.32604624 69.33354814 69.34105001 69.34855185 69.35605367 69.36355547 69.37105724 69.37855899 69.38606071 69.39356240 69.40106407 69.40856571 69.41606732 69.42356891 69.43107047 69.43857200 69.44607350 69.45357498 69.46107643 69.46857785 69.47607924 69.48358060 69.49108193 69.49858323 69.50608451 69.51358575 69.52108696 69.52858814 69.53608930 69.54359041 69.55109150 69.55859256 69.56609358 69.57359458 69.58109554</listPositions>
				</positions>
				<positions axis="Omega" unit="deg">
					<commonPosition>33.0846</commonPosition>
				</positions>
				<positions axis="Phi" unit="deg">
					<commonPosition>-1.64</commonPosition>
				</positions>
				<positions axis="Psi" unit="deg">
					<commonPosition>0.12</commonPosition>
				</positions>
				<positions axis="X" unit="mm">
					<commonPosition>0.00</commonPosition>
				</positions>
				<positions axis="Y" unit="mm">
					<commonPosition>0.00</commonPosition>
				</positions>
				<positions axis="Z" unit="mm">
					<commonPosition>17.671</commonPosition>
				</positions>
				<commonCountingTime unit="seconds">2.00</commonCountingTime>
				<intensities unit="counts">0 0 1 2 1 2 1 2 1 3 0 0 2 1 2 2 3 2 1 2 2 2 0 4 4 0 2 2 1 5 0 1 2 2 3 0 4 0 6 4 4 7 3 3 2 2 1 4 0 2 8 2 2 0 1 2 1 3 1 0 4 2 2 0 3 4 4 2 1 4 2 1 2 1 1 3 3 2 1 2 2 6 5 4 3 1 3 5 1 1 1 2 1 0 4 5 3 1 1 1 1 4 3 3 1 2 2 3 5 4 4 3 1 3 3 3 1 3 3 2 3 1 2 4 1 4 2 3 2 5 4 2 2 2 5 4 1 4 2 2 1 2 0 1 3 1 4 2 1 1 1 2 4 2 2 3 3 1 1 3 3 1 3 2 0 2 0 4 2 0 1 1 1 0 2 0 0 2 3 3 0 0 2 3 1 3 1 1 2 1 4 3 2 4 2 4 2 1 0 1 3 3 1 2 1 3 1 1 1 0 1 3 3 0 0 1 1 1 1 1 4 3 2 0 1 2 1 2 2 1 2 3 3 0 1 1 2 2 2 0 2 0 1 1 3 5 2 2 0 1 2 2 1 2 2</intensities>
			</dataPoints>
		</scan>
		<scan appendNumber="0" mode="Continuous" scanAxis="2Theta" status="Completed">
			<header>
				<startTimeStamp>2012-06-15T20:42:20+02:00</startTimeStamp>
				<endTimeStamp>2012-06-15T20:42:23+02:00</endTimeStamp>
				<author>
					<name>Johannes Kepler Univ</name>
				</author>
				<source>
					<applicationSoftware version="2.2i">X'Pert Data Collector</applicationSoftware>
					<instrumentControlSoftware version="2.1E">XPERT-PRO</instrumentControlSoftware>
					<instrumentID>0000000011071750</instrumentID>
				</source>
			</header>
			<scanAxisCenter>
				<position axis="2Theta" unit="deg">68.6283</position>
			</scanAxisCenter>
			<dataPoints>
				<positions axis="2Theta" unit="deg">
[...]
					<name>Johannes Kepler Univ</name>
				</author>
				<source>
					<applicationSoftware version="2.2i">X'Pert Data Collector</applicationSoftware>
					<instrumentControlSoftware version="2.1E">XPERT-PRO</instrumentControlSoftware>
					<instrumentID>0000000011071750</instrumentID>
				</source>
			</header>
			<scanAxisCenter>
				<position axis="2Theta" unit="deg">68.6283</position>
			</scanAxisCenter>
			<dataPoints>
				<positions axis="2Theta" unit="deg">
					<listPositions>67.67550446 67.68300542 67.69050642 67.69800744 67.70550850 67.71300959 67.72051070 67.72801186 67.73551304 67.74301425 67.75051549 67.75801677 67.76551807 67.77301940 67.78052076 67.78802215 67.79552357 67.80302502 67.81052650 67.81802800 67.82552953 67.83303109 67.84053268 67.84803429 67.85553593 67.86303760 67.87053929 67.87804101 67.88554276 67.89304453 67.90054633 67.90804815 67.91554999 67.92305186 67.93055376 67.93805567 67.94555761 67.95305958 67.96056157 67.96806358 67.97556561 67.98306767 67.99056975 67.99807185 68.00557397 68.01307611 68.02057828 68.02808046 68.03558267 68.04308489 68.05058714 68.05808940 68.06559169 68.07309399 68.08059632 68.08809866 68.09560102 68.10310340 68.11060580 68.11810821 68.12561065 68.13311310 68.14061556 68.14811805 68.15562055 68.16312306 68.17062559 68.17812814 68.18563070 68.19313328 68.20063588 68.20813848 68.21564111 68.22314374 68.23064639 68.23814906 68.24565174 68.25315443 68.26065713 68.26815985 68.27566257 68.28316531 68.29066807 68.29817083 68.30567361 68.31317639 68.32067919 68.32818200 68.33568481 68.34318764 68.35069048 68.35819333 68.36569618 68.37319905 68.38070192 68.38820481 68.39570770 68.40321060 68.41071350 68.41821642 68.42571934 68.43322227 68.44072520 68.44822814 68.45573109 68.46323405 68.47073700 68.47823997 68.48574294 68.49324591 68.50074889 68.50825188 68.51575486 68.52325786 68.53076085 68.53826385 68.54576685 68.55326986 68.56077286 68.56827587 68.57577888 68.58328190 68.59078491 68.59828793 68.60579095 68.61329396 68.62079698 68.62830000 68.63580302 68.64330604 68.65080905 68.65831207 68.66581509 68.67331810 68.68082112 68.68832413 68.69582714 68.70333014 68.71083315 68.71833615 68.72583915 68.73334214 68.74084514 68.74834812 68.75585111 68.76335409 68.77085706 68.77836003 68.78586300 68.79336595 68.80086891 68.80837186 68.81587480 68.82337773 68.83088066 68.83838358 68.84588650 68.85338940 68.86089230 68.86839519 68.87589808 68.88340095 68.89090382 68.89840667 68.90590952 68.91341236 68.92091519 68.92841800 68.93592081 68.94342361 68.95092639 68.95842917 68.96593193 68.97343469 68.98093743 68.98844015 68.99594287 69.00344557 69.01094826 69.01845094 69.02595361 69.03345626 69.04095889 69.04846152 69.05596412 69.06346672 69.07096930 69.07847186 69.08597441 69.09347694 69.10097945 69.10848195 69.11598444 69.12348690 69.13098935 69.13849179 69.14599420 69.15349660 69.16099898 69.16850134 69.17600368 69.18350601 69.19100831 69.19851060 69.20601286 69.21351511 69.22101733 69.22851954 69.23602172 69.24352389 69.25102603 69.25852815 69.26603025 69.27353233 69.28103439 69.28853642 69.29603843 69.30354042 69.31104239 69.31854433 69.32604624 69.33354814 69.34105001 69.34855185 69.35605367 69.36355547 69.37105724 69.37855899 69.38606071 69.39356240 69.40106407 69.40856571 69.41606732 69.42356891 69.43107047 69.43857200 69.44607350 69.45357498 69.46107643 69.46857785 69.47607924 69.48358060 69.49108193 69.49858323 69.50608451 69.51358575 69.52108696 69.52858814 69.53608930 69.54359041 69.55109150 69.55859256 69.56609358 69.57359458 69.58109554</listPositions>
				</positions>
				<positions axis="Omega" unit="deg">
					<commonPosition>35.0396</commonPosition>
				</positions>
				<positions axis="Phi" unit="deg">
					<commonPosition>-1.64</commonPosition>
				</positions>
				<positions axis="Psi" unit="deg">
					<commonPosition>0.12</commonPosition>
				</positions>
				<positions axis="X" unit="mm">
					<commonPosition>0.00</commonPosition>
				</positions>
				<positions axis="Y" unit="mm">
					<commonPosition>0.00</commonPosition>
				</positions>
				<positions axis="Z" unit="mm">
					<commonPosition>17.671</commonPosition>
				</positions>
				<commonCountingTime unit="seconds">2.00</commonCountingTime>
				<intensities unit="counts">1 1 0 0 2 2 4 3 2 1 0 0 0 1 2 1 0 2 2 0 2 2 0 5 2 2 2 2 1 2 1 0 2 1 0 0 2 1 0 1 0 1 2 5 4 0 1 2 1 3 3 4 0 1 1 3 0 0 1 1 1 2 0 2 2 2 1 2 1 4 1 0 0 2 1 3 0 3 2 0 4 1 2 2 1 0 0 2 1 2 1 2 3 3 2 0 2 4 1 4 3 1 3 1 2 1 0 1 2 2 2 2 4 1 0 3 3 1 1 1 6 2 0 0 1 0 1 3 2 5 4 2 3 2 3 2 0 1 6 1 0 1 2 0 4 1 0 1 3 4 3 1 2 3 2 1 4 1 1 0 4 3 2 5 3 2 1 3 4 3 3 3 3 2 2 3 3 3 3 2 2 1 5 3 1 3 3 3 4 3 1 3 3 3 5 4 4 5 3 0 2 3 6 3 2 3 2 2 1 6 5 5 1 6 2 5 6 3 2 2 3 4 5 1 3 3 5 5 3 3 5 5 7 2 3 3 4 5 6 7 1 3 3 4 5 4 4 5 2 8 4 6 1 2 6</intensities>
			</dataPoints>
		</scan>
		<scan appendNumber="0" mode="Continuous" scanAxis="2Theta" status="Completed">
			<header>
				<startTimeStamp>2012-06-15T21:36:35+02:00</startTimeStamp>
				<endTimeStamp>2012-06-15T21:36:38+02:00</endTimeStamp>
				<author>
					<name>Johannes Kepler Univ</name>
				</author>
				<source>
					<applicationSoftware version="2.2i">X'Pert Data Collector</applicationSoftware>
					<instrumentControlSoftware version="2.1E">XPERT-PRO</instrumentControlSoftware>
					<instrumentID>0000000011071750</instrumentID>
				</source>
			</header>
			<scanAxisCenter>
				<position axis="2Theta" unit="deg">68.6283</position>
			</scanAxisCenter>
			<dataPoints>
				<positions axis="2Theta" unit="deg">
					<listPositions>67.67550446 67.68300542 67.69050642 67.69800744 67.70550850 67.71300959 67.72051070 67.72801186 67.73551304 67.74301425 67.75051549 67.75801677 67.76551807 67.77301940 67.78052076 67.78802215 67.79552357 67.80302502 67.81052650 67.81802800 67.82552953 67.83303109 67.84053268 67.84803429 67.85553593 67.86303760 67.87053929 67.87804101 67.88554276 67.89304453 67.90054633 67.90804815 67.91554999 67.92305186 67.93055376 67.93805567 67.94555761 67.95305958 67.96056157 67.96806358 67.97556561 67.98306767 67.99056975 67.99807185 68.00557397 68.01307611 68.02057828 68.02808046 68.03558267 68.04308489 68.05058714 68.05808940 68.06559169 68.07309399 68.08059632 68.08809866 68.09560102 68.10310340 68.11060580 68.11810821 68.12561065 68.13311310 68.14061556 68.14811805 68.15562055 68.16312306 68.17062559 68.17812814 68.18563070 68.19313328 68.20063588 68.20813848 68.21564111 68.22314374 68.23064639 68.23814906 68.24565174 68.25315443 68.26065713 68.26815985 68.27566257 68.28316531 68.29066807 68.29817083 68.30567361 68.31317639 68.32067919 68.32818200 68.33568481 68.34318764 68.35069048 68.35819333 68.36569618 68.37319905 68.38070192 68.38820481 68.39570770 68.40321060 68.41071350 68.41821642 68.42571934 68.43322227 68.44072520 68.44822814 68.45573109 68.46323405 68.47073700 68.47823997 68.48574294 68.49324591 68.50074889 68.50825188 68.51575486 68.52325786 68.53076085 68.53826385 68.54576685 68.55326986 68.56077286 68.56827587 68.57577888 68.58328190 68.59078491 68.59828793 68.60579095 68.61329396 68.62079698 68.62830000 68.63580302 68.64330604 68.65080905 68.65831207 68.66581509 68.67331810 68.68082112 68.68832413 68.69582714 68.70333014 68.71083315 68.71833615 68.72583915 68.73334214 68.74084514 68.74834812 68.75585111 68.76335409 68.77085706 68.77836003 68.78586300 68.79336595 68.80086891 68.80837186 68.81587480 68.82337773 68.83088066 68.83838358 68.84588650 68.85338940 68.86089230 68.86839519 68.87589808 68.88340095 68.89090382 68.89840667 68.90590952 68.91341236 68.92091519 68.92841800 68.93592081 68.94342361 68.95092639 68.95842917 68.96593193 68.97343469 68.98093743 68.98844015 68.99594287 69.00344557 69.01094826 69.01845094 69.02595361 69.03345626 69.04095889 69.04846152 69.05596412 69.06346672 69.07096930 69.07847186 69.08597441 69.09347694 69.10097945 69.10848195 69.11598444 69.12348690 69.13098935 69.13849179 69.14599420 69.15349660 69.16099898 69.16850134 69.17600368 69.18350601 69.19100831 69.19851060 69.20601286 69.21351511 69.22101733 69.22851954 69.23602172 69.24352389 69.25102603 69.25852815 69.26603025 69.27353233 69.28103439 69.28853642 69.29603843 69.30354042 69.31104239 69.31854433 69.32604624 69.33354814 69.34105001 69.34855185 69.35605367 69.36355547 69.37105724 69.37855899 69.38606071 69.39356240 69.40106407 69.40856571 69.41606732 69.42356891 69.43107047 69.43857200 69.44607350 69.45357498 69.46107643 69.46857785 69.47607924 69.48358060 69.49108193 69.49858323 69.50608451 69.51358575 69.52108696 69.52858814 69.53608930 69.54359041 69.55109150 69.55859256 69.56609358 69.57359458 69.58109554</listPositions>
				</positions>
				<positions axis="Omega" unit="deg">
					<commonPosition>35.0446</commonPosition>
				</positions>
				<positions axis="Phi" unit="deg">
					<commonPosition>-1.64</commonPosition>
				</positions>
				<positions axis="Psi" unit="deg">
					<commonPosition>0.12</commonPosition>
				</positions>
				<positions axis="X" unit="mm">
					<commonPosition>0.00</commonPosition>
				</positions>
				<positions axis="Y" unit="mm">
					<commonPosition>0.00</commonPosition>
				</positions>
				<positions axis="Z" unit="mm">
					<commonPosition>17.671</commonPosition>
				</positions>
				<commonCountingTime unit="seconds">2.00</commonCountingTime>
				<intensities unit="counts">1 2 0 1 0 2 1 1 2 0 3 4 0 2 1 1 0 0 1 0 1 1 2 2 1 1 3 0 1 1 1 1 1 1 3 1 2 2 1 5 1 1 4 1 2 3 1 1 0 2 0 2 0 0 1 4 1 1 1 8 2 1 1 1 2 2 0 2 2 1 2 4 0 2 0 1 3 5 1 0 1 1 2 1 2 0 3 1 1 3 0 0 3 0 4 1 0 1 0 1 1 0 2 0 2 1 4 2 2 2 2 2 3 2 2 3 3 1 2 1 0 2 3 4 0 2 2 3 1 1 1 3 2 2 2 0 3 6 0 2 1 2 3 2 2 5 3 0 1 1 5 3 2 3 3 0 6 1 1 2 1 1 2 1 4 0 1 3 3 1 1 2 1 1 1 2 2 3 1 3 1 5 0 3 3 2 2 1 3 1 2 4 2 3 4 2 0 4 5 1 3 3 1 5 2 3 2 3 6 4 4 8 3 6 2 6 2 2 9 3 1 1 0 1 1 4 3 5 4 5 4 2 5 4 7 5 6 6 4 6 1 2 4 7 4 2 6 5 9 7 3 4 3 4 2</intensities>
			</dataPoints>
		</scan>
		<scan appendNumber="0" mode="Continuous" scanAxis="2Theta" status="Completed">
			<header>
				<startTimeStamp>2012-06-15T21:36:44+02:00</startTimeStamp>
				<endTimeStamp>2012-06-15T21:36:47+02:00</endTimeStamp>
				<author>
					<name>Johannes Kepler Univ</name>
				</author>
				<source>
					<applicationSoftware version="2.2i">X'Pert Data Collector</applicationSoftware>
					<instrumentControlSoftware version="2.1E">XPERT-PRO</instrumentControlSoftware>
					<instrumentID>0000000011071750</instrumentID>
				</source>
			</header>
			<scanAxisCenter>
				<position axis="2Theta" unit="deg">68.6283</position>
			</scanAxisCenter>
			<dataPoints>
				<positions axis="2Theta" unit="deg">
					<listPositions>67.67550446 67.68300542 67.69050642 67.69800744 67.70550850 67.71300959 67.72051070 67.72801186 67.73551304 67.74301425 67.75051549 67.75801677 67.76551807 67.77301940 67.78052076 67.78802215 67.79552357 67.80302502 67.81052650 67.81802800 67.82552953 67.83303109 67.84053268 67.84803429 67.85553593 67.86303760 67.87053929 67.87804101 67.88554276 67.89304453 67.90054633 67.90804815 67.91554999 67.92305186 67.93055376 67.93805567 67.94555761 67.95305958 67.96056157 67.96806358 67.97556561 67.98306767 67.99056975 67.99807185 68.00557397 68.01307611 68.02057828 68.02808046 68.03558267 68.04308489 68.05058714 68.05808940 68.06559169 68.07309399 68.08059632 68.08809866 68.09560102 68.10310340 68.11060580 68.11810821 68.12561065 68.13311310 68.14061556 68.14811805 68.15562055 68.16312306 68.17062559 68.17812814 68.18563070 68.19313328 68.20063588 68.20813848 68.21564111 68.22314374 68.23064639 68.23814906 68.24565174 68.25315443 68.26065713 68.26815985 68.27566257 68.28316531 68.29066807 68.29817083 68.30567361 68.31317639 68.32067919 68.32818200 68.33568481 68.34318764 68.35069048 68.35819333 68.36569618 68.37319905 68.38070192 68.38820481 68.39570770 68.40321060 68.41071350 68.41821642 68.42571934 68.43322227 68.44072520 68.44822814 68.45573109 68.46323405 68.47073700 68.47823997 68.48574294 68.49324591 68.50074889 68.50825188 68.51575486 68.52325786 68.53076085 68.53826385 68.54576685 68.55326986 68.56077286 68.56827587 68.57577888 68.58328190 68.59078491 68.59828793 68.60579095 68.61329396 68.62079698 68.62830000 68.63580302 68.64330604 68.65080905 68.65831207 68.66581509 68.67331810 68.68082112 68.68832413 68.69582714 68.70333014 68.71083315 68.71833615 68.72583915 68.73334214 68.74084514 68.74834812 68.75585111 68.76335409 68.77085706 68.77836003 68.78586300 68.79336595 68.80086891 68.80837186 68.81587480 68.82337773 68.83088066 68.83838358 68.84588650 68.85338940 68.86089230 68.86839519 68.87589808 68.88340095 68.89090382 68.89840667 68.90590952 68.91341236 68.92091519 68.92841800 68.93592081 68.94342361 68.95092639 68.95842917 68.96593193 68.97343469 68.98093743 68.98844015 68.99594287 69.00344557 69.01094826 69.01845094 69.02595361 69.03345626 69.04095889 69.04846152 69.05596412 69.06346672 69.07096930 69.07847186 69.08597441 69.09347694 69.10097945 69.10848195 69.11598444 69.12348690 69.13098935 69.13849179 69.14599420 69.15349660 69.16099898 69.16850134 69.17600368 69.18350601 69.19100831 69.19851060 69.20601286 69.21351511 69.22101733 69.22851954 69.23602172 69.24352389 69.25102603 69.25852815 69.26603025 69.27353233 69.28103439 69.28853642 69.29603843 69.30354042 69.31104239 69.31854433 69.32604624 69.33354814 69.34105001 69.34855185 69.35605367 69.36355547 69.37105724 69.37855899 69.38606071 69.39356240 69.40106407 69.40856571 69.41606732 69.42356891 69.43107047 69.43857200 69.44607350 69.45357498 69.46107643 69.46857785 69.47607924 69.48358060 69.49108193 69.49858323 69.50608451 69.51358575 69.52108696 69.52858814 69.53608930 69.54359041 69.55109150 69.55859256 69.56609358 69.57359458 69.58109554</listPositions>
				</positions>
				<positions axis="Omega" unit="deg">
					<commonPosition>35.0496</commonPosition>
				</positions>
				<positions axis="Phi" unit="deg">
					<commonPosition>-1.64</commonPosition>
				</positions>
				<positions axis="Psi" unit="deg">
					<commonPosition>0.12</commonPosition>
				</positions>
				<positions axis="X" unit="mm">
					<commonPosition>0.00</commonPosition>
				</positions>
				<positions axis="Y" unit="mm">
					<commonPosition>0.00</commonPosition>
				</positions>
				<positions axis="Z" unit="mm">
					<commonPosition>17.671</commonPosition>
				</positions>
				<commonCountingTime unit="seconds">2.00</commonCountingTime>
				<intensities unit="counts">2 3 1 0 0 0 1 0 2 1 1 0 0 2 0 1 1 1 0 0 1 2 1 1 1 1 2 2 2 1 0 1 2 0 2 2 1 2 1 1 1 2 3 0 1 5 2 1 3 0 1 2 2 3 0 5 0 1 0 1 1 1 2 1 2 2 0 1 0 4 0 2 2 1 2 1 2 0 2 0 1 1 3 2 1 0 3 1 5 3 0 4 0 0 3 1 2 1 3 2 1 4 0 1 0 2 3 1 0 0 3 5 5 0 3 1 4 2 0 1 1 2 3 5 0 3 1 0 2 2 1 3 0 4 2 3 4 4 2 3 1 3 4 2 1 4 4 4 1 2 3 4 1 6 1 5 2 1 1 0 1 4 2 2 1 2 1 2 1 3 5 2 3 2 5 2 0 2 3 0 4 4 2 1 6 4 2 7 0 3 5 2 1 2 1 4 4 5 3 5 7 5 3 2 1 2 3 5 1 2 6 1 5 4 5 3 3 2 7 2 2 5 5 5 6 5 3 2 4 7 6 3 7 3 2 6 3 2 2 6 2 4 5 2 2 7 5 3 5 6 3 2 5 5 5</intensities>
			</dataPoints>
		</scan>
		<scan appendNumber="0" mode="Continuous" scanAxis="2Theta" status="Completed">
			<header>
				<startTimeStamp>2012-06-15T21:36:53+02:00</startTimeStamp>
				<endTimeStamp>2012-06-15T21:36:56+02:00</endTimeStamp>
				<author>
					<name>Johannes Kepler Univ</name>
				</author>
				<source>
					<applicationSoftware version="2.2i">X'Pert Data Collector</applicationSoftware>
					<instrumentControlSoftware version="2.1E">XPERT-PRO</instrumentControlSoftware>
					<instrumentID>0000000011071750</instrumentID>
				</source>
			</header>
			<scanAxisCenter>
				<position axis="2Theta" unit="deg">68.6283</position>
			</scanAxisCenter>
			<dataPoints>
				<positions axis="2Theta" unit="deg">
					<listPositions>67.67550446 67.68300542 67.69050642 67.69800744 67.70550850 67.71300959 67.72051070 67.72801186 67.73551304 67.74301425 67.75051549 67.75801677 67.76551807 67.77301940 67.78052076 67.78802215 67.79552357 67.80302502 67.81052650 67.81802800 67.82552953 67.83303109 67.84053268 67.84803429 67.85553593 67.86303760 67.87053929 67.87804101 67.88554276 67.89304453 67.90054633 67.90804815 67.91554999 67.92305186 67.93055376 67.93805567 67.94555761 67.95305958 67.96056157 67.96806358 67.97556561 67.98306767 67.99056975 67.99807185 68.00557397 68.01307611 68.02057828 68.02808046 68.03558267 68.04308489 68.05058714 68.05808940 68.06559169 68.07309399 68.08059632 68.08809866 68.09560102 68.10310340 68.11060580 68.11810821 68.12561065 68.13311310 68.14061556 68.14811805 68.15562055 68.16312306 68.17062559 68.17812814 68.18563070 68.19313328 68.20063588 68.20813848 68.21564111 68.22314374 68.23064639 68.23814906 68.24565174 68.25315443 68.26065713 68.26815985 68.27566257 68.28316531 68.29066807 68.29817083 68.30567361 68.31317639 68.32067919 68.32818200 68.33568481 68.34318764 68.35069048 68.35819333 68.36569618 68.37319905 68.38070192 68.38820481 68.39570770 68.40321060 68.41071350 68.41821642 68.42571934 68.43322227 68.44072520 68.44822814 68.45573109 68.46323405 68.47073700 68.47823997 68.48574294 68.49324591 68.50074889 68.50825188 68.51575486 68.52325786 68.53076085 68.53826385 68.54576685 68.55326986 68.56077286 68.56827587 68.57577888 68.58328190 68.59078491 68.59828793 68.60579095 68.61329396 68.62079698 68.62830000 68.63580302 68.64330604 68.65080905 68.65831207 68.66581509 68.67331810 68.68082112 68.68832413 68.69582714 68.70333014 68.71083315 68.71833615 68.72583915 68.73334214 68.74084514 68.74834812 68.75585111 68.76335409 68.77085706 68.77836003 68.78586300 68.79336595 68.80086891 68.80837186 68.81587480 68.82337773 68.83088066 68.83838358 68.84588650 68.85338940 68.86089230 68.86839519 68.87589808 68.88340095 68.89090382 68.89840667 68.90590952 68.91341236 68.92091519 68.92841800 68.93592081 68.94342361 68.95092639 68.95842917 68.96593193 68.97343469 68.98093743 68.98844015 68.99594287 69.00344557 69.01094826 69.01845094 69.02595361 69.03345626 69.04095889 69.04846152 69.05596412 69.06346672 69.07096930 69.07847186 69.08597441 69.09347694 69.10097945 69.10848195 69.11598444 69.12348690 69.13098935 69.13849179 69.14599420 69.15349660 69.16099898 69.16850134 69.17600368 69.18350601 69.19100831 69.19851060 69.20601286 69.21351511 69.22101733 69.22851954 69.23602172 69.24352389 69.25102603 69.25852815 69.26603025 69.27353233 69.28103439 69.28853642 69.29603843 69.30354042 69.31104239 69.31854433 69.32604624 69.33354814 69.34105001 69.34855185 69.35605367 69.36355547 69.37105724 69.37855899 69.38606071 69.39356240 69.40106407 69.40856571 69.41606732 69.42356891 69.43107047 69.43857200 69.44607350 69.45357498 69.46107643 69.46857785 69.47607924 69.48358060 69.49108193 69.49858323 69.50608451 69.51358575 69.52108696 69.52858814 69.53608930 69.54359041 69.55109150 69.55859256 69.56609358 69.57359458 69.58109554</listPositions>
				</positions>
				<positions axis="Omega" unit="deg">
					<commonPosition>35.0546</commonPosition>
				</positions>
				<positions axis="Phi" unit="deg">
					<commonPosition>-1.64</commonPosition>
				</positions>
				<positions axis="Psi" unit="deg">
					<commonPosition>0.12</commonPosition>
				</positions>
				<positions axis="X" unit="mm">
					<commonPosition>0.00</commonPosition>
				</positions>
				<positions axis="Y" unit="mm">
					<commonPosition>0.00</commonPosition>
				</positions>
				<positions axis="Z" unit="mm">
					<commonPosition>17.671</commonPosition>
				</positions>
				<commonCountingTime unit="seconds">2.00</commonCountingTime>
				<intensities unit="counts">2 1 2 0 1 1 0 2 1 1 0 4 1 2 1 0 4 0 1 2 1 3 1 0 0 0 1 2 1 1 1 5 0 3 1 0 2 0 1 0 0 1 0 4 1 1 2 1 3 1 2 3 1 2 1 2 2 0 1 1 3 4 0 1 0 4 3 2 1 2 2 2 1 1 2 2 4 1 0 1 1 2 2 3 1 5 2 2 1 1 2 4 3 1 0 2 2 2 1 0 3 3 4 0 3 4 1 3 5 0 7 2 4 1 3 2 0 1 3 3 2 1 1 1 5 3 1 2 2 1 3 1 2 2 0 4 2 4 1 0 1 2 1 1 4 0 0 3 2 2 9 2 1 1 2 3 1 1 5 0 3 2 2 3 0 1 0 2 3 1 5 5 3 4 3 2 3 0 2 5 2 3 1 1 1 4 0 4 1 3 1 5 4 3 5 3 2 5 3 4 1 3 4 6 3 2 1 4 4 1 1 4 2 6 1 3 3 2 5 6 5 5 4 5 3 5 4 8 6 3 2 7 3 4 7 2 1 1 4 3 4 4 4 5 2 3 3 5 5 3 4 2 3 2 3</intensities>
			</dataPoints>
		</scan>
	</xrdMeasurement>
</xrdMeasurements>