File: examples/data/rsm_5.xrdml
<?xml version="1.0" encoding="UTF-8"?>
<xrdMeasurements xmlns="http://www.xrdml.com/XRDMeasurement/1.3" xmlns:xsi="http://www.w3.org/2001/XMLSchema-instance" xsi:schemaLocation="http://www.xrdml.com/XRDMeasurement/1.3 http://www.xrdml.com/XRDMeasurement/1.3/XRDMeasurement.xsd" status="Completed">
	<comment>
		<entry>Configuration=Factory configuration, Owner=User-1, Creation date=6/4/2010 10:23:02 AM</entry>
		<entry>Goniometer=PW3050/65 (Theta/2Theta); Minimum step size 2Theta:0.0001; Minimum step size Omega:0.0001</entry>
		<entry>Sample stage=MRD XL Cradle; Minimum step size Phi:0.01; Minimum step size Psi:0.01; Minimum step size X:0.01; Minimum step size Y:0.01; Minimum step size Z:0.001</entry>
		<entry>Diffractometer system=XPERT-PRO</entry>
		<entry>Measurement program=GreenSi_map_2deg2s, Owner=tanja, Creation date=3/19/2012 10:07:21 AM</entry>
		<entry>Fine Calibration Offset for 2Theta = -0.0192 deg</entry>
		<entry>Fine Calibration Offset for Omega = 0.1691 deg</entry>
		<entry>Batch program=Rastelli_XRR_XRD_short_period_sample5, Owner=tanja, Creation date=6/15/2012 3:39:26 PM</entry>
	</comment>
	<sample type="To be analyzed">
		<id></id>
		<name></name>
		<preparedBy></preparedBy>
	</sample>
	<xrdMeasurement measurementType="Area measurement" status="Completed" measurementStepAxis="Omega" sampleMode="Reflection">
		<comment>
			<entry/>
		</comment>
		<usedWavelength intended="K-Alpha 1">
			<kAlpha1 unit="Angstrom">1.5405980</kAlpha1>
			<kAlpha2 unit="Angstrom">1.5444260</kAlpha2>
			<kBeta unit="Angstrom">1.3922500</kBeta>
			<ratioKAlpha2KAlpha1>0.5000</ratioKAlpha2KAlpha1>
		</usedWavelength>
		<incidentBeamPath>
			<radius unit="mm">420.00</radius>
			<xRayTube id="1010048" name="PW3373/10 Cu LFF DK394719">
				<tension unit="kV">45</tension>
				<current unit="mA">40</current>
				<anodeMaterial>Cu</anodeMaterial>
				<focus type="Line">
					<length unit="mm">12.0</length>
					<width unit="mm">0.4</width>
					<takeOffAngle unit="deg">3.7</takeOffAngle>
				</focus>
			</xRayTube>
			<xRayMirror id="27090001" name="Inc. Beam Cu W/Si (hybrid MRD)" hybrid="true">
				<crystal type="Graded" shape="Parabolic">W/Si</crystal>
				<acceptanceAngle unit="deg">0.8</acceptanceAngle>
				<length unit="mm">60.0</length>
			</xRayMirror>
			<monochromator id="23090002" name="Inc. Beam 2xGe220 Cu Asym. (hybrid)" hybrid="true">
				<crystal type="Asymmetric" shape="Flat">Ge</crystal>
				<numberOfReflections>2</numberOfReflections>
				<hkl>
					<h>2</h>
					<k>2</k>
					<l>0</l>
				</hkl>
			</monochromator>
			<divergenceSlit id="22010009" name="Slit Fixed 1/16Â°" xsi:type="fixedDivergenceSlitType">
				<distanceToSample unit="mm">320.00</distanceToSample>
				<height unit="mm">0.10</height>
			</divergenceSlit>
		</incidentBeamPath>
		<sampleOffset>
			<position axis="2Theta" unit="deg">0.0000</position>
			<position axis="Omega" unit="deg">0.0000</position>
		</sampleOffset>
		<diffractedBeamPath>
			<radius unit="mm">420.00</radius>
			<antiScatterSlit id="22090014" name="AS Slit 5.0 mm (PIXcel non-ambient &amp; MRD)" xsi:type="fixedAntiScatterSlitType">
				<height unit="mm">5.00</height>
			</antiScatterSlit>
			<detector id="7010015" name="PIXcel" xsi:type="rtmsDetectorType">
				<phd>
					<lowerLevel unit="%">25.5</lowerLevel>
					<upperLevel unit="%">100.0</upperLevel>
				</phd>
				<mode>Static</mode>
				<activeLength unit="deg">1.9131</activeLength>
			</detector>
		</diffractedBeamPath>
		<measurementStepAxisCenter>
			<position axis="Omega" unit="deg">30.4546</position>
		</measurementStepAxisCenter>
		<scan appendNumber="0" mode="Continuous" scanAxis="2Theta" status="Completed">
			<header>
				<startTimeStamp>2012-06-16T00:27:05+02:00</startTimeStamp>
				<endTimeStamp>2012-06-16T00:27:08+02:00</endTimeStamp>
				<author>
					<name>Johannes Kepler Univ</name>
				</author>
				<source>
					<applicationSoftware version="2.2i">X'Pert Data Collector</applicationSoftware>
					<instrumentControlSoftware version="2.1E">XPERT-PRO</instrumentControlSoftware>
					<instrumentID>0000000011071750</instrumentID>
				</source>
			</header>
			<scanAxisCenter>
				<position axis="2Theta" unit="deg">61.4283</position>
			</scanAxisCenter>
			<dataPoints>
				<positions axis="2Theta" unit="deg">
					<listPositions>60.47550446 60.48300542 60.49050642 60.49800744 60.50550850 60.51300959 60.52051070 60.52801186 60.53551304 60.54301425 60.55051549 60.55801677 60.56551807 60.57301940 60.58052076 60.58802215 60.59552357 60.60302502 60.61052650 60.61802800 60.62552953 60.63303109 60.64053268 60.64803429 60.65553593 60.66303760 60.67053929 60.67804101 60.68554276 60.69304453 60.70054633 60.70804815 60.71554999 60.72305186 60.73055376 60.73805567 60.74555761 60.75305958 60.76056157 60.76806358 60.77556561 60.78306767 60.79056975 60.79807185 60.80557397 60.81307611 60.82057828 60.82808046 60.83558267 60.84308489 60.85058714 60.85808940 60.86559169 60.87309399 60.88059632 60.88809866 60.89560102 60.90310340 60.91060580 60.91810821 60.92561065 60.93311310 60.94061556 60.94811805 60.95562055 60.96312306 60.97062559 60.97812814 60.98563070 60.99313328 61.00063588 61.00813848 61.01564111 61.02314374 61.03064639 61.03814906 61.04565174 61.05315443 61.06065713 61.06815985 61.07566257 61.08316531 61.09066807 61.09817083 61.10567361 61.11317639 61.12067919 61.12818200 61.13568481 61.14318764 61.15069048 61.15819333 61.16569618 61.17319905 61.18070192 61.18820481 61.19570770 61.20321060 61.21071350 61.21821642 61.22571934 61.23322227 61.24072520 61.24822814 61.25573109 61.26323405 61.27073700 61.27823997 61.28574294 61.29324591 61.30074889 61.30825188 61.31575486 61.32325786 61.33076085 61.33826385 61.34576685 61.35326986 61.36077286 61.36827587 61.37577888 61.38328190 61.39078491 61.39828793 61.40579095 61.41329396 61.42079698 61.42830000 61.43580302 61.44330604 61.45080905 61.45831207 61.46581509 61.47331810 61.48082112 61.48832413 61.49582714 61.50333014 61.51083315 61.51833615 61.52583915 61.53334214 61.54084514 61.54834812 61.55585111 61.56335409 61.57085706 61.57836003 61.58586300 61.59336595 61.60086891 61.60837186 61.61587480 61.62337773 61.63088066 61.63838358 61.64588650 61.65338940 61.66089230 61.66839519 61.67589808 61.68340095 61.69090382 61.69840667 61.70590952 61.71341236 61.72091519 61.72841800 61.73592081 61.74342361 61.75092639 61.75842917 61.76593193 61.77343469 61.78093743 61.78844015 61.79594287 61.80344557 61.81094826 61.81845094 61.82595361 61.83345626 61.84095889 61.84846152 61.85596412 61.86346672 61.87096930 61.87847186 61.88597441 61.89347694 61.90097945 61.90848195 61.91598444 61.92348690 61.93098935 61.93849179 61.94599420 61.95349660 61.96099898 61.96850134 61.97600368 61.98350601 61.99100831 61.99851060 62.00601286 62.01351511 62.02101733 62.02851954 62.03602172 62.04352389 62.05102603 62.05852815 62.06603025 62.07353233 62.08103439 62.08853642 62.09603843 62.10354042 62.11104239 62.11854433 62.12604624 62.13354814 62.14105001 62.14855185 62.15605367 62.16355547 62.17105724 62.17855899 62.18606071 62.19356240 62.20106407 62.20856571 62.21606732 62.22356891 62.23107047 62.23857200 62.24607350 62.25357498 62.26107643 62.26857785 62.27607924 62.28358060 62.29108193 62.29858323 62.30608451 62.31358575 62.32108696 62.32858814 62.33608930 62.34359041 62.35109150 62.35859256 62.36609358 62.37359458 62.38109554</listPositions>
				</positions>
				<positions axis="Omega" unit="deg">
					<commonPosition>29.4546</commonPosition>
				</positions>
				<positions axis="Phi" unit="deg">
					<commonPosition>-1.64</commonPosition>
				</positions>
				<positions axis="Psi" unit="deg">
					<commonPosition>0.12</commonPosition>
				</positions>
				<positions axis="X" unit="mm">
					<commonPosition>0.00</commonPosition>
				</positions>
				<positions axis="Y" unit="mm">
					<commonPosition>0.00</commonPosition>
				</positions>
				<positions axis="Z" unit="mm">
					<commonPosition>17.671</commonPosition>
				</positions>
				<commonCountingTime unit="seconds">2.00</commonCountingTime>
				<intensities unit="counts">1 1 1 2 0 0 1 0 1 2 0 0 0 1 3 1 2 1 0 1 0 0 0 0 0 2 0 0 0 1 2 0 0 1 1 0 0 0 0 1 1 1 0 0 0 0 0 0 1 1 1 0 0 0 0 1 1 0 1 2 0 1 0 0 1 2 1 0 0 0 0 0 2 0 1 0 3 0 3 0 0 0 0 1 2 1 1 0 0 1 0 1 0 0 4 0 0 0 1 2 1 0 2 0 0 0 0 0 0 1 2 1 3 1 0 0 1 2 0 1 0 1 0 1 0 1 0 1 1 0 0 2 1 1 1 0 1 0 0 1 1 0 1 0 1 1 2 0 0 2 1 0 1 0 1 1 0 1 0 2 1 1 1 1 1 0 0 0 0 1 3 0 1 1 0 1 0 0 1 1 1 1 0 0 2 0 1 1 1 1 2 0 1 0 1 0 0 0 2 1 0 0 0 1 1 1 0 0 0 0 0 1 1 2 1 2 0 0 1 1 0 1 2 0 0 2 2 1 0 0 0 0 0 0 1 1 0 0 3 1 1 1 0 2 0 0 0 2 1 0 4 1 1 0 0</intensities>
			</dataPoints>
		</scan>
		<scan appendNumber="0" mode="Continuous" scanAxis="2Theta" status="Completed">
			<header>
				<startTimeStamp>2012-06-16T00:27:12+02:00</startTimeStamp>
				<endTimeStamp>2012-06-16T00:27:16+02:00</endTimeStamp>
				<author>
					<name>Johannes Kepler Univ</name>
				</author>
				<source>
					<applicationSoftware version="2.2i">X'Pert Data Collector</applicationSoftware>
					<instrumentControlSoftware version="2.1E">XPERT-PRO</instrumentControlSoftware>
					<instrumentID>0000000011071750</instrumentID>
				</source>
			</header>
			<scanAxisCenter>
				<position axis="2Theta" unit="deg">61.4283</position>
			</scanAxisCenter>
			<dataPoints>
				<positions axis="2Theta" unit="deg">
					<listPositions>60.47550446 60.48300542 60.49050642 60.49800744 60.50550850 60.51300959 60.52051070 60.52801186 60.53551304 60.54301425 60.55051549 60.55801677 60.56551807 60.57301940 60.58052076 60.58802215 60.59552357 60.60302502 60.61052650 60.61802800 60.62552953 60.63303109 60.64053268 60.64803429 60.65553593 60.66303760 60.67053929 60.67804101 60.68554276 60.69304453 60.70054633 60.70804815 60.71554999 60.72305186 60.73055376 60.73805567 60.74555761 60.75305958 60.76056157 60.76806358 60.77556561 60.78306767 60.79056975 60.79807185 60.80557397 60.81307611 60.82057828 60.82808046 60.83558267 60.84308489 60.85058714 60.85808940 60.86559169 60.87309399 60.88059632 60.88809866 60.89560102 60.90310340 60.91060580 60.91810821 60.92561065 60.93311310 60.94061556 60.94811805 60.95562055 60.96312306 60.97062559 60.97812814 60.98563070 60.99313328 61.00063588 61.00813848 61.01564111 61.02314374 61.03064639 61.03814906 61.04565174 61.05315443 61.06065713 61.06815985 61.07566257 61.08316531 61.09066807 61.09817083 61.10567361 61.11317639 61.12067919 61.12818200 61.13568481 61.14318764 61.15069048 61.15819333 61.16569618 61.17319905 61.18070192 61.18820481 61.19570770 61.20321060 61.21071350 61.21821642 61.22571934 61.23322227 61.24072520 61.24822814 61.25573109 61.26323405 61.27073700 61.27823997 61.28574294 61.29324591 61.30074889 61.30825188 61.31575486 61.32325786 61.33076085 61.33826385 61.34576685 61.35326986 61.36077286 61.36827587 61.37577888 61.38328190 61.39078491 61.39828793 61.40579095 61.41329396 61.42079698 61.42830000 61.43580302 61.44330604 61.45080905 61.45831207 61.46581509 61.47331810 61.48082112 61.48832413 61.49582714 61.50333014 61.51083315 61.51833615 61.52583915 61.53334214 61.54084514 61.54834812 61.55585111 61.56335409 61.57085706 61.57836003 61.58586300 61.59336595 61.60086891 61.60837186 61.61587480 61.62337773 61.63088066 61.63838358 61.64588650 61.65338940 61.66089230 61.66839519 61.67589808 61.68340095 61.69090382 61.69840667 61.70590952 61.71341236 61.72091519 61.72841800 61.73592081 61.74342361 61.75092639 61.75842917 61.76593193 61.77343469 61.78093743 61.78844015 61.79594287 61.80344557 61.81094826 61.81845094 61.82595361 61.83345626 61.84095889 61.84846152 61.85596412 61.86346672 61.87096930 61.87847186 61.88597441 61.89347694 61.90097945 61.90848195 61.91598444 61.92348690 61.93098935 61.93849179 61.94599420 61.95349660 61.96099898 61.96850134 61.97600368 61.98350601 61.99100831 61.99851060 62.00601286 62.01351511 62.02101733 62.02851954 62.03602172 62.04352389 62.05102603 62.05852815 62.06603025 62.07353233 62.08103439 62.08853642 62.09603843 62.10354042 62.11104239 62.11854433 62.12604624 62.13354814 62.14105001 62.14855185 62.15605367 62.16355547 62.17105724 62.17855899 62.18606071 62.19356240 62.20106407 62.20856571 62.21606732 62.22356891 62.23107047 62.23857200 62.24607350 62.25357498 62.26107643 62.26857785 62.27607924 62.28358060 62.29108193 62.29858323 62.30608451 62.31358575 62.32108696 62.32858814 62.33608930 62.34359041 62.35109150 62.35859256 62.36609358 62.37359458 62.38109554</listPositions>
				</positions>
				<positions axis="Omega" unit="deg">
					<commonPosition>29.4596</commonPosition>
				</positions>
				<positions axis="Phi" unit="deg">
					<commonPosition>-1.64</commonPosition>
				</positions>
				<positions axis="Psi" unit="deg">
					<commonPosition>0.12</commonPosition>
				</positions>
				<positions axis="X" unit="mm">
					<commonPosition>0.00</commonPosition>
				</positions>
				<positions axis="Y" unit="mm">
					<commonPosition>0.00</commonPosition>
				</positions>
				<positions axis="Z" unit="mm">
					<commonPosition>17.671</commonPosition>
				</positions>
				<commonCountingTime unit="seconds">2.00</commonCountingTime>
				<intensities unit="counts">1 0 0 0 2 1 0 0 0 2 0 2 1 0 0 1 0 1 1 0 0 0 0 0 3 1 1 1 0 1 0 2 0 0 0 1 0 1 1 1 0 0 1 1 0 0 0 2 0 1 0 0 1 0 3 1 0 1 1 0 0 1 0 1 0 1 1 0 0 0 0 1 0 1 0 0 1 1 1 0 0 1 0 1 0 0 1 1 2 1 1 0 1 1 1 2 1 3 0 0 1 2 0 0 0 1 1 0 1 1 2 0 0 1 3 0 0 0 1 0 0 1 5 1 1 0 3 0 2 0 1 1 1 0 1 0 0 0 0 1 1 0 0 4 0 1 0 1 2 1 1 0 3 1 0 0 0 3 0 1 0 3 1 0 1 1 0 1 1 1 0 0 1 1 0 1 0 2 1 0 0 3 0 1 0 0 0 0 0 0 1 0 0 3 1 0 0 2 1 0 2 1 0 0 0 2 0 0 2 1 0 0 1 0 0 0 0 0 5 0 1 0 1 1 0 0 0 0 0 3 1 0 0 1 1 1 2 1 1 1 2 1 1 1 1 0 0 3 0 1 1 0 2 1 1</intensities>
			</dataPoints>
		</scan>
		<scan appendNumber="0" mode="Continuous" scanAxis="2Theta" status="Completed">
			<header>
				<startTimeStamp>2012-06-16T00:27:20+02:00</startTimeStamp>
				<endTimeStamp>2012-06-16T00:27:24+02:00</endTimeStamp>
				<author>
					<name>Johannes Kepler Univ</name>
				</author>
				<source>
					<applicationSoftware version="2.2i">X'Pert Data Collector</applicationSoftware>
					<instrumentControlSoftware version="2.1E">XPERT-PRO</instrumentControlSoftware>
					<instrumentID>0000000011071750</instrumentID>
				</source>
			</header>
			<scanAxisCenter>
				<position axis="2Theta" unit="deg">61.4283</position>
			</scanAxisCenter>
			<dataPoints>
				<positions axis="2Theta" unit="deg">
					<listPositions>60.47550446 60.48300542 60.49050642 60.49800744 60.50550850 60.51300959 60.52051070 60.52801186 60.53551304 60.54301425 60.55051549 60.55801677 60.56551807 60.57301940 60.58052076 60.58802215 60.59552357 60.60302502 60.61052650 60.61802800 60.62552953 60.63303109 60.64053268 60.64803429 60.65553593 60.66303760 60.67053929 60.67804101 60.68554276 60.69304453 60.70054633 60.70804815 60.71554999 60.72305186 60.73055376 60.73805567 60.74555761 60.75305958 60.76056157 60.76806358 60.77556561 60.78306767 60.79056975 60.79807185 60.80557397 60.81307611 60.82057828 60.82808046 60.83558267 60.84308489 60.85058714 60.85808940 60.86559169 60.87309399 60.88059632 60.88809866 60.89560102 60.90310340 60.91060580 60.91810821 60.92561065 60.93311310 60.94061556 60.94811805 60.95562055 60.96312306 60.97062559 60.97812814 60.98563070 60.99313328 61.00063588 61.00813848 61.01564111 61.02314374 61.03064639 61.03814906 61.04565174 61.05315443 61.06065713 61.06815985 61.07566257 61.08316531 61.09066807 61.09817083 61.10567361 61.11317639 61.12067919 61.12818200 61.13568481 61.14318764 61.15069048 61.15819333 61.16569618 61.17319905 61.18070192 61.18820481 61.19570770 61.20321060 61.21071350 61.21821642 61.22571934 61.23322227 61.24072520 61.24822814 61.25573109 61.26323405 61.27073700 61.27823997 61.28574294 61.29324591 61.30074889 61.30825188 61.31575486 61.32325786 61.33076085 61.33826385 61.34576685 61.35326986 61.36077286 61.36827587 61.37577888 61.38328190 61.39078491 61.39828793 61.40579095 61.41329396 61.42079698 61.42830000 61.43580302 61.44330604 61.45080905 61.45831207 61.46581509 61.47331810 61.48082112 61.48832413 61.49582714 61.50333014 61.51083315 61.51833615 61.52583915 61.53334214 61.54084514 61.54834812 61.55585111 61.56335409 61.57085706 61.57836003 61.58586300 61.59336595 61.60086891 61.60837186 61.61587480 61.62337773 61.63088066 61.63838358 61.64588650 61.65338940 61.66089230 61.66839519 61.67589808 61.68340095 61.69090382 61.69840667 61.70590952 61.71341236 61.72091519 61.72841800 61.73592081 61.74342361 61.75092639 61.75842917 61.76593193 61.77343469 61.78093743 61.78844015 61.79594287 61.80344557 61.81094826 61.81845094 61.82595361 61.83345626 61.84095889 61.84846152 61.85596412 61.86346672 61.87096930 61.87847186 61.88597441 61.89347694 61.90097945 61.90848195 61.91598444 61.92348690 61.93098935 61.93849179 61.94599420 61.95349660 61.96099898 61.96850134 61.97600368 61.98350601 61.99100831 61.99851060 62.00601286 62.01351511 62.02101733 62.02851954 62.03602172 62.04352389 62.05102603 62.05852815 62.06603025 62.07353233 62.08103439 62.08853642 62.09603843 62.10354042 62.11104239 62.11854433 62.12604624 62.13354814 62.14105001 62.14855185 62.15605367 62.16355547 62.17105724 62.17855899 62.18606071 62.19356240 62.20106407 62.20856571 62.21606732 62.22356891 62.23107047 62.23857200 62.24607350 62.25357498 62.26107643 62.26857785 62.27607924 62.28358060 62.29108193 62.29858323 62.30608451 62.31358575 62.32108696 62.32858814 62.33608930 62.34359041 62.35109150 62.35859256 62.36609358 62.37359458 62.38109554</listPositions>
				</positions>
				<positions axis="Omega" unit="deg">
					<commonPosition>29.4646</commonPosition>
				</positions>
				<positions axis="Phi" unit="deg">
					<commonPosition>-1.64</commonPosition>
				</positions>
				<positions axis="Psi" unit="deg">
					<commonPosition>0.12</commonPosition>
				</positions>
				<positions axis="X" unit="mm">
					<commonPosition>0.00</commonPosition>
				</positions>
				<positions axis="Y" unit="mm">
					<commonPosition>0.00</commonPosition>
				</positions>
				<positions axis="Z" unit="mm">
					<commonPosition>17.671</commonPosition>
				</positions>
				<commonCountingTime unit="seconds">2.00</commonCountingTime>
				<intensities unit="counts">0 0 0 1 0 0 1 0 0 0 1 0 0 0 1 2 3 1 0 1 2 2 1 1 1 2 1 0 0 1 0 2 0 1 0 0 0 0 0 2 0 0 1 0 2 1 1 0 1 2 3 0 0 1 1 0 1 1 0 3 1 0 1 0 0 0 0 0 0 2 0 0 2 1 0 0 0 0 1 0 2 0 0 0 1 1 1 3 2 0 0 0 1 0 0 2 1 1 0 0 1 0 1 2 0 2 0 1 1 1 1 1 1 0 0 1 0 1 1 2 0 1 1 0 1 0 1 0 3 1 0 1 2 0 0 3 2 2 0 0 0 0 2 1 0 0 0 1 1 0 0 2 2 0 1 0 3 1 1 0 1 0 0 0 1 1 1 0 1 2 0 1 0 1 1 0 2 0 1 0 0 1 0 2 0 2 1 1 0 0 0 2 0 0 0 1 0 1 2 2 2 0 1 0 0 0 0 0 0 0 0 0 1 1 0 1 1 3 0 1 1 0 0 0 0 0 1 2 0 2 0 0 2 0 0 1 2 0 0 0 0 0 0 0 0 0 1 0 0 0 1 0 1 0 0</intensities>
			</dataPoints>
		</scan>
		<scan appendNumber="0" mode="Continuous" scanAxis="2Theta" status="Completed">
			<header>
				<startTimeStamp>2012-06-16T00:27:28+02:00</startTimeStamp>
				<endTimeStamp>2012-06-16T00:27:31+02:00</endTimeStamp>
				<author>
					<name>Johannes Kepler Univ</name>
				</author>
				<source>
					<applicationSoftware version="2.2i">X'Pert Data Collector</applicationSoftware>
					<instrumentControlSoftware version="2.1E">XPERT-PRO</instrumentControlSoftware>
					<instrumentID>0000000011071750</instrumentID>
				</source>
			</header>
			<scanAxisCenter>
				<position axis="2Theta" unit="deg">61.4283</position>
			</scanAxisCenter>
			<dataPoints>
				<positions axis="2Theta" unit="deg">
					<listPositions>60.47550446 60.48300542 60.49050642 60.49800744 60.50550850 60.51300959 60.52051070 60.52801186 60.53551304 60.54301425 60.55051549 60.55801677 60.56551807 60.57301940 60.58052076 60.58802215 60.59552357 60.60302502 60.61052650 60.61802800 60.62552953 60.63303109 60.64053268 60.64803429 60.65553593 60.66303760 60.67053929 60.67804101 60.68554276 60.69304453 60.70054633 60.70804815 60.71554999 60.72305186 60.73055376 60.73805567 60.74555761 60.75305958 60.76056157 60.76806358 60.77556561 60.78306767 60.79056975 60.79807185 60.80557397 60.81307611 60.82057828 60.82808046 60.83558267 60.84308489 60.85058714 60.85808940 60.86559169 60.87309399 60.88059632 60.88809866 60.89560102 60.90310340 60.91060580 60.91810821 60.92561065 60.93311310 60.94061556 60.94811805 60.95562055 60.96312306 60.97062559 60.97812814 60.98563070 60.99313328 61.00063588 61.00813848 61.01564111 61.02314374 61.03064639 61.03814906 61.04565174 61.05315443 61.06065713 61.06815985 61.07566257 61.08316531 61.09066807 61.09817083 61.10567361 61.11317639 61.12067919 61.12818200 61.13568481 61.14318764 61.15069048 61.15819333 61.16569618 61.17319905 61.18070192 61.18820481 61.19570770 61.20321060 61.21071350 61.21821642 61.22571934 61.23322227 61.24072520 61.24822814 61.25573109 61.26323405 61.27073700 61.27823997 61.28574294 61.29324591 61.30074889 61.30825188 61.31575486 61.32325786 61.33076085 61.33826385 61.34576685 61.35326986 61.36077286 61.36827587 61.37577888 61.38328190 61.39078491 61.39828793 61.40579095 61.41329396 61.42079698 61.42830000 61.43580302 61.44330604 61.45080905 61.45831207 61.46581509 61.47331810 61.48082112 61.48832413 61.49582714 61.50333014 61.51083315 61.51833615 61.52583915 61.53334214 61.54084514 61.54834812 61.55585111 61.56335409 61.57085706 61.57836003 61.58586300 61.59336595 61.60086891 61.60837186 61.61587480 61.62337773 61.63088066 61.63838358 61.64588650 61.65338940 61.66089230 61.66839519 61.67589808 61.68340095 61.69090382 61.69840667 61.70590952 61.71341236 61.72091519 61.72841800 61.73592081 61.74342361 61.75092639 61.75842917 61.76593193 61.77343469 61.78093743 61.78844015 61.79594287 61.80344557 61.81094826 61.81845094 61.82595361 61.83345626 61.84095889 61.84846152 61.85596412 61.86346672 61.87096930 61.87847186 61.88597441 61.89347694 61.90097945 61.90848195 61.91598444 61.92348690 61.93098935 61.93849179 61.94599420 61.95349660 61.96099898 61.96850134 61.97600368 61.98350601 61.99100831 61.99851060 62.00601286 62.01351511 62.02101733 62.02851954 62.03602172 62.04352389 62.05102603 62.05852815 62.06603025 62.07353233 62.08103439 62.08853642 62.09603843 62.10354042 62.11104239 62.11854433 62.12604624 62.13354814 62.14105001 62.14855185 62.15605367 62.16355547 62.17105724 62.17855899 62.18606071 62.19356240 62.20106407 62.20856571 62.21606732 62.22356891 62.23107047 62.23857200 62.24607350 62.25357498 62.26107643 62.26857785 62.27607924 62.28358060 62.29108193 62.29858323 62.30608451 62.31358575 62.32108696 62.32858814 62.33608930 62.34359041 62.35109150 62.35859256 62.36609358 62.37359458 62.38109554</listPositions>
				</positions>
				<positions axis="Omega" unit="deg">
					<commonPosition>29.4696</commonPosition>
				</positions>
				<positions axis="Phi" unit="deg">
					<commonPosition>-1.64</commonPosition>
				</positions>
				<positions axis="Psi" unit="deg">
					<commonPosition>0.12</commonPosition>
				</positions>
				<positions axis="X" unit="mm">
					<commonPosition>0.00</commonPosition>
				</positions>
				<positions axis="Y" unit="mm">
					<commonPosition>0.00</commonPosition>
				</positions>
				<positions axis="Z" unit="mm">
					<commonPosition>17.671</commonPosition>
				</positions>
				<commonCountingTime unit="seconds">2.00</commonCountingTime>
				<intensities unit="counts">1 1 0 0 0 0 0 0 0 0 0 1 0 1 1 1 0 1 0 1 0 1 1 1 2 0 0 1 0 2 1 0 0 0 1 0 0 2 0 0 1 0 0 2 0 1 0 1 3 0 1 0 1 1 4 1 2 0 0 0 2 1 1 0 1 0 0 1 1 0 1 0 2 0 1 3 2 1 0 0 0 0 1 2 0 0 0 0 2 2 1 2 0 0 0 2 0 1 1 0 1 0 0 1 0 0 0 2 1 1 0 3 0 1 0 0 1 0 1 0 1 0 0 1 0 1 1 0 0 2 0 0 3 2 0 0 0 0 3 1 1 0 0 1 0 0 0 0 0 1 0 3 0 0 1 0 2 0 1 1 1 0 1 1 1 0 0 0 0 0 2 0 0 2 0 0 1 0 1 0 0 2 0 0 3 3 2 1 1 0 1 0 0 2 1 2 1 0 3 1 0 0 1 1 0 1 1 0 1 0 3 0 0 0 1 0 0 0 0 0 0 0 3 1 0 0 1 0 3 0 0 0 3 0 1 1 1 2 0 1 2 0 0 0 2 0 0 1 1 1 0 0 1 2 1</intensities>
			</dataPoints>
		</scan>
		<scan appendNumber="0" mode="Continuous" scanAxis="2Theta" status="Completed">
			<header>
				<startTimeStamp>2012-06-16T00:27:36+02:00</startTimeStamp>
				<endTimeStamp>2012-06-16T00:27:39+02:00</endTimeStamp>
				<author>
					<name>Johannes Kepler Univ</name>
				</author>
				<source>
					<applicationSoftware version="2.2i">X'Pert Data Collector</applicationSoftware>
					<instrumentControlSoftware version="2.1E">XPERT-PRO</instrumentControlSoftware>
					<instrumentID>0000000011071750</instrumentID>
				</source>
			</header>
			<scanAxisCenter>
				<position axis="2Theta" unit="deg">61.4283</position>
			</scanAxisCenter>
			<dataPoints>
				<positions axis="2Theta" unit="deg">
					<listPositions>60.47550446 60.48300542 60.49050642 60.49800744 60.50550850 60.51300959 60.52051070 60.52801186 60.53551304 60.54301425 60.55051549 60.55801677 60.56551807 60.57301940 60.58052076 60.58802215 60.59552357 60.60302502 60.61052650 60.61802800 60.62552953 60.63303109 60.64053268 60.64803429 60.65553593 60.66303760 60.67053929 60.67804101 60.68554276 60.69304453 60.70054633 60.70804815 60.71554999 60.72305186 60.73055376 60.73805567 60.74555761 60.75305958 60.76056157 60.76806358 60.77556561 60.78306767 60.79056975 60.79807185 60.80557397 60.81307611 60.82057828 60.82808046 60.83558267 60.84308489 60.85058714 60.85808940 60.86559169 60.87309399 60.88059632 60.88809866 60.89560102 60.90310340 60.91060580 60.91810821 60.92561065 60.93311310 60.94061556 60.94811805 60.95562055 60.96312306 60.97062559 60.97812814 60.98563070 60.99313328 61.00063588 61.00813848 61.01564111 61.02314374 61.03064639 61.03814906 61.04565174 61.05315443 61.06065713 61.06815985 61.07566257 61.08316531 61.09066807 61.09817083 61.10567361 61.11317639 61.12067919 61.12818200 61.13568481 61.14318764 61.15069048 61.15819333 61.16569618 61.17319905 61.18070192 61.18820481 61.19570770 61.20321060 61.21071350 61.21821642 61.22571934 61.23322227 61.24072520 61.24822814 61.25573109 61.26323405 61.27073700 61.27823997 61.28574294 61.29324591 61.30074889 61.30825188 61.31575486 61.32325786 61.33076085 61.33826385 61.34576685 61.35326986 61.36077286 61.36827587 61.37577888 61.38328190 61.39078491 61.39828793 61.40579095 61.41329396 61.42079698 61.42830000 61.43580302 61.44330604 61.45080905 61.45831207 61.46581509 61.47331810 61.48082112 61.48832413 61.49582714 61.50333014 61.51083315 61.51833615 61.52583915 61.53334214 61.54084514 61.54834812 61.55585111 61.56335409 61.57085706 61.57836003 61.58586300 61.59336595 61.60086891 61.60837186 61.61587480 61.62337773 61.63088066 61.63838358 61.64588650 61.65338940 61.66089230 61.66839519 61.67589808 61.68340095 61.69090382 61.69840667 61.70590952 61.71341236 61.72091519 61.72841800 61.73592081 61.74342361 61.75092639 61.75842917 61.76593193 61.77343469 61.78093743 61.78844015 61.79594287 61.80344557 61.81094826 61.81845094 61.82595361 61.83345626 61.84095889 61.84846152 61.85596412 61.86346672 61.87096930 61.87847186 61.88597441 61.89347694 61.90097945 61.90848195 61.91598444 61.92348690 61.93098935 61.93849179 61.94599420 61.95349660 61.96099898 61.96850134 61.97600368 61.98350601 61.99100831 61.99851060 62.00601286 62.01351511 62.02101733 62.02851954 62.03602172 62.04352389 62.05102603 62.05852815 62.06603025 62.07353233 62.08103439 62.08853642 62.09603843 62.10354042 62.11104239 62.11854433 62.12604624 62.13354814 62.14105001 62.14855185 62.15605367 62.16355547 62.17105724 62.17855899 62.18606071 62.19356240 62.20106407 62.20856571 62.21606732 62.22356891 62.23107047 62.23857200 62.24607350 62.25357498 62.26107643 62.26857785 62.27607924 62.28358060 62.29108193 62.29858323 62.30608451 62.31358575 62.32108696 62.32858814 62.33608930 62.34359041 62.35109150 62.35859256 62.36609358 62.37359458 62.38109554</listPositions>
				</positions>
				<positions axis="Omega" unit="deg">
					<commonPosition>29.4746</commonPosition>
				</positions>
				<positions axis="Phi" unit="deg">
					<commonPosition>-1.64</commonPosition>
				</positions>
				<positions axis="Psi" unit="deg">
					<commonPosition>0.12</commonPosition>
				</positions>
				<positions axis="X" unit="mm">
					<commonPosition>0.00</commonPosition>
				</positions>
				<positions axis="Y" unit="mm">
					<commonPosition>0.00</commonPosition>
				</positions>
				<positions axis="Z" unit="mm">
					<commonPosition>17.671</commonPosition>
				</positions>
				<commonCountingTime unit="seconds">2.00</commonCountingTime>
				<intensities unit="counts">0 2 0 0 1 1 0 2 0 0 1 2 0 0 0 0 1 0 0 1 1 1 0 1 0 0 0 2 1 2 0 2 0 3 3 0 1 0 0 1 1 1 0 1 1 0 0 0 1 0 0 0 2 1 1 1 2 0 1 1 1 0 0 1 0 2 3 0 2 1 0 2 1 0 0 1 1 0 2 1 0 0 0 1 0 3 2 1 0 1 3 1 1 1 1 4 0 0 2 2 0 1 2 0 1 2 3 0 0 0 1 1 2 0 3 0 0 0 1 0 4 0 0 0 0 1 0 0 2 1 1 0 1 0 0 1 0 1 2 0 2 0 1 0 2 2 0 2 1 1 0 3 0 1 0 0 1 1 0 1 0 2 0 0 1 1 2 0 1 1 1 0 1 0 0 2 2 1 2 1 0 1 0 1 0 2 1 1 0 2 1 1 0 0 0 0 1 1 0 1 0 1 0 1 1 1 3 0 1 1 0 0 1 0 1 0 0 1 0 0 1 0 0 2 0 1 1 1 1 1 2 0 0 1 0 0 0 0 0 0 2 0 0 1 1 0 0 1 1 1 0 1 0 2 2</intensities>
			</dataPoints>
		</scan>
		<scan appendNumber="0" mode="Continuous" scanAxis="2Theta" status="Completed">
			<header>
				<startTimeStamp>2012-06-16T00:27:43+02:00</startTimeStamp>
				<endTimeStamp>2012-06-16T00:27:47+02:00</endTimeStamp>
				<author>
					<name>Johannes Kepler Univ</name>
				</author>
				<source>
					<applicationSoftware version="2.2i">X'Pert Data Collector</applicationSoftware>
					<instrumentControlSoftware version="2.1E">XPERT-PRO</instrumentControlSoftware>
					<instrumentID>0000000011071750</instrumentID>
				</source>
			</header>
			<scanAxisCenter>
				<position axis="2Theta" unit="deg">61.4283</position>
			</scanAxisCenter>
			<dataPoints>
				<positions axis="2Theta" unit="deg">
					<listPositions>60.47550446 60.48300542 60.49050642 60.49800744 60.50550850 60.51300959 60.52051070 60.52801186 60.53551304 60.54301425 60.55051549 60.55801677 60.56551807 60.57301940 60.58052076 60.58802215 60.59552357 60.60302502 60.61052650 60.61802800 60.62552953 60.63303109 60.64053268 60.64803429 60.65553593 60.66303760 60.67053929 60.67804101 60.68554276 60.69304453 60.70054633 60.70804815 60.71554999 60.72305186 60.73055376 60.73805567 60.74555761 60.75305958 60.76056157 60.76806358 60.77556561 60.78306767 60.79056975 60.79807185 60.80557397 60.81307611 60.82057828 60.82808046 60.83558267 60.84308489 60.85058714 60.85808940 60.86559169 60.87309399 60.88059632 60.88809866 60.89560102 60.90310340 60.91060580 60.91810821 60.92561065 60.93311310 60.94061556 60.94811805 60.95562055 60.96312306 60.97062559 60.97812814 60.98563070 60.99313328 61.00063588 61.00813848 61.01564111 61.02314374 61.03064639 61.03814906 61.04565174 61.05315443 61.06065713 61.06815985 61.07566257 61.08316531 61.09066807 61.09817083 61.10567361 61.11317639 61.12067919 61.12818200 61.13568481 61.14318764 61.15069048 61.15819333 61.16569618 61.17319905 61.18070192 61.18820481 61.19570770 61.20321060 61.21071350 61.21821642 61.22571934 61.23322227 61.24072520 61.24822814 61.25573109 61.26323405 61.27073700 61.27823997 61.28574294 61.29324591 61.30074889 61.30825188 61.31575486 61.32325786 61.33076085 61.33826385 61.34576685 61.35326986 61.36077286 61.36827587 61.37577888 61.38328190 61.39078491 61.39828793 61.40579095 61.41329396 61.42079698 61.42830000 61.43580302 61.44330604 61.45080905 61.45831207 61.46581509 61.47331810 61.48082112 61.48832413 61.49582714 61.50333014 61.51083315 61.51833615 61.52583915 61.53334214 61.54084514 61.54834812 61.55585111 61.56335409 61.57085706 61.57836003 61.58586300 61.59336595 61.60086891 61.60837186 61.61587480 61.62337773 61.63088066 61.63838358 61.64588650 61.65338940 61.66089230 61.66839519 61.67589808 61.68340095 61.69090382 61.69840667 61.70590952 61.71341236 61.72091519 61.72841800 61.73592081 61.74342361 61.75092639 61.75842917 61.76593193 61.77343469 61.78093743 61.78844015 61.79594287 61.80344557 61.81094826 61.81845094 61.82595361 61.83345626 61.84095889 61.84846152 61.85596412 61.86346672 61.87096930 61.87847186 61.88597441 61.89347694 61.90097945 61.90848195 61.91598444 61.92348690 61.93098935 61.93849179 61.94599420 61.95349660 61.96099898 61.96850134 61.97600368 61.98350601 61.99100831 61.99851060 62.00601286 62.01351511 62.02101733 62.02851954 62.03602172 62.04352389 62.05102603 62.05852815 62.06603025 62.07353233 62.08103439 62.08853642 62.09603843 62.10354042 62.11104239 62.11854433 62.12604624 62.13354814 62.14105001 62.14855185 62.15605367 62.16355547 62.17105724 62.17855899 62.18606071 62.19356240 62.20106407 62.20856571 62.21606732 62.22356891 62.23107047 62.23857200 62.24607350 62.25357498 62.26107643 62.26857785 62.27607924 62.28358060 62.29108193 62.29858323 62.30608451 62.31358575 62.32108696 62.32858814 62.33608930 62.34359041 62.35109150 62.35859256 62.36609358 62.37359458 62.38109554</listPositions>
				</positions>
				<positions axis="Omega" unit="deg">
					<commonPosition>29.4796</commonPosition>
				</positions>
				<positions axis="Phi" unit="deg">
					<commonPosition>-1.64</commonPosition>
				</positions>
				<positions axis="Psi" unit="deg">
					<commonPosition>0.12</commonPosition>
				</positions>
				<positions axis="X" unit="mm">
					<commonPosition>0.00</commonPosition>
				</positions>
				<positions axis="Y" unit="mm">
					<commonPosition>0.00</commonPosition>
				</positions>
				<positions axis="Z" unit="mm">
					<commonPosition>17.671</commonPosition>
				</positions>
				<commonCountingTime unit="seconds">2.00</commonCountingTime>
				<intensities unit="counts">0 2 1 0 1 2 1 1 1 0 1 1 0 0 1 0 3 0 1 0 1 0 0 0 0 0 1 0 0 2 1 2 2 0 1 0 1 0 0 2 0 0 0 1 1 0 0 0 1 3 1 0 2 0 2 0 0 1 0 2 1 1 0 0 0 1 2 1 1 0 1 1 1 0 0 1 0 0 2 0 1 0 2 1 0 1 0 0 0 2 0 0 0 2 0 0 0 1 0 1 3 1 2 1 0 0 1 0 0 1 0 0 1 0 2 1 1 0 0 2 0 2 4 0 0 0 0 0 1 1 1 0 1 0 1 0 0 1 1 0 2 0 0 1 0 0 1 1 0 0 0 1 0 1 2 0 0 0 0 0 0 0 0 1 0 0 2 0 0 0 1 0 0 1 2 0 0 1 2 1 0 1 0 0 1 0 2 0 1 1 0 1 1 0 0 1 0 1 1 2 0 0 1 0 1 0 0 0 0 1 0 0 0 1 1 1 0 0 0 1 0 1 0 0 2 3 0 2 1 0 0 0 2 0 0 0 1 1 1 1 0 1 0 0 2 0 0 0 0 0 0 1 2 1 0</intensities>
			</dataPoints>
		</scan>
		<scan appendNumber="0" mode="Continuous" scanAxis="2Theta" status="Completed">
			<header>
				<startTimeStamp>2012-06-16T00:27:51+02:00</startTimeStamp>
				<endTimeStamp>2012-06-16T00:27:54+02:00</endTimeStamp>
				<author>
					<name>Johannes Kepler Univ</name>
				</author>
				<source>
					<applicationSoftware version="2.2i">X'Pert Data Collector</applicationSoftware>
					<instrumentControlSoftware version="2.1E">XPERT-PRO</instrumentControlSoftware>
					<instrumentID>0000000011071750</instrumentID>
				</source>
			</header>
			<scanAxisCenter>
				<position axis="2Theta" unit="deg">61.4283</position>
			</scanAxisCenter>
			<dataPoints>
				<positions axis="2Theta" unit="deg">
					<listPositions>60.47550446 60.48300542 60.49050642 60.49800744 60.50550850 60.51300959 60.52051070 60.52801186 60.53551304 60.54301425 60.55051549 60.55801677 60.56551807 60.57301940 60.58052076 60.58802215 60.59552357 60.60302502 60.61052650 60.61802800 60.62552953 60.63303109 60.64053268 60.64803429 60.65553593 60.66303760 60.67053929 60.67804101 60.68554276 60.69304453 60.70054633 60.70804815 60.71554999 60.72305186 60.73055376 60.73805567 60.74555761 60.75305958 60.76056157 60.76806358 60.77556561 60.78306767 60.79056975 60.79807185 60.80557397 60.81307611 60.82057828 60.82808046 60.83558267 60.84308489 60.85058714 60.85808940 60.86559169 60.87309399 60.88059632 60.88809866 60.89560102 60.90310340 60.91060580 60.91810821 60.92561065 60.93311310 60.94061556 60.94811805 60.95562055 60.96312306 60.97062559 60.97812814 60.98563070 60.99313328 61.00063588 61.00813848 61.01564111 61.02314374 61.03064639 61.03814906 61.04565174 61.05315443 61.06065713 61.06815985 61.07566257 61.08316531 61.09066807 61.09817083 61.10567361 61.11317639 61.12067919 61.12818200 61.13568481 61.14318764 61.15069048 61.15819333 61.16569618 61.17319905 61.18070192 61.18820481 61.19570770 61.20321060 61.21071350 61.21821642 61.22571934 61.23322227 61.24072520 61.24822814 61.25573109 61.26323405 61.27073700 61.27823997 61.28574294 61.29324591 61.30074889 61.30825188 61.31575486 61.32325786 61.33076085 61.33826385 61.34576685 61.35326986 61.36077286 61.36827587 61.37577888 61.38328190 61.39078491 61.39828793 61.40579095 61.41329396 61.42079698 61.42830000 61.43580302 61.44330604 61.45080905 61.45831207 61.46581509 61.47331810 61.48082112 61.48832413 61.49582714 61.50333014 61.51083315 61.51833615 61.52583915 61.53334214 61.54084514 61.54834812 61.55585111 61.56335409 61.57085706 61.57836003 61.58586300 61.59336595 61.60086891 61.60837186 61.61587480 61.62337773 61.63088066 61.63838358 61.64588650 61.65338940 61.66089230 61.66839519 61.67589808 61.68340095 61.69090382 61.69840667 61.70590952 61.71341236 61.72091519 61.72841800 61.73592081 61.74342361 61.75092639 61.75842917 61.76593193 61.77343469 61.78093743 61.78844015 61.79594287 61.80344557 61.81094826 61.81845094 61.82595361 61.83345626 61.84095889 61.84846152 61.85596412 61.86346672 61.87096930 61.87847186 61.88597441 61.89347694 61.90097945 61.90848195 61.91598444 61.92348690 61.93098935 61.93849179 61.94599420 61.95349660 61.96099898 61.96850134 61.97600368 61.98350601 61.99100831 61.99851060 62.00601286 62.01351511 62.02101733 62.02851954 62.03602172 62.04352389 62.05102603 62.05852815 62.06603025 62.07353233 62.08103439 62.08853642 62.09603843 62.10354042 62.11104239 62.11854433 62.12604624 62.13354814 62.14105001 62.14855185 62.15605367 62.16355547 62.17105724 62.17855899 62.18606071 62.19356240 62.20106407 62.20856571 62.21606732 62.22356891 62.23107047 62.23857200 62.24607350 62.25357498 62.26107643 62.26857785 62.27607924 62.28358060 62.29108193 62.29858323 62.30608451 62.31358575 62.32108696 62.32858814 62.33608930 62.34359041 62.35109150 62.35859256 62.36609358 62.37359458 62.38109554</listPositions>
				</positions>
				<positions axis="Omega" unit="deg">
					<commonPosition>29.4846</commonPosition>
				</positions>
				<positions axis="Phi" unit="deg">
					<commonPosition>-1.64</commonPosition>
				</positions>
				<positions axis="Psi" unit="deg">
					<commonPosition>0.12</commonPosition>
				</positions>
				<positions axis="X" unit="mm">
					<commonPosition>0.00</commonPosition>
				</positions>
				<positions axis="Y" unit="mm">
					<commonPosition>0.00</commonPosition>
				</positions>
				<positions axis="Z" unit="mm">
					<commonPosition>17.671</commonPosition>
				</positions>
				<commonCountingTime unit="seconds">2.00</commonCountingTime>
				<intensities unit="counts">3 1 1 0 1 3 0 0 0 1 1 1 1 0 0 0 2 1 1 1 1 2 2 1 2 0 2 0 1 0 1 2 0 1 0 2 0 1 2 1 0 1 0 0 2 0 0 0 0 1 0 1 1 1 2 1 0 2 0 1 0 0 1 2 1 0 2 1 0 2 1 1 1 1 1 0 1 0 1 2 0 1 1 2 2 1 0 1 1 1 2 2 0 1 0 4 1 1 0 0 3 2 0 0 0 0 0 1 0 1 1 1 0 1 1 1 1 1 0 0 0 1 1 2 0 1 1 0 0 0 3 1 1 0 0 1 1 0 1 1 0 1 0 0 1 0 0 0 0 0 3 2 2 2 1 0 2 1 0 1 0 1 1 1 2 0 0 0 0 2 0 0 2 2 0 0 0 0 0 0 1 0 0 1 1 0 0 1 0 1 0 1 1 1 1 1 0 0 1 1 0 0 1 1 0 0 1 1 0 0 1 2 0 0 2 1 0 1 0 0 0 0 0 0 1 0 1 0 0 1 2 0 0 0 0 0 0 1 0 2 0 0 0 0 2 1 0 1 1 3 1 2 0 0 0</intensities>
			</dataPoints>
		</scan>
		<scan appendNumber="0" mode="Continuous" scanAxis="2Theta" status="Completed">
			<header>
				<startTimeStamp>2012-06-16T00:27:58+02:00</startTimeStamp>
				<endTimeStamp>2012-06-16T00:28:02+02:00</endTimeStamp>
				<author>
					<name>Johannes Kepler Univ</name>
				</author>
				<source>
					<applicationSoftware version="2.2i">X'Pert Data Collector</applicationSoftware>
					<instrumentControlSoftware version="2.1E">XPERT-PRO</instrumentControlSoftware>
					<instrumentID>0000000011071750</instrumentID>
				</source>
			</header>
			<scanAxisCenter>
				<position axis="2Theta" unit="deg">61.4283</position>
			</scanAxisCenter>
			<dataPoints>
				<positions axis="2Theta" unit="deg">
[...]
					<name>Johannes Kepler Univ</name>
				</author>
				<source>
					<applicationSoftware version="2.2i">X'Pert Data Collector</applicationSoftware>
					<instrumentControlSoftware version="2.1E">XPERT-PRO</instrumentControlSoftware>
					<instrumentID>0000000011071750</instrumentID>
				</source>
			</header>
			<scanAxisCenter>
				<position axis="2Theta" unit="deg">61.4283</position>
			</scanAxisCenter>
			<dataPoints>
				<positions axis="2Theta" unit="deg">
					<listPositions>60.47550446 60.48300542 60.49050642 60.49800744 60.50550850 60.51300959 60.52051070 60.52801186 60.53551304 60.54301425 60.55051549 60.55801677 60.56551807 60.57301940 60.58052076 60.58802215 60.59552357 60.60302502 60.61052650 60.61802800 60.62552953 60.63303109 60.64053268 60.64803429 60.65553593 60.66303760 60.67053929 60.67804101 60.68554276 60.69304453 60.70054633 60.70804815 60.71554999 60.72305186 60.73055376 60.73805567 60.74555761 60.75305958 60.76056157 60.76806358 60.77556561 60.78306767 60.79056975 60.79807185 60.80557397 60.81307611 60.82057828 60.82808046 60.83558267 60.84308489 60.85058714 60.85808940 60.86559169 60.87309399 60.88059632 60.88809866 60.89560102 60.90310340 60.91060580 60.91810821 60.92561065 60.93311310 60.94061556 60.94811805 60.95562055 60.96312306 60.97062559 60.97812814 60.98563070 60.99313328 61.00063588 61.00813848 61.01564111 61.02314374 61.03064639 61.03814906 61.04565174 61.05315443 61.06065713 61.06815985 61.07566257 61.08316531 61.09066807 61.09817083 61.10567361 61.11317639 61.12067919 61.12818200 61.13568481 61.14318764 61.15069048 61.15819333 61.16569618 61.17319905 61.18070192 61.18820481 61.19570770 61.20321060 61.21071350 61.21821642 61.22571934 61.23322227 61.24072520 61.24822814 61.25573109 61.26323405 61.27073700 61.27823997 61.28574294 61.29324591 61.30074889 61.30825188 61.31575486 61.32325786 61.33076085 61.33826385 61.34576685 61.35326986 61.36077286 61.36827587 61.37577888 61.38328190 61.39078491 61.39828793 61.40579095 61.41329396 61.42079698 61.42830000 61.43580302 61.44330604 61.45080905 61.45831207 61.46581509 61.47331810 61.48082112 61.48832413 61.49582714 61.50333014 61.51083315 61.51833615 61.52583915 61.53334214 61.54084514 61.54834812 61.55585111 61.56335409 61.57085706 61.57836003 61.58586300 61.59336595 61.60086891 61.60837186 61.61587480 61.62337773 61.63088066 61.63838358 61.64588650 61.65338940 61.66089230 61.66839519 61.67589808 61.68340095 61.69090382 61.69840667 61.70590952 61.71341236 61.72091519 61.72841800 61.73592081 61.74342361 61.75092639 61.75842917 61.76593193 61.77343469 61.78093743 61.78844015 61.79594287 61.80344557 61.81094826 61.81845094 61.82595361 61.83345626 61.84095889 61.84846152 61.85596412 61.86346672 61.87096930 61.87847186 61.88597441 61.89347694 61.90097945 61.90848195 61.91598444 61.92348690 61.93098935 61.93849179 61.94599420 61.95349660 61.96099898 61.96850134 61.97600368 61.98350601 61.99100831 61.99851060 62.00601286 62.01351511 62.02101733 62.02851954 62.03602172 62.04352389 62.05102603 62.05852815 62.06603025 62.07353233 62.08103439 62.08853642 62.09603843 62.10354042 62.11104239 62.11854433 62.12604624 62.13354814 62.14105001 62.14855185 62.15605367 62.16355547 62.17105724 62.17855899 62.18606071 62.19356240 62.20106407 62.20856571 62.21606732 62.22356891 62.23107047 62.23857200 62.24607350 62.25357498 62.26107643 62.26857785 62.27607924 62.28358060 62.29108193 62.29858323 62.30608451 62.31358575 62.32108696 62.32858814 62.33608930 62.34359041 62.35109150 62.35859256 62.36609358 62.37359458 62.38109554</listPositions>
				</positions>
				<positions axis="Omega" unit="deg">
					<commonPosition>31.4396</commonPosition>
				</positions>
				<positions axis="Phi" unit="deg">
					<commonPosition>-1.64</commonPosition>
				</positions>
				<positions axis="Psi" unit="deg">
					<commonPosition>0.12</commonPosition>
				</positions>
				<positions axis="X" unit="mm">
					<commonPosition>0.00</commonPosition>
				</positions>
				<positions axis="Y" unit="mm">
					<commonPosition>0.00</commonPosition>
				</positions>
				<positions axis="Z" unit="mm">
					<commonPosition>17.671</commonPosition>
				</positions>
				<commonCountingTime unit="seconds">2.00</commonCountingTime>
				<intensities unit="counts">1 0 0 0 0 1 3 0 0 0 0 1 1 1 1 1 1 1 0 2 0 1 2 1 1 0 0 2 1 1 1 0 2 1 0 0 0 1 1 0 0 1 1 1 1 2 1 0 0 1 1 1 0 0 0 1 0 1 1 0 2 1 1 1 0 1 1 1 0 0 1 2 2 0 2 2 0 2 0 3 0 0 1 3 0 1 1 3 3 0 0 0 1 3 0 0 1 0 1 1 1 4 0 1 0 1 0 0 1 1 0 0 2 1 1 1 2 1 3 1 1 3 0 0 1 0 3 0 0 1 1 0 0 0 0 1 0 1 1 0 1 0 0 1 1 2 0 1 1 2 1 1 0 1 1 1 3 0 0 1 0 1 1 2 2 1 1 0 0 1 1 1 0 1 1 2 0 0 0 3 0 1 1 0 0 3 1 1 2 1 2 0 2 0 1 2 0 0 2 1 1 1 2 1 0 0 0 0 1 1 1 0 0 0 0 1 1 1 2 1 2 0 0 1 0 0 0 0 0 1 0 0 2 0 0 0 0 2 0 1 1 2 0 0 0 0 0 0 0 0 1 1 0 0 2</intensities>
			</dataPoints>
		</scan>
		<scan appendNumber="0" mode="Continuous" scanAxis="2Theta" status="Completed">
			<header>
				<startTimeStamp>2012-06-16T01:23:05+02:00</startTimeStamp>
				<endTimeStamp>2012-06-16T01:23:09+02:00</endTimeStamp>
				<author>
					<name>Johannes Kepler Univ</name>
				</author>
				<source>
					<applicationSoftware version="2.2i">X'Pert Data Collector</applicationSoftware>
					<instrumentControlSoftware version="2.1E">XPERT-PRO</instrumentControlSoftware>
					<instrumentID>0000000011071750</instrumentID>
				</source>
			</header>
			<scanAxisCenter>
				<position axis="2Theta" unit="deg">61.4283</position>
			</scanAxisCenter>
			<dataPoints>
				<positions axis="2Theta" unit="deg">
					<listPositions>60.47550446 60.48300542 60.49050642 60.49800744 60.50550850 60.51300959 60.52051070 60.52801186 60.53551304 60.54301425 60.55051549 60.55801677 60.56551807 60.57301940 60.58052076 60.58802215 60.59552357 60.60302502 60.61052650 60.61802800 60.62552953 60.63303109 60.64053268 60.64803429 60.65553593 60.66303760 60.67053929 60.67804101 60.68554276 60.69304453 60.70054633 60.70804815 60.71554999 60.72305186 60.73055376 60.73805567 60.74555761 60.75305958 60.76056157 60.76806358 60.77556561 60.78306767 60.79056975 60.79807185 60.80557397 60.81307611 60.82057828 60.82808046 60.83558267 60.84308489 60.85058714 60.85808940 60.86559169 60.87309399 60.88059632 60.88809866 60.89560102 60.90310340 60.91060580 60.91810821 60.92561065 60.93311310 60.94061556 60.94811805 60.95562055 60.96312306 60.97062559 60.97812814 60.98563070 60.99313328 61.00063588 61.00813848 61.01564111 61.02314374 61.03064639 61.03814906 61.04565174 61.05315443 61.06065713 61.06815985 61.07566257 61.08316531 61.09066807 61.09817083 61.10567361 61.11317639 61.12067919 61.12818200 61.13568481 61.14318764 61.15069048 61.15819333 61.16569618 61.17319905 61.18070192 61.18820481 61.19570770 61.20321060 61.21071350 61.21821642 61.22571934 61.23322227 61.24072520 61.24822814 61.25573109 61.26323405 61.27073700 61.27823997 61.28574294 61.29324591 61.30074889 61.30825188 61.31575486 61.32325786 61.33076085 61.33826385 61.34576685 61.35326986 61.36077286 61.36827587 61.37577888 61.38328190 61.39078491 61.39828793 61.40579095 61.41329396 61.42079698 61.42830000 61.43580302 61.44330604 61.45080905 61.45831207 61.46581509 61.47331810 61.48082112 61.48832413 61.49582714 61.50333014 61.51083315 61.51833615 61.52583915 61.53334214 61.54084514 61.54834812 61.55585111 61.56335409 61.57085706 61.57836003 61.58586300 61.59336595 61.60086891 61.60837186 61.61587480 61.62337773 61.63088066 61.63838358 61.64588650 61.65338940 61.66089230 61.66839519 61.67589808 61.68340095 61.69090382 61.69840667 61.70590952 61.71341236 61.72091519 61.72841800 61.73592081 61.74342361 61.75092639 61.75842917 61.76593193 61.77343469 61.78093743 61.78844015 61.79594287 61.80344557 61.81094826 61.81845094 61.82595361 61.83345626 61.84095889 61.84846152 61.85596412 61.86346672 61.87096930 61.87847186 61.88597441 61.89347694 61.90097945 61.90848195 61.91598444 61.92348690 61.93098935 61.93849179 61.94599420 61.95349660 61.96099898 61.96850134 61.97600368 61.98350601 61.99100831 61.99851060 62.00601286 62.01351511 62.02101733 62.02851954 62.03602172 62.04352389 62.05102603 62.05852815 62.06603025 62.07353233 62.08103439 62.08853642 62.09603843 62.10354042 62.11104239 62.11854433 62.12604624 62.13354814 62.14105001 62.14855185 62.15605367 62.16355547 62.17105724 62.17855899 62.18606071 62.19356240 62.20106407 62.20856571 62.21606732 62.22356891 62.23107047 62.23857200 62.24607350 62.25357498 62.26107643 62.26857785 62.27607924 62.28358060 62.29108193 62.29858323 62.30608451 62.31358575 62.32108696 62.32858814 62.33608930 62.34359041 62.35109150 62.35859256 62.36609358 62.37359458 62.38109554</listPositions>
				</positions>
				<positions axis="Omega" unit="deg">
					<commonPosition>31.4446</commonPosition>
				</positions>
				<positions axis="Phi" unit="deg">
					<commonPosition>-1.64</commonPosition>
				</positions>
				<positions axis="Psi" unit="deg">
					<commonPosition>0.12</commonPosition>
				</positions>
				<positions axis="X" unit="mm">
					<commonPosition>0.00</commonPosition>
				</positions>
				<positions axis="Y" unit="mm">
					<commonPosition>0.00</commonPosition>
				</positions>
				<positions axis="Z" unit="mm">
					<commonPosition>17.671</commonPosition>
				</positions>
				<commonCountingTime unit="seconds">2.00</commonCountingTime>
				<intensities unit="counts">1 1 1 3 0 1 0 1 0 0 2 0 2 0 1 1 0 0 1 3 1 0 0 0 0 0 0 2 1 1 2 2 1 2 0 0 1 0 0 0 0 1 2 0 1 0 2 0 1 0 0 0 1 2 1 0 0 0 1 0 1 0 0 1 3 1 2 1 0 2 1 0 0 0 0 0 1 0 0 0 1 1 0 0 0 2 2 1 0 0 1 1 0 2 1 0 0 1 0 0 3 1 0 1 3 0 0 1 1 1 0 0 0 0 0 2 1 0 0 1 1 2 0 0 0 0 0 0 0 0 0 2 1 0 1 0 0 1 0 1 1 2 1 0 0 2 2 1 2 3 1 0 1 0 1 1 1 0 0 2 0 0 1 0 1 2 1 2 0 1 1 0 1 1 2 1 1 0 1 0 0 2 0 1 0 0 1 0 1 1 0 0 1 0 0 0 0 1 0 4 1 1 1 0 1 0 2 1 2 0 0 1 1 0 1 0 0 1 0 1 1 0 0 2 1 1 0 0 1 1 1 2 1 0 1 2 1 0 0 2 1 0 1 1 3 0 1 0 1 0 2 0 0 1 0</intensities>
			</dataPoints>
		</scan>
		<scan appendNumber="0" mode="Continuous" scanAxis="2Theta" status="Completed">
			<header>
				<startTimeStamp>2012-06-16T01:23:15+02:00</startTimeStamp>
				<endTimeStamp>2012-06-16T01:23:18+02:00</endTimeStamp>
				<author>
					<name>Johannes Kepler Univ</name>
				</author>
				<source>
					<applicationSoftware version="2.2i">X'Pert Data Collector</applicationSoftware>
					<instrumentControlSoftware version="2.1E">XPERT-PRO</instrumentControlSoftware>
					<instrumentID>0000000011071750</instrumentID>
				</source>
			</header>
			<scanAxisCenter>
				<position axis="2Theta" unit="deg">61.4283</position>
			</scanAxisCenter>
			<dataPoints>
				<positions axis="2Theta" unit="deg">
					<listPositions>60.47550446 60.48300542 60.49050642 60.49800744 60.50550850 60.51300959 60.52051070 60.52801186 60.53551304 60.54301425 60.55051549 60.55801677 60.56551807 60.57301940 60.58052076 60.58802215 60.59552357 60.60302502 60.61052650 60.61802800 60.62552953 60.63303109 60.64053268 60.64803429 60.65553593 60.66303760 60.67053929 60.67804101 60.68554276 60.69304453 60.70054633 60.70804815 60.71554999 60.72305186 60.73055376 60.73805567 60.74555761 60.75305958 60.76056157 60.76806358 60.77556561 60.78306767 60.79056975 60.79807185 60.80557397 60.81307611 60.82057828 60.82808046 60.83558267 60.84308489 60.85058714 60.85808940 60.86559169 60.87309399 60.88059632 60.88809866 60.89560102 60.90310340 60.91060580 60.91810821 60.92561065 60.93311310 60.94061556 60.94811805 60.95562055 60.96312306 60.97062559 60.97812814 60.98563070 60.99313328 61.00063588 61.00813848 61.01564111 61.02314374 61.03064639 61.03814906 61.04565174 61.05315443 61.06065713 61.06815985 61.07566257 61.08316531 61.09066807 61.09817083 61.10567361 61.11317639 61.12067919 61.12818200 61.13568481 61.14318764 61.15069048 61.15819333 61.16569618 61.17319905 61.18070192 61.18820481 61.19570770 61.20321060 61.21071350 61.21821642 61.22571934 61.23322227 61.24072520 61.24822814 61.25573109 61.26323405 61.27073700 61.27823997 61.28574294 61.29324591 61.30074889 61.30825188 61.31575486 61.32325786 61.33076085 61.33826385 61.34576685 61.35326986 61.36077286 61.36827587 61.37577888 61.38328190 61.39078491 61.39828793 61.40579095 61.41329396 61.42079698 61.42830000 61.43580302 61.44330604 61.45080905 61.45831207 61.46581509 61.47331810 61.48082112 61.48832413 61.49582714 61.50333014 61.51083315 61.51833615 61.52583915 61.53334214 61.54084514 61.54834812 61.55585111 61.56335409 61.57085706 61.57836003 61.58586300 61.59336595 61.60086891 61.60837186 61.61587480 61.62337773 61.63088066 61.63838358 61.64588650 61.65338940 61.66089230 61.66839519 61.67589808 61.68340095 61.69090382 61.69840667 61.70590952 61.71341236 61.72091519 61.72841800 61.73592081 61.74342361 61.75092639 61.75842917 61.76593193 61.77343469 61.78093743 61.78844015 61.79594287 61.80344557 61.81094826 61.81845094 61.82595361 61.83345626 61.84095889 61.84846152 61.85596412 61.86346672 61.87096930 61.87847186 61.88597441 61.89347694 61.90097945 61.90848195 61.91598444 61.92348690 61.93098935 61.93849179 61.94599420 61.95349660 61.96099898 61.96850134 61.97600368 61.98350601 61.99100831 61.99851060 62.00601286 62.01351511 62.02101733 62.02851954 62.03602172 62.04352389 62.05102603 62.05852815 62.06603025 62.07353233 62.08103439 62.08853642 62.09603843 62.10354042 62.11104239 62.11854433 62.12604624 62.13354814 62.14105001 62.14855185 62.15605367 62.16355547 62.17105724 62.17855899 62.18606071 62.19356240 62.20106407 62.20856571 62.21606732 62.22356891 62.23107047 62.23857200 62.24607350 62.25357498 62.26107643 62.26857785 62.27607924 62.28358060 62.29108193 62.29858323 62.30608451 62.31358575 62.32108696 62.32858814 62.33608930 62.34359041 62.35109150 62.35859256 62.36609358 62.37359458 62.38109554</listPositions>
				</positions>
				<positions axis="Omega" unit="deg">
					<commonPosition>31.4496</commonPosition>
				</positions>
				<positions axis="Phi" unit="deg">
					<commonPosition>-1.64</commonPosition>
				</positions>
				<positions axis="Psi" unit="deg">
					<commonPosition>0.12</commonPosition>
				</positions>
				<positions axis="X" unit="mm">
					<commonPosition>0.00</commonPosition>
				</positions>
				<positions axis="Y" unit="mm">
					<commonPosition>0.00</commonPosition>
				</positions>
				<positions axis="Z" unit="mm">
					<commonPosition>17.671</commonPosition>
				</positions>
				<commonCountingTime unit="seconds">2.00</commonCountingTime>
				<intensities unit="counts">1 1 2 0 1 0 1 0 1 1 1 0 0 1 1 0 1 1 0 0 0 0 2 0 2 1 0 0 0 2 1 1 1 0 2 2 0 0 1 0 1 0 0 0 0 1 2 1 1 1 1 0 0 1 2 0 1 1 0 0 1 1 1 0 1 2 0 0 0 1 1 1 0 1 2 3 1 3 0 1 1 1 1 0 2 2 1 0 0 0 1 0 1 2 0 0 1 0 2 1 0 2 1 0 1 0 0 1 1 1 1 2 0 0 0 0 3 0 1 0 1 1 2 0 0 0 1 2 0 0 2 0 1 0 1 0 1 1 2 1 1 1 1 1 0 0 1 0 0 2 1 2 0 0 0 1 3 3 0 1 0 2 0 0 1 1 1 1 1 0 0 0 0 1 1 2 0 1 2 2 3 1 4 0 0 2 1 0 1 3 0 0 0 0 2 0 1 0 0 0 0 0 1 0 1 0 1 0 0 0 1 4 2 0 0 2 1 0 0 2 1 0 0 0 1 0 0 0 1 0 1 2 1 0 1 0 2 0 2 0 1 1 0 2 0 0 3 2 1 0 0 0 2 0 1</intensities>
			</dataPoints>
		</scan>
		<scan appendNumber="0" mode="Continuous" scanAxis="2Theta" status="Completed">
			<header>
				<startTimeStamp>2012-06-16T01:23:24+02:00</startTimeStamp>
				<endTimeStamp>2012-06-16T01:23:27+02:00</endTimeStamp>
				<author>
					<name>Johannes Kepler Univ</name>
				</author>
				<source>
					<applicationSoftware version="2.2i">X'Pert Data Collector</applicationSoftware>
					<instrumentControlSoftware version="2.1E">XPERT-PRO</instrumentControlSoftware>
					<instrumentID>0000000011071750</instrumentID>
				</source>
			</header>
			<scanAxisCenter>
				<position axis="2Theta" unit="deg">61.4283</position>
			</scanAxisCenter>
			<dataPoints>
				<positions axis="2Theta" unit="deg">
					<listPositions>60.47550446 60.48300542 60.49050642 60.49800744 60.50550850 60.51300959 60.52051070 60.52801186 60.53551304 60.54301425 60.55051549 60.55801677 60.56551807 60.57301940 60.58052076 60.58802215 60.59552357 60.60302502 60.61052650 60.61802800 60.62552953 60.63303109 60.64053268 60.64803429 60.65553593 60.66303760 60.67053929 60.67804101 60.68554276 60.69304453 60.70054633 60.70804815 60.71554999 60.72305186 60.73055376 60.73805567 60.74555761 60.75305958 60.76056157 60.76806358 60.77556561 60.78306767 60.79056975 60.79807185 60.80557397 60.81307611 60.82057828 60.82808046 60.83558267 60.84308489 60.85058714 60.85808940 60.86559169 60.87309399 60.88059632 60.88809866 60.89560102 60.90310340 60.91060580 60.91810821 60.92561065 60.93311310 60.94061556 60.94811805 60.95562055 60.96312306 60.97062559 60.97812814 60.98563070 60.99313328 61.00063588 61.00813848 61.01564111 61.02314374 61.03064639 61.03814906 61.04565174 61.05315443 61.06065713 61.06815985 61.07566257 61.08316531 61.09066807 61.09817083 61.10567361 61.11317639 61.12067919 61.12818200 61.13568481 61.14318764 61.15069048 61.15819333 61.16569618 61.17319905 61.18070192 61.18820481 61.19570770 61.20321060 61.21071350 61.21821642 61.22571934 61.23322227 61.24072520 61.24822814 61.25573109 61.26323405 61.27073700 61.27823997 61.28574294 61.29324591 61.30074889 61.30825188 61.31575486 61.32325786 61.33076085 61.33826385 61.34576685 61.35326986 61.36077286 61.36827587 61.37577888 61.38328190 61.39078491 61.39828793 61.40579095 61.41329396 61.42079698 61.42830000 61.43580302 61.44330604 61.45080905 61.45831207 61.46581509 61.47331810 61.48082112 61.48832413 61.49582714 61.50333014 61.51083315 61.51833615 61.52583915 61.53334214 61.54084514 61.54834812 61.55585111 61.56335409 61.57085706 61.57836003 61.58586300 61.59336595 61.60086891 61.60837186 61.61587480 61.62337773 61.63088066 61.63838358 61.64588650 61.65338940 61.66089230 61.66839519 61.67589808 61.68340095 61.69090382 61.69840667 61.70590952 61.71341236 61.72091519 61.72841800 61.73592081 61.74342361 61.75092639 61.75842917 61.76593193 61.77343469 61.78093743 61.78844015 61.79594287 61.80344557 61.81094826 61.81845094 61.82595361 61.83345626 61.84095889 61.84846152 61.85596412 61.86346672 61.87096930 61.87847186 61.88597441 61.89347694 61.90097945 61.90848195 61.91598444 61.92348690 61.93098935 61.93849179 61.94599420 61.95349660 61.96099898 61.96850134 61.97600368 61.98350601 61.99100831 61.99851060 62.00601286 62.01351511 62.02101733 62.02851954 62.03602172 62.04352389 62.05102603 62.05852815 62.06603025 62.07353233 62.08103439 62.08853642 62.09603843 62.10354042 62.11104239 62.11854433 62.12604624 62.13354814 62.14105001 62.14855185 62.15605367 62.16355547 62.17105724 62.17855899 62.18606071 62.19356240 62.20106407 62.20856571 62.21606732 62.22356891 62.23107047 62.23857200 62.24607350 62.25357498 62.26107643 62.26857785 62.27607924 62.28358060 62.29108193 62.29858323 62.30608451 62.31358575 62.32108696 62.32858814 62.33608930 62.34359041 62.35109150 62.35859256 62.36609358 62.37359458 62.38109554</listPositions>
				</positions>
				<positions axis="Omega" unit="deg">
					<commonPosition>31.4546</commonPosition>
				</positions>
				<positions axis="Phi" unit="deg">
					<commonPosition>-1.64</commonPosition>
				</positions>
				<positions axis="Psi" unit="deg">
					<commonPosition>0.12</commonPosition>
				</positions>
				<positions axis="X" unit="mm">
					<commonPosition>0.00</commonPosition>
				</positions>
				<positions axis="Y" unit="mm">
					<commonPosition>0.00</commonPosition>
				</positions>
				<positions axis="Z" unit="mm">
					<commonPosition>17.671</commonPosition>
				</positions>
				<commonCountingTime unit="seconds">2.00</commonCountingTime>
				<intensities unit="counts">0 1 1 0 1 1 2 1 0 0 1 1 0 0 1 2 1 0 0 0 0 2 0 1 2 0 3 0 0 2 0 0 0 3 3 1 1 1 0 1 1 1 1 0 0 1 0 0 0 0 0 0 0 0 1 1 3 1 0 0 0 2 2 1 1 0 1 0 1 1 1 0 0 1 0 0 0 1 0 0 1 1 0 1 0 0 1 0 1 0 0 0 0 0 1 4 0 0 1 1 1 0 0 1 2 0 1 0 0 2 0 0 2 3 1 1 2 0 0 1 0 1 2 0 1 0 0 2 0 0 2 3 0 1 0 2 1 1 1 0 0 2 1 0 1 0 0 0 2 0 1 1 0 1 1 3 1 1 0 1 0 0 0 0 1 0 0 0 0 1 1 1 1 1 0 0 0 0 1 1 0 0 1 0 1 0 0 0 1 0 0 0 2 1 1 0 1 1 0 0 0 0 0 1 1 2 0 0 0 2 1 0 0 2 0 0 2 1 0 1 1 4 1 1 0 1 0 1 1 1 0 1 0 1 0 1 2 0 1 1 0 0 0 0 1 2 2 1 0 0 0 0 0 0 0</intensities>
			</dataPoints>
		</scan>
	</xrdMeasurement>
</xrdMeasurements>