File: examples/data/rsm_4.xrdml
<?xml version="1.0" encoding="UTF-8"?>
<xrdMeasurements xmlns="http://www.xrdml.com/XRDMeasurement/1.3" xmlns:xsi="http://www.w3.org/2001/XMLSchema-instance" xsi:schemaLocation="http://www.xrdml.com/XRDMeasurement/1.3 http://www.xrdml.com/XRDMeasurement/1.3/XRDMeasurement.xsd" status="Completed">
	<comment>
		<entry>Configuration=Factory configuration, Owner=User-1, Creation date=6/4/2010 10:23:02 AM</entry>
		<entry>Goniometer=PW3050/65 (Theta/2Theta); Minimum step size 2Theta:0.0001; Minimum step size Omega:0.0001</entry>
		<entry>Sample stage=MRD XL Cradle; Minimum step size Phi:0.01; Minimum step size Psi:0.01; Minimum step size X:0.01; Minimum step size Y:0.01; Minimum step size Z:0.001</entry>
		<entry>Diffractometer system=XPERT-PRO</entry>
		<entry>Measurement program=GreenSi_map_2deg2s, Owner=tanja, Creation date=3/19/2012 10:07:21 AM</entry>
		<entry>Fine Calibration Offset for 2Theta = -0.0192 deg</entry>
		<entry>Fine Calibration Offset for Omega = 0.1691 deg</entry>
		<entry>Batch program=Rastelli_XRR_XRD_short_period_sample5, Owner=tanja, Creation date=6/15/2012 3:39:26 PM</entry>
	</comment>
	<sample type="To be analyzed">
		<id></id>
		<name></name>
		<preparedBy></preparedBy>
	</sample>
	<xrdMeasurement measurementType="Area measurement" status="Completed" measurementStepAxis="Omega" sampleMode="Reflection">
		<comment>
			<entry/>
		</comment>
		<usedWavelength intended="K-Alpha 1">
			<kAlpha1 unit="Angstrom">1.5405980</kAlpha1>
			<kAlpha2 unit="Angstrom">1.5444260</kAlpha2>
			<kBeta unit="Angstrom">1.3922500</kBeta>
			<ratioKAlpha2KAlpha1>0.5000</ratioKAlpha2KAlpha1>
		</usedWavelength>
		<incidentBeamPath>
			<radius unit="mm">420.00</radius>
			<xRayTube id="1010048" name="PW3373/10 Cu LFF DK394719">
				<tension unit="kV">45</tension>
				<current unit="mA">40</current>
				<anodeMaterial>Cu</anodeMaterial>
				<focus type="Line">
					<length unit="mm">12.0</length>
					<width unit="mm">0.4</width>
					<takeOffAngle unit="deg">3.7</takeOffAngle>
				</focus>
			</xRayTube>
			<xRayMirror id="27090001" name="Inc. Beam Cu W/Si (hybrid MRD)" hybrid="true">
				<crystal type="Graded" shape="Parabolic">W/Si</crystal>
				<acceptanceAngle unit="deg">0.8</acceptanceAngle>
				<length unit="mm">60.0</length>
			</xRayMirror>
			<monochromator id="23090002" name="Inc. Beam 2xGe220 Cu Asym. (hybrid)" hybrid="true">
				<crystal type="Asymmetric" shape="Flat">Ge</crystal>
				<numberOfReflections>2</numberOfReflections>
				<hkl>
					<h>2</h>
					<k>2</k>
					<l>0</l>
				</hkl>
			</monochromator>
			<divergenceSlit id="22010009" name="Slit Fixed 1/16Â°" xsi:type="fixedDivergenceSlitType">
				<distanceToSample unit="mm">320.00</distanceToSample>
				<height unit="mm">0.10</height>
			</divergenceSlit>
		</incidentBeamPath>
		<sampleOffset>
			<position axis="2Theta" unit="deg">0.0000</position>
			<position axis="Omega" unit="deg">0.0000</position>
		</sampleOffset>
		<diffractedBeamPath>
			<radius unit="mm">420.00</radius>
			<antiScatterSlit id="22090014" name="AS Slit 5.0 mm (PIXcel non-ambient &amp; MRD)" xsi:type="fixedAntiScatterSlitType">
				<height unit="mm">5.00</height>
			</antiScatterSlit>
			<detector id="7010015" name="PIXcel" xsi:type="rtmsDetectorType">
				<phd>
					<lowerLevel unit="%">25.5</lowerLevel>
					<upperLevel unit="%">100.0</upperLevel>
				</phd>
				<mode>Static</mode>
				<activeLength unit="deg">1.9131</activeLength>
			</detector>
		</diffractedBeamPath>
		<measurementStepAxisCenter>
			<position axis="Omega" unit="deg">31.3546</position>
		</measurementStepAxisCenter>
		<scan appendNumber="0" mode="Continuous" scanAxis="2Theta" status="Completed">
			<header>
				<startTimeStamp>2012-06-15T23:30:06+02:00</startTimeStamp>
				<endTimeStamp>2012-06-15T23:30:10+02:00</endTimeStamp>
				<author>
					<name>Johannes Kepler Univ</name>
				</author>
				<source>
					<applicationSoftware version="2.2i">X'Pert Data Collector</applicationSoftware>
					<instrumentControlSoftware version="2.1E">XPERT-PRO</instrumentControlSoftware>
					<instrumentID>0000000011071750</instrumentID>
				</source>
			</header>
			<scanAxisCenter>
				<position axis="2Theta" unit="deg">63.2283</position>
			</scanAxisCenter>
			<dataPoints>
				<positions axis="2Theta" unit="deg">
					<listPositions>62.27550446 62.28300542 62.29050642 62.29800744 62.30550850 62.31300959 62.32051070 62.32801186 62.33551304 62.34301425 62.35051549 62.35801677 62.36551807 62.37301940 62.38052076 62.38802215 62.39552357 62.40302502 62.41052650 62.41802800 62.42552953 62.43303109 62.44053268 62.44803429 62.45553593 62.46303760 62.47053929 62.47804101 62.48554276 62.49304453 62.50054633 62.50804815 62.51554999 62.52305186 62.53055376 62.53805567 62.54555761 62.55305958 62.56056157 62.56806358 62.57556561 62.58306767 62.59056975 62.59807185 62.60557397 62.61307611 62.62057828 62.62808046 62.63558267 62.64308489 62.65058714 62.65808940 62.66559169 62.67309399 62.68059632 62.68809866 62.69560102 62.70310340 62.71060580 62.71810821 62.72561065 62.73311310 62.74061556 62.74811805 62.75562055 62.76312306 62.77062559 62.77812814 62.78563070 62.79313328 62.80063588 62.80813848 62.81564111 62.82314374 62.83064639 62.83814906 62.84565174 62.85315443 62.86065713 62.86815985 62.87566257 62.88316531 62.89066807 62.89817083 62.90567361 62.91317639 62.92067919 62.92818200 62.93568481 62.94318764 62.95069048 62.95819333 62.96569618 62.97319905 62.98070192 62.98820481 62.99570770 63.00321060 63.01071350 63.01821642 63.02571934 63.03322227 63.04072520 63.04822814 63.05573109 63.06323405 63.07073700 63.07823997 63.08574294 63.09324591 63.10074889 63.10825188 63.11575486 63.12325786 63.13076085 63.13826385 63.14576685 63.15326986 63.16077286 63.16827587 63.17577888 63.18328190 63.19078491 63.19828793 63.20579095 63.21329396 63.22079698 63.22830000 63.23580302 63.24330604 63.25080905 63.25831207 63.26581509 63.27331810 63.28082112 63.28832413 63.29582714 63.30333014 63.31083315 63.31833615 63.32583915 63.33334214 63.34084514 63.34834812 63.35585111 63.36335409 63.37085706 63.37836003 63.38586300 63.39336595 63.40086891 63.40837186 63.41587480 63.42337773 63.43088066 63.43838358 63.44588650 63.45338940 63.46089230 63.46839519 63.47589808 63.48340095 63.49090382 63.49840667 63.50590952 63.51341236 63.52091519 63.52841800 63.53592081 63.54342361 63.55092639 63.55842917 63.56593193 63.57343469 63.58093743 63.58844015 63.59594287 63.60344557 63.61094826 63.61845094 63.62595361 63.63345626 63.64095889 63.64846152 63.65596412 63.66346672 63.67096930 63.67847186 63.68597441 63.69347694 63.70097945 63.70848195 63.71598444 63.72348690 63.73098935 63.73849179 63.74599420 63.75349660 63.76099898 63.76850134 63.77600368 63.78350601 63.79100831 63.79851060 63.80601286 63.81351511 63.82101733 63.82851954 63.83602172 63.84352389 63.85102603 63.85852815 63.86603025 63.87353233 63.88103439 63.88853642 63.89603843 63.90354042 63.91104239 63.91854433 63.92604624 63.93354814 63.94105001 63.94855185 63.95605367 63.96355547 63.97105724 63.97855899 63.98606071 63.99356240 64.00106407 64.00856571 64.01606732 64.02356891 64.03107047 64.03857200 64.04607350 64.05357498 64.06107643 64.06857785 64.07607924 64.08358060 64.09108193 64.09858323 64.10608451 64.11358575 64.12108696 64.12858814 64.13608930 64.14359041 64.15109150 64.15859256 64.16609358 64.17359458 64.18109554</listPositions>
				</positions>
				<positions axis="Omega" unit="deg">
					<commonPosition>30.3546</commonPosition>
				</positions>
				<positions axis="Phi" unit="deg">
					<commonPosition>-1.64</commonPosition>
				</positions>
				<positions axis="Psi" unit="deg">
					<commonPosition>0.12</commonPosition>
				</positions>
				<positions axis="X" unit="mm">
					<commonPosition>0.00</commonPosition>
				</positions>
				<positions axis="Y" unit="mm">
					<commonPosition>0.00</commonPosition>
				</positions>
				<positions axis="Z" unit="mm">
					<commonPosition>17.671</commonPosition>
				</positions>
				<commonCountingTime unit="seconds">2.00</commonCountingTime>
				<intensities unit="counts">0 0 0 1 1 0 0 0 0 1 0 1 1 0 1 1 0 0 2 0 1 2 1 4 0 1 0 0 0 0 0 2 0 0 0 2 1 1 1 0 1 0 2 1 0 0 1 1 1 1 1 1 0 1 1 0 0 2 0 0 3 1 0 1 0 0 0 2 1 1 2 0 0 1 0 1 1 1 0 0 0 0 2 1 1 0 1 0 0 0 3 1 0 0 2 1 0 0 0 1 2 1 0 1 0 2 0 0 1 1 0 1 1 1 2 2 1 0 0 2 0 0 1 0 0 0 1 0 1 0 0 0 0 0 2 0 0 1 1 1 0 0 0 0 1 2 0 0 0 0 0 0 0 0 0 2 1 0 2 1 1 1 1 0 0 0 0 1 0 0 0 1 0 0 0 2 0 0 0 1 1 0 1 1 2 1 0 0 1 0 1 0 1 0 1 0 1 1 0 0 2 0 0 0 0 0 1 1 1 0 0 0 1 1 1 0 0 0 0 2 0 1 2 0 0 2 1 1 1 1 3 2 0 0 0 0 0 1 0 1 0 0 1 0 0 1 1 0 1 0 0 2 0 2 0</intensities>
			</dataPoints>
		</scan>
		<scan appendNumber="0" mode="Continuous" scanAxis="2Theta" status="Completed">
			<header>
				<startTimeStamp>2012-06-15T23:30:14+02:00</startTimeStamp>
				<endTimeStamp>2012-06-15T23:30:17+02:00</endTimeStamp>
				<author>
					<name>Johannes Kepler Univ</name>
				</author>
				<source>
					<applicationSoftware version="2.2i">X'Pert Data Collector</applicationSoftware>
					<instrumentControlSoftware version="2.1E">XPERT-PRO</instrumentControlSoftware>
					<instrumentID>0000000011071750</instrumentID>
				</source>
			</header>
			<scanAxisCenter>
				<position axis="2Theta" unit="deg">63.2283</position>
			</scanAxisCenter>
			<dataPoints>
				<positions axis="2Theta" unit="deg">
					<listPositions>62.27550446 62.28300542 62.29050642 62.29800744 62.30550850 62.31300959 62.32051070 62.32801186 62.33551304 62.34301425 62.35051549 62.35801677 62.36551807 62.37301940 62.38052076 62.38802215 62.39552357 62.40302502 62.41052650 62.41802800 62.42552953 62.43303109 62.44053268 62.44803429 62.45553593 62.46303760 62.47053929 62.47804101 62.48554276 62.49304453 62.50054633 62.50804815 62.51554999 62.52305186 62.53055376 62.53805567 62.54555761 62.55305958 62.56056157 62.56806358 62.57556561 62.58306767 62.59056975 62.59807185 62.60557397 62.61307611 62.62057828 62.62808046 62.63558267 62.64308489 62.65058714 62.65808940 62.66559169 62.67309399 62.68059632 62.68809866 62.69560102 62.70310340 62.71060580 62.71810821 62.72561065 62.73311310 62.74061556 62.74811805 62.75562055 62.76312306 62.77062559 62.77812814 62.78563070 62.79313328 62.80063588 62.80813848 62.81564111 62.82314374 62.83064639 62.83814906 62.84565174 62.85315443 62.86065713 62.86815985 62.87566257 62.88316531 62.89066807 62.89817083 62.90567361 62.91317639 62.92067919 62.92818200 62.93568481 62.94318764 62.95069048 62.95819333 62.96569618 62.97319905 62.98070192 62.98820481 62.99570770 63.00321060 63.01071350 63.01821642 63.02571934 63.03322227 63.04072520 63.04822814 63.05573109 63.06323405 63.07073700 63.07823997 63.08574294 63.09324591 63.10074889 63.10825188 63.11575486 63.12325786 63.13076085 63.13826385 63.14576685 63.15326986 63.16077286 63.16827587 63.17577888 63.18328190 63.19078491 63.19828793 63.20579095 63.21329396 63.22079698 63.22830000 63.23580302 63.24330604 63.25080905 63.25831207 63.26581509 63.27331810 63.28082112 63.28832413 63.29582714 63.30333014 63.31083315 63.31833615 63.32583915 63.33334214 63.34084514 63.34834812 63.35585111 63.36335409 63.37085706 63.37836003 63.38586300 63.39336595 63.40086891 63.40837186 63.41587480 63.42337773 63.43088066 63.43838358 63.44588650 63.45338940 63.46089230 63.46839519 63.47589808 63.48340095 63.49090382 63.49840667 63.50590952 63.51341236 63.52091519 63.52841800 63.53592081 63.54342361 63.55092639 63.55842917 63.56593193 63.57343469 63.58093743 63.58844015 63.59594287 63.60344557 63.61094826 63.61845094 63.62595361 63.63345626 63.64095889 63.64846152 63.65596412 63.66346672 63.67096930 63.67847186 63.68597441 63.69347694 63.70097945 63.70848195 63.71598444 63.72348690 63.73098935 63.73849179 63.74599420 63.75349660 63.76099898 63.76850134 63.77600368 63.78350601 63.79100831 63.79851060 63.80601286 63.81351511 63.82101733 63.82851954 63.83602172 63.84352389 63.85102603 63.85852815 63.86603025 63.87353233 63.88103439 63.88853642 63.89603843 63.90354042 63.91104239 63.91854433 63.92604624 63.93354814 63.94105001 63.94855185 63.95605367 63.96355547 63.97105724 63.97855899 63.98606071 63.99356240 64.00106407 64.00856571 64.01606732 64.02356891 64.03107047 64.03857200 64.04607350 64.05357498 64.06107643 64.06857785 64.07607924 64.08358060 64.09108193 64.09858323 64.10608451 64.11358575 64.12108696 64.12858814 64.13608930 64.14359041 64.15109150 64.15859256 64.16609358 64.17359458 64.18109554</listPositions>
				</positions>
				<positions axis="Omega" unit="deg">
					<commonPosition>30.3596</commonPosition>
				</positions>
				<positions axis="Phi" unit="deg">
					<commonPosition>-1.64</commonPosition>
				</positions>
				<positions axis="Psi" unit="deg">
					<commonPosition>0.12</commonPosition>
				</positions>
				<positions axis="X" unit="mm">
					<commonPosition>0.00</commonPosition>
				</positions>
				<positions axis="Y" unit="mm">
					<commonPosition>0.00</commonPosition>
				</positions>
				<positions axis="Z" unit="mm">
					<commonPosition>17.671</commonPosition>
				</positions>
				<commonCountingTime unit="seconds">2.00</commonCountingTime>
				<intensities unit="counts">1 1 1 0 1 2 0 1 2 0 0 0 1 0 1 0 3 1 2 0 0 1 2 0 0 1 2 0 0 0 1 0 1 1 1 0 3 0 1 2 0 1 0 2 0 1 0 1 1 1 1 1 1 0 1 2 0 2 0 0 0 2 2 1 0 1 3 0 0 0 1 2 2 1 0 0 1 1 1 2 1 2 1 2 0 1 2 0 0 1 1 1 3 3 0 4 0 1 0 1 1 0 2 0 0 0 0 3 0 1 1 1 0 1 0 0 1 2 0 0 0 2 1 0 1 0 2 0 0 0 2 0 1 1 0 1 0 0 0 0 1 0 2 0 0 0 2 0 0 0 0 0 1 1 1 2 0 0 0 1 0 1 1 1 1 2 1 2 1 0 0 0 0 0 1 1 2 0 2 1 0 2 2 0 2 2 0 1 1 1 0 1 1 1 3 0 0 0 2 2 2 0 2 2 0 0 1 1 0 1 0 0 0 0 0 1 2 1 0 1 1 0 3 0 1 1 1 1 0 0 0 1 1 0 1 0 0 1 0 2 1 1 0 2 2 2 0 0 0 1 1 2 0 0 0</intensities>
			</dataPoints>
		</scan>
		<scan appendNumber="0" mode="Continuous" scanAxis="2Theta" status="Completed">
			<header>
				<startTimeStamp>2012-06-15T23:30:22+02:00</startTimeStamp>
				<endTimeStamp>2012-06-15T23:30:26+02:00</endTimeStamp>
				<author>
					<name>Johannes Kepler Univ</name>
				</author>
				<source>
					<applicationSoftware version="2.2i">X'Pert Data Collector</applicationSoftware>
					<instrumentControlSoftware version="2.1E">XPERT-PRO</instrumentControlSoftware>
					<instrumentID>0000000011071750</instrumentID>
				</source>
			</header>
			<scanAxisCenter>
				<position axis="2Theta" unit="deg">63.2283</position>
			</scanAxisCenter>
			<dataPoints>
				<positions axis="2Theta" unit="deg">
					<listPositions>62.27550446 62.28300542 62.29050642 62.29800744 62.30550850 62.31300959 62.32051070 62.32801186 62.33551304 62.34301425 62.35051549 62.35801677 62.36551807 62.37301940 62.38052076 62.38802215 62.39552357 62.40302502 62.41052650 62.41802800 62.42552953 62.43303109 62.44053268 62.44803429 62.45553593 62.46303760 62.47053929 62.47804101 62.48554276 62.49304453 62.50054633 62.50804815 62.51554999 62.52305186 62.53055376 62.53805567 62.54555761 62.55305958 62.56056157 62.56806358 62.57556561 62.58306767 62.59056975 62.59807185 62.60557397 62.61307611 62.62057828 62.62808046 62.63558267 62.64308489 62.65058714 62.65808940 62.66559169 62.67309399 62.68059632 62.68809866 62.69560102 62.70310340 62.71060580 62.71810821 62.72561065 62.73311310 62.74061556 62.74811805 62.75562055 62.76312306 62.77062559 62.77812814 62.78563070 62.79313328 62.80063588 62.80813848 62.81564111 62.82314374 62.83064639 62.83814906 62.84565174 62.85315443 62.86065713 62.86815985 62.87566257 62.88316531 62.89066807 62.89817083 62.90567361 62.91317639 62.92067919 62.92818200 62.93568481 62.94318764 62.95069048 62.95819333 62.96569618 62.97319905 62.98070192 62.98820481 62.99570770 63.00321060 63.01071350 63.01821642 63.02571934 63.03322227 63.04072520 63.04822814 63.05573109 63.06323405 63.07073700 63.07823997 63.08574294 63.09324591 63.10074889 63.10825188 63.11575486 63.12325786 63.13076085 63.13826385 63.14576685 63.15326986 63.16077286 63.16827587 63.17577888 63.18328190 63.19078491 63.19828793 63.20579095 63.21329396 63.22079698 63.22830000 63.23580302 63.24330604 63.25080905 63.25831207 63.26581509 63.27331810 63.28082112 63.28832413 63.29582714 63.30333014 63.31083315 63.31833615 63.32583915 63.33334214 63.34084514 63.34834812 63.35585111 63.36335409 63.37085706 63.37836003 63.38586300 63.39336595 63.40086891 63.40837186 63.41587480 63.42337773 63.43088066 63.43838358 63.44588650 63.45338940 63.46089230 63.46839519 63.47589808 63.48340095 63.49090382 63.49840667 63.50590952 63.51341236 63.52091519 63.52841800 63.53592081 63.54342361 63.55092639 63.55842917 63.56593193 63.57343469 63.58093743 63.58844015 63.59594287 63.60344557 63.61094826 63.61845094 63.62595361 63.63345626 63.64095889 63.64846152 63.65596412 63.66346672 63.67096930 63.67847186 63.68597441 63.69347694 63.70097945 63.70848195 63.71598444 63.72348690 63.73098935 63.73849179 63.74599420 63.75349660 63.76099898 63.76850134 63.77600368 63.78350601 63.79100831 63.79851060 63.80601286 63.81351511 63.82101733 63.82851954 63.83602172 63.84352389 63.85102603 63.85852815 63.86603025 63.87353233 63.88103439 63.88853642 63.89603843 63.90354042 63.91104239 63.91854433 63.92604624 63.93354814 63.94105001 63.94855185 63.95605367 63.96355547 63.97105724 63.97855899 63.98606071 63.99356240 64.00106407 64.00856571 64.01606732 64.02356891 64.03107047 64.03857200 64.04607350 64.05357498 64.06107643 64.06857785 64.07607924 64.08358060 64.09108193 64.09858323 64.10608451 64.11358575 64.12108696 64.12858814 64.13608930 64.14359041 64.15109150 64.15859256 64.16609358 64.17359458 64.18109554</listPositions>
				</positions>
				<positions axis="Omega" unit="deg">
					<commonPosition>30.3646</commonPosition>
				</positions>
				<positions axis="Phi" unit="deg">
					<commonPosition>-1.64</commonPosition>
				</positions>
				<positions axis="Psi" unit="deg">
					<commonPosition>0.12</commonPosition>
				</positions>
				<positions axis="X" unit="mm">
					<commonPosition>0.00</commonPosition>
				</positions>
				<positions axis="Y" unit="mm">
					<commonPosition>0.00</commonPosition>
				</positions>
				<positions axis="Z" unit="mm">
					<commonPosition>17.671</commonPosition>
				</positions>
				<commonCountingTime unit="seconds">2.00</commonCountingTime>
				<intensities unit="counts">0 1 0 1 0 0 1 1 0 0 1 1 1 1 1 1 1 1 0 0 0 0 2 1 0 1 0 0 1 1 2 1 2 2 0 0 3 0 1 0 0 0 0 1 0 2 2 2 1 0 1 1 0 0 1 0 2 0 0 2 0 1 1 1 2 0 0 0 1 0 1 0 0 0 1 1 1 1 0 1 2 0 1 0 2 2 0 1 0 0 0 0 1 0 3 1 0 1 0 2 0 0 0 1 0 3 1 0 0 2 4 0 2 0 2 2 0 0 3 2 1 0 0 0 1 0 0 0 0 0 0 0 1 1 2 2 2 2 2 0 0 1 0 0 0 1 0 0 0 0 1 0 0 2 0 0 0 1 0 1 1 1 1 1 1 1 0 1 1 0 0 0 0 2 1 3 0 3 1 1 4 1 1 1 0 2 0 1 2 1 0 0 3 0 0 1 0 0 0 0 2 0 0 1 0 1 0 0 0 1 0 0 0 0 1 0 2 0 0 1 1 0 1 2 1 0 0 0 0 0 0 1 1 0 0 1 1 0 0 0 0 0 0 0 0 0 2 0 1 1 4 0 1 0 0</intensities>
			</dataPoints>
		</scan>
		<scan appendNumber="0" mode="Continuous" scanAxis="2Theta" status="Completed">
			<header>
				<startTimeStamp>2012-06-15T23:30:30+02:00</startTimeStamp>
				<endTimeStamp>2012-06-15T23:30:34+02:00</endTimeStamp>
				<author>
					<name>Johannes Kepler Univ</name>
				</author>
				<source>
					<applicationSoftware version="2.2i">X'Pert Data Collector</applicationSoftware>
					<instrumentControlSoftware version="2.1E">XPERT-PRO</instrumentControlSoftware>
					<instrumentID>0000000011071750</instrumentID>
				</source>
			</header>
			<scanAxisCenter>
				<position axis="2Theta" unit="deg">63.2283</position>
			</scanAxisCenter>
			<dataPoints>
				<positions axis="2Theta" unit="deg">
					<listPositions>62.27550446 62.28300542 62.29050642 62.29800744 62.30550850 62.31300959 62.32051070 62.32801186 62.33551304 62.34301425 62.35051549 62.35801677 62.36551807 62.37301940 62.38052076 62.38802215 62.39552357 62.40302502 62.41052650 62.41802800 62.42552953 62.43303109 62.44053268 62.44803429 62.45553593 62.46303760 62.47053929 62.47804101 62.48554276 62.49304453 62.50054633 62.50804815 62.51554999 62.52305186 62.53055376 62.53805567 62.54555761 62.55305958 62.56056157 62.56806358 62.57556561 62.58306767 62.59056975 62.59807185 62.60557397 62.61307611 62.62057828 62.62808046 62.63558267 62.64308489 62.65058714 62.65808940 62.66559169 62.67309399 62.68059632 62.68809866 62.69560102 62.70310340 62.71060580 62.71810821 62.72561065 62.73311310 62.74061556 62.74811805 62.75562055 62.76312306 62.77062559 62.77812814 62.78563070 62.79313328 62.80063588 62.80813848 62.81564111 62.82314374 62.83064639 62.83814906 62.84565174 62.85315443 62.86065713 62.86815985 62.87566257 62.88316531 62.89066807 62.89817083 62.90567361 62.91317639 62.92067919 62.92818200 62.93568481 62.94318764 62.95069048 62.95819333 62.96569618 62.97319905 62.98070192 62.98820481 62.99570770 63.00321060 63.01071350 63.01821642 63.02571934 63.03322227 63.04072520 63.04822814 63.05573109 63.06323405 63.07073700 63.07823997 63.08574294 63.09324591 63.10074889 63.10825188 63.11575486 63.12325786 63.13076085 63.13826385 63.14576685 63.15326986 63.16077286 63.16827587 63.17577888 63.18328190 63.19078491 63.19828793 63.20579095 63.21329396 63.22079698 63.22830000 63.23580302 63.24330604 63.25080905 63.25831207 63.26581509 63.27331810 63.28082112 63.28832413 63.29582714 63.30333014 63.31083315 63.31833615 63.32583915 63.33334214 63.34084514 63.34834812 63.35585111 63.36335409 63.37085706 63.37836003 63.38586300 63.39336595 63.40086891 63.40837186 63.41587480 63.42337773 63.43088066 63.43838358 63.44588650 63.45338940 63.46089230 63.46839519 63.47589808 63.48340095 63.49090382 63.49840667 63.50590952 63.51341236 63.52091519 63.52841800 63.53592081 63.54342361 63.55092639 63.55842917 63.56593193 63.57343469 63.58093743 63.58844015 63.59594287 63.60344557 63.61094826 63.61845094 63.62595361 63.63345626 63.64095889 63.64846152 63.65596412 63.66346672 63.67096930 63.67847186 63.68597441 63.69347694 63.70097945 63.70848195 63.71598444 63.72348690 63.73098935 63.73849179 63.74599420 63.75349660 63.76099898 63.76850134 63.77600368 63.78350601 63.79100831 63.79851060 63.80601286 63.81351511 63.82101733 63.82851954 63.83602172 63.84352389 63.85102603 63.85852815 63.86603025 63.87353233 63.88103439 63.88853642 63.89603843 63.90354042 63.91104239 63.91854433 63.92604624 63.93354814 63.94105001 63.94855185 63.95605367 63.96355547 63.97105724 63.97855899 63.98606071 63.99356240 64.00106407 64.00856571 64.01606732 64.02356891 64.03107047 64.03857200 64.04607350 64.05357498 64.06107643 64.06857785 64.07607924 64.08358060 64.09108193 64.09858323 64.10608451 64.11358575 64.12108696 64.12858814 64.13608930 64.14359041 64.15109150 64.15859256 64.16609358 64.17359458 64.18109554</listPositions>
				</positions>
				<positions axis="Omega" unit="deg">
					<commonPosition>30.3696</commonPosition>
				</positions>
				<positions axis="Phi" unit="deg">
					<commonPosition>-1.64</commonPosition>
				</positions>
				<positions axis="Psi" unit="deg">
					<commonPosition>0.12</commonPosition>
				</positions>
				<positions axis="X" unit="mm">
					<commonPosition>0.00</commonPosition>
				</positions>
				<positions axis="Y" unit="mm">
					<commonPosition>0.00</commonPosition>
				</positions>
				<positions axis="Z" unit="mm">
					<commonPosition>17.671</commonPosition>
				</positions>
				<commonCountingTime unit="seconds">2.00</commonCountingTime>
				<intensities unit="counts">0 3 3 0 1 1 0 0 1 1 1 0 1 1 1 0 1 0 0 1 1 0 3 0 0 2 0 2 1 0 0 0 2 1 2 0 0 1 1 0 0 0 1 0 0 0 1 1 1 1 2 3 1 4 1 0 1 2 0 1 0 0 2 0 1 3 0 0 1 0 1 1 1 1 1 1 1 1 2 2 2 1 2 1 0 1 0 1 1 0 1 0 1 0 1 2 0 1 1 0 1 0 0 1 0 0 0 0 0 1 0 1 0 1 1 0 0 2 0 0 0 0 1 1 3 0 2 2 1 0 0 0 0 1 2 1 1 2 0 3 1 2 1 1 1 1 1 1 2 1 0 1 0 1 1 0 1 1 0 0 0 0 0 1 0 2 0 1 0 4 0 1 0 0 0 1 0 3 0 1 0 0 1 1 1 1 1 2 0 2 1 1 0 0 0 2 0 0 0 0 0 1 0 2 1 2 0 0 1 0 2 0 2 0 0 2 0 1 0 1 1 3 1 0 1 0 2 1 0 1 0 0 1 2 1 2 1 1 2 0 0 0 1 0 1 1 1 2 3 0 0 1 4 0 0</intensities>
			</dataPoints>
		</scan>
		<scan appendNumber="0" mode="Continuous" scanAxis="2Theta" status="Completed">
			<header>
				<startTimeStamp>2012-06-15T23:30:38+02:00</startTimeStamp>
				<endTimeStamp>2012-06-15T23:30:41+02:00</endTimeStamp>
				<author>
					<name>Johannes Kepler Univ</name>
				</author>
				<source>
					<applicationSoftware version="2.2i">X'Pert Data Collector</applicationSoftware>
					<instrumentControlSoftware version="2.1E">XPERT-PRO</instrumentControlSoftware>
					<instrumentID>0000000011071750</instrumentID>
				</source>
			</header>
			<scanAxisCenter>
				<position axis="2Theta" unit="deg">63.2283</position>
			</scanAxisCenter>
			<dataPoints>
				<positions axis="2Theta" unit="deg">
					<listPositions>62.27550446 62.28300542 62.29050642 62.29800744 62.30550850 62.31300959 62.32051070 62.32801186 62.33551304 62.34301425 62.35051549 62.35801677 62.36551807 62.37301940 62.38052076 62.38802215 62.39552357 62.40302502 62.41052650 62.41802800 62.42552953 62.43303109 62.44053268 62.44803429 62.45553593 62.46303760 62.47053929 62.47804101 62.48554276 62.49304453 62.50054633 62.50804815 62.51554999 62.52305186 62.53055376 62.53805567 62.54555761 62.55305958 62.56056157 62.56806358 62.57556561 62.58306767 62.59056975 62.59807185 62.60557397 62.61307611 62.62057828 62.62808046 62.63558267 62.64308489 62.65058714 62.65808940 62.66559169 62.67309399 62.68059632 62.68809866 62.69560102 62.70310340 62.71060580 62.71810821 62.72561065 62.73311310 62.74061556 62.74811805 62.75562055 62.76312306 62.77062559 62.77812814 62.78563070 62.79313328 62.80063588 62.80813848 62.81564111 62.82314374 62.83064639 62.83814906 62.84565174 62.85315443 62.86065713 62.86815985 62.87566257 62.88316531 62.89066807 62.89817083 62.90567361 62.91317639 62.92067919 62.92818200 62.93568481 62.94318764 62.95069048 62.95819333 62.96569618 62.97319905 62.98070192 62.98820481 62.99570770 63.00321060 63.01071350 63.01821642 63.02571934 63.03322227 63.04072520 63.04822814 63.05573109 63.06323405 63.07073700 63.07823997 63.08574294 63.09324591 63.10074889 63.10825188 63.11575486 63.12325786 63.13076085 63.13826385 63.14576685 63.15326986 63.16077286 63.16827587 63.17577888 63.18328190 63.19078491 63.19828793 63.20579095 63.21329396 63.22079698 63.22830000 63.23580302 63.24330604 63.25080905 63.25831207 63.26581509 63.27331810 63.28082112 63.28832413 63.29582714 63.30333014 63.31083315 63.31833615 63.32583915 63.33334214 63.34084514 63.34834812 63.35585111 63.36335409 63.37085706 63.37836003 63.38586300 63.39336595 63.40086891 63.40837186 63.41587480 63.42337773 63.43088066 63.43838358 63.44588650 63.45338940 63.46089230 63.46839519 63.47589808 63.48340095 63.49090382 63.49840667 63.50590952 63.51341236 63.52091519 63.52841800 63.53592081 63.54342361 63.55092639 63.55842917 63.56593193 63.57343469 63.58093743 63.58844015 63.59594287 63.60344557 63.61094826 63.61845094 63.62595361 63.63345626 63.64095889 63.64846152 63.65596412 63.66346672 63.67096930 63.67847186 63.68597441 63.69347694 63.70097945 63.70848195 63.71598444 63.72348690 63.73098935 63.73849179 63.74599420 63.75349660 63.76099898 63.76850134 63.77600368 63.78350601 63.79100831 63.79851060 63.80601286 63.81351511 63.82101733 63.82851954 63.83602172 63.84352389 63.85102603 63.85852815 63.86603025 63.87353233 63.88103439 63.88853642 63.89603843 63.90354042 63.91104239 63.91854433 63.92604624 63.93354814 63.94105001 63.94855185 63.95605367 63.96355547 63.97105724 63.97855899 63.98606071 63.99356240 64.00106407 64.00856571 64.01606732 64.02356891 64.03107047 64.03857200 64.04607350 64.05357498 64.06107643 64.06857785 64.07607924 64.08358060 64.09108193 64.09858323 64.10608451 64.11358575 64.12108696 64.12858814 64.13608930 64.14359041 64.15109150 64.15859256 64.16609358 64.17359458 64.18109554</listPositions>
				</positions>
				<positions axis="Omega" unit="deg">
					<commonPosition>30.3746</commonPosition>
				</positions>
				<positions axis="Phi" unit="deg">
					<commonPosition>-1.64</commonPosition>
				</positions>
				<positions axis="Psi" unit="deg">
					<commonPosition>0.12</commonPosition>
				</positions>
				<positions axis="X" unit="mm">
					<commonPosition>0.00</commonPosition>
				</positions>
				<positions axis="Y" unit="mm">
					<commonPosition>0.00</commonPosition>
				</positions>
				<positions axis="Z" unit="mm">
					<commonPosition>17.671</commonPosition>
				</positions>
				<commonCountingTime unit="seconds">2.00</commonCountingTime>
				<intensities unit="counts">0 0 1 3 0 0 0 0 1 0 0 1 2 1 0 2 0 2 0 2 0 1 1 0 1 0 1 0 1 4 1 0 3 0 0 1 0 2 1 0 1 0 1 1 0 0 0 0 1 0 1 2 1 0 0 0 1 1 0 0 0 0 0 0 1 0 2 0 0 0 0 1 0 1 1 1 0 0 1 1 1 0 0 0 2 0 1 0 0 1 1 0 0 3 1 0 1 1 1 1 0 1 2 1 0 0 0 0 0 0 0 0 1 0 0 4 0 2 1 1 1 2 0 0 0 6 6 4 2 0 1 1 1 1 1 3 0 2 3 2 1 0 0 0 0 0 1 0 1 1 0 0 0 1 0 0 3 0 1 0 0 1 1 1 1 0 0 1 1 1 0 2 0 1 0 1 1 1 0 1 1 1 0 0 1 0 0 1 0 1 0 2 2 2 1 0 0 0 0 0 0 2 0 0 1 1 0 0 3 0 0 0 1 0 1 0 1 0 1 1 2 1 0 2 0 1 1 0 0 1 0 1 1 0 0 0 0 1 0 2 1 1 1 0 0 0 0 0 0 0 2 2 0 0 1</intensities>
			</dataPoints>
		</scan>
		<scan appendNumber="0" mode="Continuous" scanAxis="2Theta" status="Completed">
			<header>
				<startTimeStamp>2012-06-15T23:30:45+02:00</startTimeStamp>
				<endTimeStamp>2012-06-15T23:30:49+02:00</endTimeStamp>
				<author>
					<name>Johannes Kepler Univ</name>
				</author>
				<source>
					<applicationSoftware version="2.2i">X'Pert Data Collector</applicationSoftware>
					<instrumentControlSoftware version="2.1E">XPERT-PRO</instrumentControlSoftware>
					<instrumentID>0000000011071750</instrumentID>
				</source>
			</header>
			<scanAxisCenter>
				<position axis="2Theta" unit="deg">63.2283</position>
			</scanAxisCenter>
			<dataPoints>
				<positions axis="2Theta" unit="deg">
					<listPositions>62.27550446 62.28300542 62.29050642 62.29800744 62.30550850 62.31300959 62.32051070 62.32801186 62.33551304 62.34301425 62.35051549 62.35801677 62.36551807 62.37301940 62.38052076 62.38802215 62.39552357 62.40302502 62.41052650 62.41802800 62.42552953 62.43303109 62.44053268 62.44803429 62.45553593 62.46303760 62.47053929 62.47804101 62.48554276 62.49304453 62.50054633 62.50804815 62.51554999 62.52305186 62.53055376 62.53805567 62.54555761 62.55305958 62.56056157 62.56806358 62.57556561 62.58306767 62.59056975 62.59807185 62.60557397 62.61307611 62.62057828 62.62808046 62.63558267 62.64308489 62.65058714 62.65808940 62.66559169 62.67309399 62.68059632 62.68809866 62.69560102 62.70310340 62.71060580 62.71810821 62.72561065 62.73311310 62.74061556 62.74811805 62.75562055 62.76312306 62.77062559 62.77812814 62.78563070 62.79313328 62.80063588 62.80813848 62.81564111 62.82314374 62.83064639 62.83814906 62.84565174 62.85315443 62.86065713 62.86815985 62.87566257 62.88316531 62.89066807 62.89817083 62.90567361 62.91317639 62.92067919 62.92818200 62.93568481 62.94318764 62.95069048 62.95819333 62.96569618 62.97319905 62.98070192 62.98820481 62.99570770 63.00321060 63.01071350 63.01821642 63.02571934 63.03322227 63.04072520 63.04822814 63.05573109 63.06323405 63.07073700 63.07823997 63.08574294 63.09324591 63.10074889 63.10825188 63.11575486 63.12325786 63.13076085 63.13826385 63.14576685 63.15326986 63.16077286 63.16827587 63.17577888 63.18328190 63.19078491 63.19828793 63.20579095 63.21329396 63.22079698 63.22830000 63.23580302 63.24330604 63.25080905 63.25831207 63.26581509 63.27331810 63.28082112 63.28832413 63.29582714 63.30333014 63.31083315 63.31833615 63.32583915 63.33334214 63.34084514 63.34834812 63.35585111 63.36335409 63.37085706 63.37836003 63.38586300 63.39336595 63.40086891 63.40837186 63.41587480 63.42337773 63.43088066 63.43838358 63.44588650 63.45338940 63.46089230 63.46839519 63.47589808 63.48340095 63.49090382 63.49840667 63.50590952 63.51341236 63.52091519 63.52841800 63.53592081 63.54342361 63.55092639 63.55842917 63.56593193 63.57343469 63.58093743 63.58844015 63.59594287 63.60344557 63.61094826 63.61845094 63.62595361 63.63345626 63.64095889 63.64846152 63.65596412 63.66346672 63.67096930 63.67847186 63.68597441 63.69347694 63.70097945 63.70848195 63.71598444 63.72348690 63.73098935 63.73849179 63.74599420 63.75349660 63.76099898 63.76850134 63.77600368 63.78350601 63.79100831 63.79851060 63.80601286 63.81351511 63.82101733 63.82851954 63.83602172 63.84352389 63.85102603 63.85852815 63.86603025 63.87353233 63.88103439 63.88853642 63.89603843 63.90354042 63.91104239 63.91854433 63.92604624 63.93354814 63.94105001 63.94855185 63.95605367 63.96355547 63.97105724 63.97855899 63.98606071 63.99356240 64.00106407 64.00856571 64.01606732 64.02356891 64.03107047 64.03857200 64.04607350 64.05357498 64.06107643 64.06857785 64.07607924 64.08358060 64.09108193 64.09858323 64.10608451 64.11358575 64.12108696 64.12858814 64.13608930 64.14359041 64.15109150 64.15859256 64.16609358 64.17359458 64.18109554</listPositions>
				</positions>
				<positions axis="Omega" unit="deg">
					<commonPosition>30.3796</commonPosition>
				</positions>
				<positions axis="Phi" unit="deg">
					<commonPosition>-1.64</commonPosition>
				</positions>
				<positions axis="Psi" unit="deg">
					<commonPosition>0.12</commonPosition>
				</positions>
				<positions axis="X" unit="mm">
					<commonPosition>0.00</commonPosition>
				</positions>
				<positions axis="Y" unit="mm">
					<commonPosition>0.00</commonPosition>
				</positions>
				<positions axis="Z" unit="mm">
					<commonPosition>17.671</commonPosition>
				</positions>
				<commonCountingTime unit="seconds">2.00</commonCountingTime>
				<intensities unit="counts">3 1 2 1 1 0 0 0 1 1 0 1 0 1 0 0 1 2 0 0 1 0 2 2 3 1 0 2 1 0 1 0 0 1 1 0 1 0 1 0 2 1 0 2 1 0 0 0 1 1 1 0 0 1 1 1 0 1 0 0 1 1 0 0 2 1 3 0 0 1 0 1 0 1 1 0 1 1 1 0 1 0 3 0 0 0 1 0 1 0 1 0 0 4 3 0 0 0 0 1 0 1 0 1 0 0 0 0 2 2 1 2 2 1 0 2 2 0 0 0 1 1 0 3 1 1 2 0 0 3 1 2 2 2 0 0 0 1 0 0 0 3 0 0 1 1 2 0 0 1 1 1 0 0 0 0 0 0 0 0 2 1 1 1 0 2 1 0 3 1 1 0 1 2 0 3 0 2 4 1 1 2 1 3 2 0 0 0 0 1 1 0 0 1 1 0 0 0 2 1 2 1 2 0 0 1 0 0 1 0 1 0 0 0 2 0 1 0 0 0 1 0 3 0 1 2 0 0 5 0 0 1 0 0 1 2 0 0 1 0 0 0 0 2 1 0 0 0 0 0 0 0 0 1 1</intensities>
			</dataPoints>
		</scan>
		<scan appendNumber="0" mode="Continuous" scanAxis="2Theta" status="Completed">
			<header>
				<startTimeStamp>2012-06-15T23:30:53+02:00</startTimeStamp>
				<endTimeStamp>2012-06-15T23:30:56+02:00</endTimeStamp>
				<author>
					<name>Johannes Kepler Univ</name>
				</author>
				<source>
					<applicationSoftware version="2.2i">X'Pert Data Collector</applicationSoftware>
					<instrumentControlSoftware version="2.1E">XPERT-PRO</instrumentControlSoftware>
					<instrumentID>0000000011071750</instrumentID>
				</source>
			</header>
			<scanAxisCenter>
				<position axis="2Theta" unit="deg">63.2283</position>
			</scanAxisCenter>
			<dataPoints>
				<positions axis="2Theta" unit="deg">
					<listPositions>62.27550446 62.28300542 62.29050642 62.29800744 62.30550850 62.31300959 62.32051070 62.32801186 62.33551304 62.34301425 62.35051549 62.35801677 62.36551807 62.37301940 62.38052076 62.38802215 62.39552357 62.40302502 62.41052650 62.41802800 62.42552953 62.43303109 62.44053268 62.44803429 62.45553593 62.46303760 62.47053929 62.47804101 62.48554276 62.49304453 62.50054633 62.50804815 62.51554999 62.52305186 62.53055376 62.53805567 62.54555761 62.55305958 62.56056157 62.56806358 62.57556561 62.58306767 62.59056975 62.59807185 62.60557397 62.61307611 62.62057828 62.62808046 62.63558267 62.64308489 62.65058714 62.65808940 62.66559169 62.67309399 62.68059632 62.68809866 62.69560102 62.70310340 62.71060580 62.71810821 62.72561065 62.73311310 62.74061556 62.74811805 62.75562055 62.76312306 62.77062559 62.77812814 62.78563070 62.79313328 62.80063588 62.80813848 62.81564111 62.82314374 62.83064639 62.83814906 62.84565174 62.85315443 62.86065713 62.86815985 62.87566257 62.88316531 62.89066807 62.89817083 62.90567361 62.91317639 62.92067919 62.92818200 62.93568481 62.94318764 62.95069048 62.95819333 62.96569618 62.97319905 62.98070192 62.98820481 62.99570770 63.00321060 63.01071350 63.01821642 63.02571934 63.03322227 63.04072520 63.04822814 63.05573109 63.06323405 63.07073700 63.07823997 63.08574294 63.09324591 63.10074889 63.10825188 63.11575486 63.12325786 63.13076085 63.13826385 63.14576685 63.15326986 63.16077286 63.16827587 63.17577888 63.18328190 63.19078491 63.19828793 63.20579095 63.21329396 63.22079698 63.22830000 63.23580302 63.24330604 63.25080905 63.25831207 63.26581509 63.27331810 63.28082112 63.28832413 63.29582714 63.30333014 63.31083315 63.31833615 63.32583915 63.33334214 63.34084514 63.34834812 63.35585111 63.36335409 63.37085706 63.37836003 63.38586300 63.39336595 63.40086891 63.40837186 63.41587480 63.42337773 63.43088066 63.43838358 63.44588650 63.45338940 63.46089230 63.46839519 63.47589808 63.48340095 63.49090382 63.49840667 63.50590952 63.51341236 63.52091519 63.52841800 63.53592081 63.54342361 63.55092639 63.55842917 63.56593193 63.57343469 63.58093743 63.58844015 63.59594287 63.60344557 63.61094826 63.61845094 63.62595361 63.63345626 63.64095889 63.64846152 63.65596412 63.66346672 63.67096930 63.67847186 63.68597441 63.69347694 63.70097945 63.70848195 63.71598444 63.72348690 63.73098935 63.73849179 63.74599420 63.75349660 63.76099898 63.76850134 63.77600368 63.78350601 63.79100831 63.79851060 63.80601286 63.81351511 63.82101733 63.82851954 63.83602172 63.84352389 63.85102603 63.85852815 63.86603025 63.87353233 63.88103439 63.88853642 63.89603843 63.90354042 63.91104239 63.91854433 63.92604624 63.93354814 63.94105001 63.94855185 63.95605367 63.96355547 63.97105724 63.97855899 63.98606071 63.99356240 64.00106407 64.00856571 64.01606732 64.02356891 64.03107047 64.03857200 64.04607350 64.05357498 64.06107643 64.06857785 64.07607924 64.08358060 64.09108193 64.09858323 64.10608451 64.11358575 64.12108696 64.12858814 64.13608930 64.14359041 64.15109150 64.15859256 64.16609358 64.17359458 64.18109554</listPositions>
				</positions>
				<positions axis="Omega" unit="deg">
					<commonPosition>30.3846</commonPosition>
				</positions>
				<positions axis="Phi" unit="deg">
					<commonPosition>-1.64</commonPosition>
				</positions>
				<positions axis="Psi" unit="deg">
					<commonPosition>0.12</commonPosition>
				</positions>
				<positions axis="X" unit="mm">
					<commonPosition>0.00</commonPosition>
				</positions>
				<positions axis="Y" unit="mm">
					<commonPosition>0.00</commonPosition>
				</positions>
				<positions axis="Z" unit="mm">
					<commonPosition>17.671</commonPosition>
				</positions>
				<commonCountingTime unit="seconds">2.00</commonCountingTime>
				<intensities unit="counts">1 1 0 1 0 1 2 2 0 0 1 1 3 0 0 1 0 1 1 1 2 0 2 2 2 0 1 1 2 1 2 2 0 1 1 0 0 2 0 2 2 1 1 0 1 0 0 0 0 2 0 0 1 0 1 0 0 1 4 3 0 0 0 1 1 0 0 2 1 1 1 4 1 0 0 1 1 0 0 2 2 0 1 0 2 0 1 1 1 2 1 0 3 1 0 1 1 1 1 0 1 0 2 0 1 1 0 1 2 0 1 0 3 1 2 2 2 0 0 1 1 1 1 1 0 1 0 0 2 2 2 0 0 0 0 0 0 2 1 0 0 0 2 0 2 1 1 2 1 0 0 0 1 0 1 0 1 0 1 0 0 2 0 0 0 1 1 0 0 1 2 0 0 1 1 1 0 0 0 1 1 1 0 1 0 1 4 0 0 3 0 0 2 2 0 2 1 3 1 1 1 0 0 0 0 2 2 2 0 0 2 1 0 0 0 0 0 2 1 1 0 1 0 0 2 0 0 0 1 3 1 1 0 2 0 0 2 0 0 1 0 0 0 0 1 0 0 1 0 1 1 1 0 1 1</intensities>
			</dataPoints>
		</scan>
		<scan appendNumber="0" mode="Continuous" scanAxis="2Theta" status="Completed">
			<header>
				<startTimeStamp>2012-06-15T23:31:01+02:00</startTimeStamp>
				<endTimeStamp>2012-06-15T23:31:04+02:00</endTimeStamp>
				<author>
					<name>Johannes Kepler Univ</name>
				</author>
				<source>
					<applicationSoftware version="2.2i">X'Pert Data Collector</applicationSoftware>
					<instrumentControlSoftware version="2.1E">XPERT-PRO</instrumentControlSoftware>
					<instrumentID>0000000011071750</instrumentID>
				</source>
			</header>
			<scanAxisCenter>
				<position axis="2Theta" unit="deg">63.2283</position>
			</scanAxisCenter>
			<dataPoints>
				<positions axis="2Theta" unit="deg">
[...]
					<name>Johannes Kepler Univ</name>
				</author>
				<source>
					<applicationSoftware version="2.2i">X'Pert Data Collector</applicationSoftware>
					<instrumentControlSoftware version="2.1E">XPERT-PRO</instrumentControlSoftware>
					<instrumentID>0000000011071750</instrumentID>
				</source>
			</header>
			<scanAxisCenter>
				<position axis="2Theta" unit="deg">63.2283</position>
			</scanAxisCenter>
			<dataPoints>
				<positions axis="2Theta" unit="deg">
					<listPositions>62.27550446 62.28300542 62.29050642 62.29800744 62.30550850 62.31300959 62.32051070 62.32801186 62.33551304 62.34301425 62.35051549 62.35801677 62.36551807 62.37301940 62.38052076 62.38802215 62.39552357 62.40302502 62.41052650 62.41802800 62.42552953 62.43303109 62.44053268 62.44803429 62.45553593 62.46303760 62.47053929 62.47804101 62.48554276 62.49304453 62.50054633 62.50804815 62.51554999 62.52305186 62.53055376 62.53805567 62.54555761 62.55305958 62.56056157 62.56806358 62.57556561 62.58306767 62.59056975 62.59807185 62.60557397 62.61307611 62.62057828 62.62808046 62.63558267 62.64308489 62.65058714 62.65808940 62.66559169 62.67309399 62.68059632 62.68809866 62.69560102 62.70310340 62.71060580 62.71810821 62.72561065 62.73311310 62.74061556 62.74811805 62.75562055 62.76312306 62.77062559 62.77812814 62.78563070 62.79313328 62.80063588 62.80813848 62.81564111 62.82314374 62.83064639 62.83814906 62.84565174 62.85315443 62.86065713 62.86815985 62.87566257 62.88316531 62.89066807 62.89817083 62.90567361 62.91317639 62.92067919 62.92818200 62.93568481 62.94318764 62.95069048 62.95819333 62.96569618 62.97319905 62.98070192 62.98820481 62.99570770 63.00321060 63.01071350 63.01821642 63.02571934 63.03322227 63.04072520 63.04822814 63.05573109 63.06323405 63.07073700 63.07823997 63.08574294 63.09324591 63.10074889 63.10825188 63.11575486 63.12325786 63.13076085 63.13826385 63.14576685 63.15326986 63.16077286 63.16827587 63.17577888 63.18328190 63.19078491 63.19828793 63.20579095 63.21329396 63.22079698 63.22830000 63.23580302 63.24330604 63.25080905 63.25831207 63.26581509 63.27331810 63.28082112 63.28832413 63.29582714 63.30333014 63.31083315 63.31833615 63.32583915 63.33334214 63.34084514 63.34834812 63.35585111 63.36335409 63.37085706 63.37836003 63.38586300 63.39336595 63.40086891 63.40837186 63.41587480 63.42337773 63.43088066 63.43838358 63.44588650 63.45338940 63.46089230 63.46839519 63.47589808 63.48340095 63.49090382 63.49840667 63.50590952 63.51341236 63.52091519 63.52841800 63.53592081 63.54342361 63.55092639 63.55842917 63.56593193 63.57343469 63.58093743 63.58844015 63.59594287 63.60344557 63.61094826 63.61845094 63.62595361 63.63345626 63.64095889 63.64846152 63.65596412 63.66346672 63.67096930 63.67847186 63.68597441 63.69347694 63.70097945 63.70848195 63.71598444 63.72348690 63.73098935 63.73849179 63.74599420 63.75349660 63.76099898 63.76850134 63.77600368 63.78350601 63.79100831 63.79851060 63.80601286 63.81351511 63.82101733 63.82851954 63.83602172 63.84352389 63.85102603 63.85852815 63.86603025 63.87353233 63.88103439 63.88853642 63.89603843 63.90354042 63.91104239 63.91854433 63.92604624 63.93354814 63.94105001 63.94855185 63.95605367 63.96355547 63.97105724 63.97855899 63.98606071 63.99356240 64.00106407 64.00856571 64.01606732 64.02356891 64.03107047 64.03857200 64.04607350 64.05357498 64.06107643 64.06857785 64.07607924 64.08358060 64.09108193 64.09858323 64.10608451 64.11358575 64.12108696 64.12858814 64.13608930 64.14359041 64.15109150 64.15859256 64.16609358 64.17359458 64.18109554</listPositions>
				</positions>
				<positions axis="Omega" unit="deg">
					<commonPosition>32.3396</commonPosition>
				</positions>
				<positions axis="Phi" unit="deg">
					<commonPosition>-1.64</commonPosition>
				</positions>
				<positions axis="Psi" unit="deg">
					<commonPosition>0.12</commonPosition>
				</positions>
				<positions axis="X" unit="mm">
					<commonPosition>0.00</commonPosition>
				</positions>
				<positions axis="Y" unit="mm">
					<commonPosition>0.00</commonPosition>
				</positions>
				<positions axis="Z" unit="mm">
					<commonPosition>17.671</commonPosition>
				</positions>
				<commonCountingTime unit="seconds">2.00</commonCountingTime>
				<intensities unit="counts">1 2 0 1 4 0 2 0 0 2 3 1 2 1 0 0 0 0 1 3 1 2 2 0 0 0 1 1 2 1 0 1 1 2 0 1 1 1 0 0 1 0 0 1 2 2 0 0 0 1 3 0 0 1 2 0 1 1 0 1 0 0 0 3 0 1 1 1 2 0 1 0 1 1 0 1 0 2 1 1 1 0 1 2 0 0 0 0 1 0 1 1 0 0 1 0 1 3 1 0 0 0 0 1 1 1 1 1 1 0 1 1 2 1 0 2 2 3 0 0 0 0 1 2 1 0 1 0 1 1 1 1 0 0 0 0 1 1 2 0 1 0 1 1 2 1 2 1 1 1 0 0 2 2 1 1 0 0 1 0 0 0 3 1 0 0 1 0 0 0 0 0 0 1 1 0 0 1 2 0 0 0 0 0 1 1 0 2 2 0 0 2 1 0 0 1 0 1 1 0 1 1 1 1 0 0 1 2 3 2 1 0 0 1 1 2 0 1 0 0 0 2 0 0 0 0 0 0 0 1 0 1 0 0 0 0 0 0 2 0 0 1 0 2 0 2 0 1 0 0 0 1 0 0 0</intensities>
			</dataPoints>
		</scan>
		<scan appendNumber="0" mode="Continuous" scanAxis="2Theta" status="Completed">
			<header>
				<startTimeStamp>2012-06-16T00:26:18+02:00</startTimeStamp>
				<endTimeStamp>2012-06-16T00:26:21+02:00</endTimeStamp>
				<author>
					<name>Johannes Kepler Univ</name>
				</author>
				<source>
					<applicationSoftware version="2.2i">X'Pert Data Collector</applicationSoftware>
					<instrumentControlSoftware version="2.1E">XPERT-PRO</instrumentControlSoftware>
					<instrumentID>0000000011071750</instrumentID>
				</source>
			</header>
			<scanAxisCenter>
				<position axis="2Theta" unit="deg">63.2283</position>
			</scanAxisCenter>
			<dataPoints>
				<positions axis="2Theta" unit="deg">
					<listPositions>62.27550446 62.28300542 62.29050642 62.29800744 62.30550850 62.31300959 62.32051070 62.32801186 62.33551304 62.34301425 62.35051549 62.35801677 62.36551807 62.37301940 62.38052076 62.38802215 62.39552357 62.40302502 62.41052650 62.41802800 62.42552953 62.43303109 62.44053268 62.44803429 62.45553593 62.46303760 62.47053929 62.47804101 62.48554276 62.49304453 62.50054633 62.50804815 62.51554999 62.52305186 62.53055376 62.53805567 62.54555761 62.55305958 62.56056157 62.56806358 62.57556561 62.58306767 62.59056975 62.59807185 62.60557397 62.61307611 62.62057828 62.62808046 62.63558267 62.64308489 62.65058714 62.65808940 62.66559169 62.67309399 62.68059632 62.68809866 62.69560102 62.70310340 62.71060580 62.71810821 62.72561065 62.73311310 62.74061556 62.74811805 62.75562055 62.76312306 62.77062559 62.77812814 62.78563070 62.79313328 62.80063588 62.80813848 62.81564111 62.82314374 62.83064639 62.83814906 62.84565174 62.85315443 62.86065713 62.86815985 62.87566257 62.88316531 62.89066807 62.89817083 62.90567361 62.91317639 62.92067919 62.92818200 62.93568481 62.94318764 62.95069048 62.95819333 62.96569618 62.97319905 62.98070192 62.98820481 62.99570770 63.00321060 63.01071350 63.01821642 63.02571934 63.03322227 63.04072520 63.04822814 63.05573109 63.06323405 63.07073700 63.07823997 63.08574294 63.09324591 63.10074889 63.10825188 63.11575486 63.12325786 63.13076085 63.13826385 63.14576685 63.15326986 63.16077286 63.16827587 63.17577888 63.18328190 63.19078491 63.19828793 63.20579095 63.21329396 63.22079698 63.22830000 63.23580302 63.24330604 63.25080905 63.25831207 63.26581509 63.27331810 63.28082112 63.28832413 63.29582714 63.30333014 63.31083315 63.31833615 63.32583915 63.33334214 63.34084514 63.34834812 63.35585111 63.36335409 63.37085706 63.37836003 63.38586300 63.39336595 63.40086891 63.40837186 63.41587480 63.42337773 63.43088066 63.43838358 63.44588650 63.45338940 63.46089230 63.46839519 63.47589808 63.48340095 63.49090382 63.49840667 63.50590952 63.51341236 63.52091519 63.52841800 63.53592081 63.54342361 63.55092639 63.55842917 63.56593193 63.57343469 63.58093743 63.58844015 63.59594287 63.60344557 63.61094826 63.61845094 63.62595361 63.63345626 63.64095889 63.64846152 63.65596412 63.66346672 63.67096930 63.67847186 63.68597441 63.69347694 63.70097945 63.70848195 63.71598444 63.72348690 63.73098935 63.73849179 63.74599420 63.75349660 63.76099898 63.76850134 63.77600368 63.78350601 63.79100831 63.79851060 63.80601286 63.81351511 63.82101733 63.82851954 63.83602172 63.84352389 63.85102603 63.85852815 63.86603025 63.87353233 63.88103439 63.88853642 63.89603843 63.90354042 63.91104239 63.91854433 63.92604624 63.93354814 63.94105001 63.94855185 63.95605367 63.96355547 63.97105724 63.97855899 63.98606071 63.99356240 64.00106407 64.00856571 64.01606732 64.02356891 64.03107047 64.03857200 64.04607350 64.05357498 64.06107643 64.06857785 64.07607924 64.08358060 64.09108193 64.09858323 64.10608451 64.11358575 64.12108696 64.12858814 64.13608930 64.14359041 64.15109150 64.15859256 64.16609358 64.17359458 64.18109554</listPositions>
				</positions>
				<positions axis="Omega" unit="deg">
					<commonPosition>32.3446</commonPosition>
				</positions>
				<positions axis="Phi" unit="deg">
					<commonPosition>-1.64</commonPosition>
				</positions>
				<positions axis="Psi" unit="deg">
					<commonPosition>0.12</commonPosition>
				</positions>
				<positions axis="X" unit="mm">
					<commonPosition>0.00</commonPosition>
				</positions>
				<positions axis="Y" unit="mm">
					<commonPosition>0.00</commonPosition>
				</positions>
				<positions axis="Z" unit="mm">
					<commonPosition>17.671</commonPosition>
				</positions>
				<commonCountingTime unit="seconds">2.00</commonCountingTime>
				<intensities unit="counts">2 0 3 1 3 1 0 1 1 0 1 1 0 1 0 1 0 0 3 2 0 0 2 2 0 0 0 0 1 0 0 2 1 1 0 0 0 0 0 0 0 3 0 3 0 0 0 1 2 0 2 1 0 1 0 1 2 0 1 1 1 0 0 0 2 1 1 1 1 1 2 0 0 0 2 1 3 0 1 1 2 1 0 0 0 0 3 0 1 0 1 1 0 1 0 0 0 0 2 0 0 1 0 0 3 1 1 0 2 0 1 1 0 2 1 0 0 1 2 0 2 0 1 0 0 0 0 0 1 1 1 1 0 0 1 1 1 0 0 0 1 0 0 0 0 1 0 0 0 0 0 1 0 0 0 0 0 0 0 0 0 2 1 2 1 1 2 1 0 0 0 2 0 2 2 0 1 0 0 0 1 0 1 0 0 0 1 1 0 2 0 1 2 0 0 2 0 0 0 1 1 0 1 1 0 0 0 1 1 1 0 0 0 0 4 0 0 0 0 0 0 1 1 0 1 0 0 0 1 1 1 0 0 1 2 1 1 0 0 1 1 0 1 0 0 0 0 1 0 0 0 1 1 0 1</intensities>
			</dataPoints>
		</scan>
		<scan appendNumber="0" mode="Continuous" scanAxis="2Theta" status="Completed">
			<header>
				<startTimeStamp>2012-06-16T00:26:27+02:00</startTimeStamp>
				<endTimeStamp>2012-06-16T00:26:31+02:00</endTimeStamp>
				<author>
					<name>Johannes Kepler Univ</name>
				</author>
				<source>
					<applicationSoftware version="2.2i">X'Pert Data Collector</applicationSoftware>
					<instrumentControlSoftware version="2.1E">XPERT-PRO</instrumentControlSoftware>
					<instrumentID>0000000011071750</instrumentID>
				</source>
			</header>
			<scanAxisCenter>
				<position axis="2Theta" unit="deg">63.2283</position>
			</scanAxisCenter>
			<dataPoints>
				<positions axis="2Theta" unit="deg">
					<listPositions>62.27550446 62.28300542 62.29050642 62.29800744 62.30550850 62.31300959 62.32051070 62.32801186 62.33551304 62.34301425 62.35051549 62.35801677 62.36551807 62.37301940 62.38052076 62.38802215 62.39552357 62.40302502 62.41052650 62.41802800 62.42552953 62.43303109 62.44053268 62.44803429 62.45553593 62.46303760 62.47053929 62.47804101 62.48554276 62.49304453 62.50054633 62.50804815 62.51554999 62.52305186 62.53055376 62.53805567 62.54555761 62.55305958 62.56056157 62.56806358 62.57556561 62.58306767 62.59056975 62.59807185 62.60557397 62.61307611 62.62057828 62.62808046 62.63558267 62.64308489 62.65058714 62.65808940 62.66559169 62.67309399 62.68059632 62.68809866 62.69560102 62.70310340 62.71060580 62.71810821 62.72561065 62.73311310 62.74061556 62.74811805 62.75562055 62.76312306 62.77062559 62.77812814 62.78563070 62.79313328 62.80063588 62.80813848 62.81564111 62.82314374 62.83064639 62.83814906 62.84565174 62.85315443 62.86065713 62.86815985 62.87566257 62.88316531 62.89066807 62.89817083 62.90567361 62.91317639 62.92067919 62.92818200 62.93568481 62.94318764 62.95069048 62.95819333 62.96569618 62.97319905 62.98070192 62.98820481 62.99570770 63.00321060 63.01071350 63.01821642 63.02571934 63.03322227 63.04072520 63.04822814 63.05573109 63.06323405 63.07073700 63.07823997 63.08574294 63.09324591 63.10074889 63.10825188 63.11575486 63.12325786 63.13076085 63.13826385 63.14576685 63.15326986 63.16077286 63.16827587 63.17577888 63.18328190 63.19078491 63.19828793 63.20579095 63.21329396 63.22079698 63.22830000 63.23580302 63.24330604 63.25080905 63.25831207 63.26581509 63.27331810 63.28082112 63.28832413 63.29582714 63.30333014 63.31083315 63.31833615 63.32583915 63.33334214 63.34084514 63.34834812 63.35585111 63.36335409 63.37085706 63.37836003 63.38586300 63.39336595 63.40086891 63.40837186 63.41587480 63.42337773 63.43088066 63.43838358 63.44588650 63.45338940 63.46089230 63.46839519 63.47589808 63.48340095 63.49090382 63.49840667 63.50590952 63.51341236 63.52091519 63.52841800 63.53592081 63.54342361 63.55092639 63.55842917 63.56593193 63.57343469 63.58093743 63.58844015 63.59594287 63.60344557 63.61094826 63.61845094 63.62595361 63.63345626 63.64095889 63.64846152 63.65596412 63.66346672 63.67096930 63.67847186 63.68597441 63.69347694 63.70097945 63.70848195 63.71598444 63.72348690 63.73098935 63.73849179 63.74599420 63.75349660 63.76099898 63.76850134 63.77600368 63.78350601 63.79100831 63.79851060 63.80601286 63.81351511 63.82101733 63.82851954 63.83602172 63.84352389 63.85102603 63.85852815 63.86603025 63.87353233 63.88103439 63.88853642 63.89603843 63.90354042 63.91104239 63.91854433 63.92604624 63.93354814 63.94105001 63.94855185 63.95605367 63.96355547 63.97105724 63.97855899 63.98606071 63.99356240 64.00106407 64.00856571 64.01606732 64.02356891 64.03107047 64.03857200 64.04607350 64.05357498 64.06107643 64.06857785 64.07607924 64.08358060 64.09108193 64.09858323 64.10608451 64.11358575 64.12108696 64.12858814 64.13608930 64.14359041 64.15109150 64.15859256 64.16609358 64.17359458 64.18109554</listPositions>
				</positions>
				<positions axis="Omega" unit="deg">
					<commonPosition>32.3496</commonPosition>
				</positions>
				<positions axis="Phi" unit="deg">
					<commonPosition>-1.64</commonPosition>
				</positions>
				<positions axis="Psi" unit="deg">
					<commonPosition>0.12</commonPosition>
				</positions>
				<positions axis="X" unit="mm">
					<commonPosition>0.00</commonPosition>
				</positions>
				<positions axis="Y" unit="mm">
					<commonPosition>0.00</commonPosition>
				</positions>
				<positions axis="Z" unit="mm">
					<commonPosition>17.671</commonPosition>
				</positions>
				<commonCountingTime unit="seconds">2.00</commonCountingTime>
				<intensities unit="counts">1 2 3 2 0 1 1 0 1 1 0 1 2 1 1 0 0 1 2 0 0 1 0 2 2 1 1 0 1 1 0 0 3 1 1 0 0 3 2 0 1 0 0 0 0 2 1 0 3 1 0 1 0 1 0 0 1 0 2 2 0 0 0 0 1 4 0 0 0 0 2 1 1 1 1 0 0 0 0 1 1 0 1 0 0 1 0 0 1 1 0 0 0 1 1 0 1 0 0 0 1 2 0 2 1 0 0 1 0 0 1 0 0 0 0 1 1 1 1 0 1 1 0 1 1 1 0 1 1 3 1 4 1 2 1 1 0 2 0 3 2 0 1 0 0 0 0 0 1 1 1 0 2 0 0 0 1 1 0 0 0 0 0 0 0 0 1 1 0 0 2 1 0 0 0 0 1 0 0 2 0 3 0 0 0 0 1 0 0 1 0 1 0 0 0 0 1 0 0 0 2 0 1 0 1 2 1 1 1 0 0 0 0 0 0 3 1 0 0 2 1 0 0 1 1 0 0 0 0 0 0 0 1 1 1 0 1 0 0 0 0 0 1 0 0 0 0 0 0 1 0 0 1 0 2</intensities>
			</dataPoints>
		</scan>
		<scan appendNumber="0" mode="Continuous" scanAxis="2Theta" status="Completed">
			<header>
				<startTimeStamp>2012-06-16T00:26:37+02:00</startTimeStamp>
				<endTimeStamp>2012-06-16T00:26:40+02:00</endTimeStamp>
				<author>
					<name>Johannes Kepler Univ</name>
				</author>
				<source>
					<applicationSoftware version="2.2i">X'Pert Data Collector</applicationSoftware>
					<instrumentControlSoftware version="2.1E">XPERT-PRO</instrumentControlSoftware>
					<instrumentID>0000000011071750</instrumentID>
				</source>
			</header>
			<scanAxisCenter>
				<position axis="2Theta" unit="deg">63.2283</position>
			</scanAxisCenter>
			<dataPoints>
				<positions axis="2Theta" unit="deg">
					<listPositions>62.27550446 62.28300542 62.29050642 62.29800744 62.30550850 62.31300959 62.32051070 62.32801186 62.33551304 62.34301425 62.35051549 62.35801677 62.36551807 62.37301940 62.38052076 62.38802215 62.39552357 62.40302502 62.41052650 62.41802800 62.42552953 62.43303109 62.44053268 62.44803429 62.45553593 62.46303760 62.47053929 62.47804101 62.48554276 62.49304453 62.50054633 62.50804815 62.51554999 62.52305186 62.53055376 62.53805567 62.54555761 62.55305958 62.56056157 62.56806358 62.57556561 62.58306767 62.59056975 62.59807185 62.60557397 62.61307611 62.62057828 62.62808046 62.63558267 62.64308489 62.65058714 62.65808940 62.66559169 62.67309399 62.68059632 62.68809866 62.69560102 62.70310340 62.71060580 62.71810821 62.72561065 62.73311310 62.74061556 62.74811805 62.75562055 62.76312306 62.77062559 62.77812814 62.78563070 62.79313328 62.80063588 62.80813848 62.81564111 62.82314374 62.83064639 62.83814906 62.84565174 62.85315443 62.86065713 62.86815985 62.87566257 62.88316531 62.89066807 62.89817083 62.90567361 62.91317639 62.92067919 62.92818200 62.93568481 62.94318764 62.95069048 62.95819333 62.96569618 62.97319905 62.98070192 62.98820481 62.99570770 63.00321060 63.01071350 63.01821642 63.02571934 63.03322227 63.04072520 63.04822814 63.05573109 63.06323405 63.07073700 63.07823997 63.08574294 63.09324591 63.10074889 63.10825188 63.11575486 63.12325786 63.13076085 63.13826385 63.14576685 63.15326986 63.16077286 63.16827587 63.17577888 63.18328190 63.19078491 63.19828793 63.20579095 63.21329396 63.22079698 63.22830000 63.23580302 63.24330604 63.25080905 63.25831207 63.26581509 63.27331810 63.28082112 63.28832413 63.29582714 63.30333014 63.31083315 63.31833615 63.32583915 63.33334214 63.34084514 63.34834812 63.35585111 63.36335409 63.37085706 63.37836003 63.38586300 63.39336595 63.40086891 63.40837186 63.41587480 63.42337773 63.43088066 63.43838358 63.44588650 63.45338940 63.46089230 63.46839519 63.47589808 63.48340095 63.49090382 63.49840667 63.50590952 63.51341236 63.52091519 63.52841800 63.53592081 63.54342361 63.55092639 63.55842917 63.56593193 63.57343469 63.58093743 63.58844015 63.59594287 63.60344557 63.61094826 63.61845094 63.62595361 63.63345626 63.64095889 63.64846152 63.65596412 63.66346672 63.67096930 63.67847186 63.68597441 63.69347694 63.70097945 63.70848195 63.71598444 63.72348690 63.73098935 63.73849179 63.74599420 63.75349660 63.76099898 63.76850134 63.77600368 63.78350601 63.79100831 63.79851060 63.80601286 63.81351511 63.82101733 63.82851954 63.83602172 63.84352389 63.85102603 63.85852815 63.86603025 63.87353233 63.88103439 63.88853642 63.89603843 63.90354042 63.91104239 63.91854433 63.92604624 63.93354814 63.94105001 63.94855185 63.95605367 63.96355547 63.97105724 63.97855899 63.98606071 63.99356240 64.00106407 64.00856571 64.01606732 64.02356891 64.03107047 64.03857200 64.04607350 64.05357498 64.06107643 64.06857785 64.07607924 64.08358060 64.09108193 64.09858323 64.10608451 64.11358575 64.12108696 64.12858814 64.13608930 64.14359041 64.15109150 64.15859256 64.16609358 64.17359458 64.18109554</listPositions>
				</positions>
				<positions axis="Omega" unit="deg">
					<commonPosition>32.3546</commonPosition>
				</positions>
				<positions axis="Phi" unit="deg">
					<commonPosition>-1.64</commonPosition>
				</positions>
				<positions axis="Psi" unit="deg">
					<commonPosition>0.12</commonPosition>
				</positions>
				<positions axis="X" unit="mm">
					<commonPosition>0.00</commonPosition>
				</positions>
				<positions axis="Y" unit="mm">
					<commonPosition>0.00</commonPosition>
				</positions>
				<positions axis="Z" unit="mm">
					<commonPosition>17.671</commonPosition>
				</positions>
				<commonCountingTime unit="seconds">2.00</commonCountingTime>
				<intensities unit="counts">1 1 1 0 1 1 4 1 0 0 0 1 0 0 0 1 1 1 2 1 1 0 0 0 0 0 1 1 2 1 1 2 0 0 0 0 0 0 0 0 0 0 0 2 0 0 0 0 1 4 2 2 0 1 0 2 0 1 0 0 1 1 1 1 0 1 1 0 1 3 0 1 0 2 1 1 2 1 0 2 1 0 0 2 1 1 0 0 0 2 0 0 0 1 0 1 1 0 0 1 1 1 0 1 0 0 1 0 1 1 1 1 0 0 2 0 1 0 1 1 1 1 0 2 3 1 0 1 0 0 0 0 0 0 0 0 0 0 0 2 1 0 0 1 3 0 0 0 1 1 1 1 0 1 0 1 0 1 0 3 0 0 0 2 0 1 1 0 0 1 1 0 0 0 0 1 0 2 0 0 0 1 1 0 0 4 1 1 0 0 0 1 1 1 1 0 0 1 0 0 0 1 0 0 1 2 2 0 0 0 1 1 1 2 1 0 0 1 1 0 2 0 0 2 0 0 1 0 0 1 3 0 1 0 1 0 0 0 0 2 0 2 0 1 1 4 1 1 1 0 1 0 1 0 0</intensities>
			</dataPoints>
		</scan>
	</xrdMeasurement>
</xrdMeasurements>