File: examples/data/rsm_2.xrdml
<?xml version="1.0" encoding="UTF-8"?>
<xrdMeasurements xmlns="http://www.xrdml.com/XRDMeasurement/1.3" xmlns:xsi="http://www.w3.org/2001/XMLSchema-instance" xsi:schemaLocation="http://www.xrdml.com/XRDMeasurement/1.3 http://www.xrdml.com/XRDMeasurement/1.3/XRDMeasurement.xsd" status="Completed">
	<comment>
		<entry>Configuration=Factory configuration, Owner=User-1, Creation date=6/4/2010 10:23:02 AM</entry>
		<entry>Goniometer=PW3050/65 (Theta/2Theta); Minimum step size 2Theta:0.0001; Minimum step size Omega:0.0001</entry>
		<entry>Sample stage=MRD XL Cradle; Minimum step size Phi:0.01; Minimum step size Psi:0.01; Minimum step size X:0.01; Minimum step size Y:0.01; Minimum step size Z:0.001</entry>
		<entry>Diffractometer system=XPERT-PRO</entry>
		<entry>Measurement program=GreenSi_map_2deg2s, Owner=tanja, Creation date=3/19/2012 10:07:21 AM</entry>
		<entry>Fine Calibration Offset for 2Theta = -0.0192 deg</entry>
		<entry>Fine Calibration Offset for Omega = 0.1691 deg</entry>
		<entry>Batch program=Rastelli_XRR_XRD_short_period_sample5, Owner=tanja, Creation date=6/15/2012 3:39:26 PM</entry>
	</comment>
	<sample type="To be analyzed">
		<id></id>
		<name></name>
		<preparedBy></preparedBy>
	</sample>
	<xrdMeasurement measurementType="Area measurement" status="Completed" measurementStepAxis="Omega" sampleMode="Reflection">
		<comment>
			<entry/>
		</comment>
		<usedWavelength intended="K-Alpha 1">
			<kAlpha1 unit="Angstrom">1.5405980</kAlpha1>
			<kAlpha2 unit="Angstrom">1.5444260</kAlpha2>
			<kBeta unit="Angstrom">1.3922500</kBeta>
			<ratioKAlpha2KAlpha1>0.5000</ratioKAlpha2KAlpha1>
		</usedWavelength>
		<incidentBeamPath>
			<radius unit="mm">420.00</radius>
			<xRayTube id="1010048" name="PW3373/10 Cu LFF DK394719">
				<tension unit="kV">45</tension>
				<current unit="mA">40</current>
				<anodeMaterial>Cu</anodeMaterial>
				<focus type="Line">
					<length unit="mm">12.0</length>
					<width unit="mm">0.4</width>
					<takeOffAngle unit="deg">3.7</takeOffAngle>
				</focus>
			</xRayTube>
			<xRayMirror id="27090001" name="Inc. Beam Cu W/Si (hybrid MRD)" hybrid="true">
				<crystal type="Graded" shape="Parabolic">W/Si</crystal>
				<acceptanceAngle unit="deg">0.8</acceptanceAngle>
				<length unit="mm">60.0</length>
			</xRayMirror>
			<monochromator id="23090002" name="Inc. Beam 2xGe220 Cu Asym. (hybrid)" hybrid="true">
				<crystal type="Asymmetric" shape="Flat">Ge</crystal>
				<numberOfReflections>2</numberOfReflections>
				<hkl>
					<h>2</h>
					<k>2</k>
					<l>0</l>
				</hkl>
			</monochromator>
			<divergenceSlit id="22010009" name="Slit Fixed 1/16Â°" xsi:type="fixedDivergenceSlitType">
				<distanceToSample unit="mm">320.00</distanceToSample>
				<height unit="mm">0.10</height>
			</divergenceSlit>
		</incidentBeamPath>
		<sampleOffset>
			<position axis="2Theta" unit="deg">0.0000</position>
			<position axis="Omega" unit="deg">0.0000</position>
		</sampleOffset>
		<diffractedBeamPath>
			<radius unit="mm">420.00</radius>
			<antiScatterSlit id="22090014" name="AS Slit 5.0 mm (PIXcel non-ambient &amp; MRD)" xsi:type="fixedAntiScatterSlitType">
				<height unit="mm">5.00</height>
			</antiScatterSlit>
			<detector id="7010015" name="PIXcel" xsi:type="rtmsDetectorType">
				<phd>
					<lowerLevel unit="%">25.5</lowerLevel>
					<upperLevel unit="%">100.0</upperLevel>
				</phd>
				<mode>Static</mode>
				<activeLength unit="deg">1.9131</activeLength>
			</detector>
		</diffractedBeamPath>
		<measurementStepAxisCenter>
			<position axis="Omega" unit="deg">33.1546</position>
		</measurementStepAxisCenter>
		<scan appendNumber="0" mode="Continuous" scanAxis="2Theta" status="Completed">
			<header>
				<startTimeStamp>2012-06-15T21:37:19+02:00</startTimeStamp>
				<endTimeStamp>2012-06-15T21:37:22+02:00</endTimeStamp>
				<author>
					<name>Johannes Kepler Univ</name>
				</author>
				<source>
					<applicationSoftware version="2.2i">X'Pert Data Collector</applicationSoftware>
					<instrumentControlSoftware version="2.1E">XPERT-PRO</instrumentControlSoftware>
					<instrumentID>0000000011071750</instrumentID>
				</source>
			</header>
			<scanAxisCenter>
				<position axis="2Theta" unit="deg">66.8283</position>
			</scanAxisCenter>
			<dataPoints>
				<positions axis="2Theta" unit="deg">
					<listPositions>65.87550446 65.88300542 65.89050642 65.89800744 65.90550850 65.91300959 65.92051070 65.92801186 65.93551304 65.94301425 65.95051549 65.95801677 65.96551807 65.97301940 65.98052076 65.98802215 65.99552357 66.00302502 66.01052650 66.01802800 66.02552953 66.03303109 66.04053268 66.04803429 66.05553593 66.06303760 66.07053929 66.07804101 66.08554276 66.09304453 66.10054633 66.10804815 66.11554999 66.12305186 66.13055376 66.13805567 66.14555761 66.15305958 66.16056157 66.16806358 66.17556561 66.18306767 66.19056975 66.19807185 66.20557397 66.21307611 66.22057828 66.22808046 66.23558267 66.24308489 66.25058714 66.25808940 66.26559169 66.27309399 66.28059632 66.28809866 66.29560102 66.30310340 66.31060580 66.31810821 66.32561065 66.33311310 66.34061556 66.34811805 66.35562055 66.36312306 66.37062559 66.37812814 66.38563070 66.39313328 66.40063588 66.40813848 66.41564111 66.42314374 66.43064639 66.43814906 66.44565174 66.45315443 66.46065713 66.46815985 66.47566257 66.48316531 66.49066807 66.49817083 66.50567361 66.51317639 66.52067919 66.52818200 66.53568481 66.54318764 66.55069048 66.55819333 66.56569618 66.57319905 66.58070192 66.58820481 66.59570770 66.60321060 66.61071350 66.61821642 66.62571934 66.63322227 66.64072520 66.64822814 66.65573109 66.66323405 66.67073700 66.67823997 66.68574294 66.69324591 66.70074889 66.70825188 66.71575486 66.72325786 66.73076085 66.73826385 66.74576685 66.75326986 66.76077286 66.76827587 66.77577888 66.78328190 66.79078491 66.79828793 66.80579095 66.81329396 66.82079698 66.82830000 66.83580302 66.84330604 66.85080905 66.85831207 66.86581509 66.87331810 66.88082112 66.88832413 66.89582714 66.90333014 66.91083315 66.91833615 66.92583915 66.93334214 66.94084514 66.94834812 66.95585111 66.96335409 66.97085706 66.97836003 66.98586300 66.99336595 67.00086891 67.00837186 67.01587480 67.02337773 67.03088066 67.03838358 67.04588650 67.05338940 67.06089230 67.06839519 67.07589808 67.08340095 67.09090382 67.09840667 67.10590952 67.11341236 67.12091519 67.12841800 67.13592081 67.14342361 67.15092639 67.15842917 67.16593193 67.17343469 67.18093743 67.18844015 67.19594287 67.20344557 67.21094826 67.21845094 67.22595361 67.23345626 67.24095889 67.24846152 67.25596412 67.26346672 67.27096930 67.27847186 67.28597441 67.29347694 67.30097945 67.30848195 67.31598444 67.32348690 67.33098935 67.33849179 67.34599420 67.35349660 67.36099898 67.36850134 67.37600368 67.38350601 67.39100831 67.39851060 67.40601286 67.41351511 67.42101733 67.42851954 67.43602172 67.44352389 67.45102603 67.45852815 67.46603025 67.47353233 67.48103439 67.48853642 67.49603843 67.50354042 67.51104239 67.51854433 67.52604624 67.53354814 67.54105001 67.54855185 67.55605367 67.56355547 67.57105724 67.57855899 67.58606071 67.59356240 67.60106407 67.60856571 67.61606732 67.62356891 67.63107047 67.63857200 67.64607350 67.65357498 67.66107643 67.66857785 67.67607924 67.68358060 67.69108193 67.69858323 67.70608451 67.71358575 67.72108696 67.72858814 67.73608930 67.74359041 67.75109150 67.75859256 67.76609358 67.77359458 67.78109554</listPositions>
				</positions>
				<positions axis="Omega" unit="deg">
					<commonPosition>32.1546</commonPosition>
				</positions>
				<positions axis="Phi" unit="deg">
					<commonPosition>-1.64</commonPosition>
				</positions>
				<positions axis="Psi" unit="deg">
					<commonPosition>0.12</commonPosition>
				</positions>
				<positions axis="X" unit="mm">
					<commonPosition>0.00</commonPosition>
				</positions>
				<positions axis="Y" unit="mm">
					<commonPosition>0.00</commonPosition>
				</positions>
				<positions axis="Z" unit="mm">
					<commonPosition>17.671</commonPosition>
				</positions>
				<commonCountingTime unit="seconds">2.00</commonCountingTime>
				<intensities unit="counts">0 2 2 0 1 1 0 4 0 3 3 1 3 1 1 0 0 0 1 1 1 0 1 1 0 0 0 1 2 2 1 0 0 0 0 0 0 1 4 3 2 0 0 1 0 0 0 0 1 0 1 0 0 1 0 0 1 2 3 0 1 1 1 0 0 3 0 2 1 0 0 2 1 1 0 1 0 2 1 2 3 1 2 0 1 1 2 0 1 2 5 1 2 1 0 2 0 1 3 0 1 1 1 0 2 3 0 1 3 3 0 1 2 1 0 0 4 1 0 0 1 1 1 2 1 1 1 1 0 1 0 0 0 2 0 0 0 0 0 0 0 0 1 1 2 1 1 2 0 3 0 1 0 1 0 1 1 0 1 0 1 1 0 4 2 1 2 1 0 1 0 3 1 3 0 1 1 1 0 2 2 3 2 0 0 0 2 0 0 2 3 2 0 2 2 2 0 0 1 1 2 1 0 1 1 0 1 0 1 0 3 2 0 2 1 2 1 0 1 2 2 0 1 1 1 0 3 0 0 2 0 1 5 1 1 0 1 0 1 1 0 6 0 0 1 1 0 1 1 1 3 3 3 0 1</intensities>
			</dataPoints>
		</scan>
		<scan appendNumber="0" mode="Continuous" scanAxis="2Theta" status="Completed">
			<header>
				<startTimeStamp>2012-06-15T21:37:26+02:00</startTimeStamp>
				<endTimeStamp>2012-06-15T21:37:30+02:00</endTimeStamp>
				<author>
					<name>Johannes Kepler Univ</name>
				</author>
				<source>
					<applicationSoftware version="2.2i">X'Pert Data Collector</applicationSoftware>
					<instrumentControlSoftware version="2.1E">XPERT-PRO</instrumentControlSoftware>
					<instrumentID>0000000011071750</instrumentID>
				</source>
			</header>
			<scanAxisCenter>
				<position axis="2Theta" unit="deg">66.8283</position>
			</scanAxisCenter>
			<dataPoints>
				<positions axis="2Theta" unit="deg">
					<listPositions>65.87550446 65.88300542 65.89050642 65.89800744 65.90550850 65.91300959 65.92051070 65.92801186 65.93551304 65.94301425 65.95051549 65.95801677 65.96551807 65.97301940 65.98052076 65.98802215 65.99552357 66.00302502 66.01052650 66.01802800 66.02552953 66.03303109 66.04053268 66.04803429 66.05553593 66.06303760 66.07053929 66.07804101 66.08554276 66.09304453 66.10054633 66.10804815 66.11554999 66.12305186 66.13055376 66.13805567 66.14555761 66.15305958 66.16056157 66.16806358 66.17556561 66.18306767 66.19056975 66.19807185 66.20557397 66.21307611 66.22057828 66.22808046 66.23558267 66.24308489 66.25058714 66.25808940 66.26559169 66.27309399 66.28059632 66.28809866 66.29560102 66.30310340 66.31060580 66.31810821 66.32561065 66.33311310 66.34061556 66.34811805 66.35562055 66.36312306 66.37062559 66.37812814 66.38563070 66.39313328 66.40063588 66.40813848 66.41564111 66.42314374 66.43064639 66.43814906 66.44565174 66.45315443 66.46065713 66.46815985 66.47566257 66.48316531 66.49066807 66.49817083 66.50567361 66.51317639 66.52067919 66.52818200 66.53568481 66.54318764 66.55069048 66.55819333 66.56569618 66.57319905 66.58070192 66.58820481 66.59570770 66.60321060 66.61071350 66.61821642 66.62571934 66.63322227 66.64072520 66.64822814 66.65573109 66.66323405 66.67073700 66.67823997 66.68574294 66.69324591 66.70074889 66.70825188 66.71575486 66.72325786 66.73076085 66.73826385 66.74576685 66.75326986 66.76077286 66.76827587 66.77577888 66.78328190 66.79078491 66.79828793 66.80579095 66.81329396 66.82079698 66.82830000 66.83580302 66.84330604 66.85080905 66.85831207 66.86581509 66.87331810 66.88082112 66.88832413 66.89582714 66.90333014 66.91083315 66.91833615 66.92583915 66.93334214 66.94084514 66.94834812 66.95585111 66.96335409 66.97085706 66.97836003 66.98586300 66.99336595 67.00086891 67.00837186 67.01587480 67.02337773 67.03088066 67.03838358 67.04588650 67.05338940 67.06089230 67.06839519 67.07589808 67.08340095 67.09090382 67.09840667 67.10590952 67.11341236 67.12091519 67.12841800 67.13592081 67.14342361 67.15092639 67.15842917 67.16593193 67.17343469 67.18093743 67.18844015 67.19594287 67.20344557 67.21094826 67.21845094 67.22595361 67.23345626 67.24095889 67.24846152 67.25596412 67.26346672 67.27096930 67.27847186 67.28597441 67.29347694 67.30097945 67.30848195 67.31598444 67.32348690 67.33098935 67.33849179 67.34599420 67.35349660 67.36099898 67.36850134 67.37600368 67.38350601 67.39100831 67.39851060 67.40601286 67.41351511 67.42101733 67.42851954 67.43602172 67.44352389 67.45102603 67.45852815 67.46603025 67.47353233 67.48103439 67.48853642 67.49603843 67.50354042 67.51104239 67.51854433 67.52604624 67.53354814 67.54105001 67.54855185 67.55605367 67.56355547 67.57105724 67.57855899 67.58606071 67.59356240 67.60106407 67.60856571 67.61606732 67.62356891 67.63107047 67.63857200 67.64607350 67.65357498 67.66107643 67.66857785 67.67607924 67.68358060 67.69108193 67.69858323 67.70608451 67.71358575 67.72108696 67.72858814 67.73608930 67.74359041 67.75109150 67.75859256 67.76609358 67.77359458 67.78109554</listPositions>
				</positions>
				<positions axis="Omega" unit="deg">
					<commonPosition>32.1596</commonPosition>
				</positions>
				<positions axis="Phi" unit="deg">
					<commonPosition>-1.64</commonPosition>
				</positions>
				<positions axis="Psi" unit="deg">
					<commonPosition>0.12</commonPosition>
				</positions>
				<positions axis="X" unit="mm">
					<commonPosition>0.00</commonPosition>
				</positions>
				<positions axis="Y" unit="mm">
					<commonPosition>0.00</commonPosition>
				</positions>
				<positions axis="Z" unit="mm">
					<commonPosition>17.671</commonPosition>
				</positions>
				<commonCountingTime unit="seconds">2.00</commonCountingTime>
				<intensities unit="counts">0 1 1 3 0 0 1 0 1 0 2 2 0 1 0 1 0 2 2 0 0 0 0 0 1 0 0 0 1 2 1 1 1 0 0 0 0 0 2 1 0 2 0 2 1 0 1 1 0 1 1 2 1 1 1 0 1 1 3 0 2 0 0 2 2 0 0 0 1 1 1 0 1 0 1 0 1 2 2 0 3 2 1 1 0 0 0 0 2 1 0 3 1 1 1 2 0 0 1 0 1 0 1 1 0 3 2 0 0 0 1 1 0 0 2 1 2 0 1 0 0 1 4 1 0 0 1 1 1 0 0 1 1 1 2 1 3 0 7 2 0 1 1 1 2 1 0 1 0 2 2 1 1 0 1 1 2 0 0 1 1 0 1 3 2 1 0 2 1 0 1 2 0 0 0 1 2 0 1 2 1 3 2 1 0 1 3 1 0 2 0 0 0 0 0 2 1 1 0 2 1 1 0 1 2 0 0 2 1 1 0 0 0 3 2 3 2 2 2 1 1 0 1 1 1 2 2 0 1 2 0 0 2 2 0 2 2 2 1 0 0 0 2 2 1 2 0 2 0 2 1 1 1 1 1</intensities>
			</dataPoints>
		</scan>
		<scan appendNumber="0" mode="Continuous" scanAxis="2Theta" status="Completed">
			<header>
				<startTimeStamp>2012-06-15T21:37:34+02:00</startTimeStamp>
				<endTimeStamp>2012-06-15T21:37:38+02:00</endTimeStamp>
				<author>
					<name>Johannes Kepler Univ</name>
				</author>
				<source>
					<applicationSoftware version="2.2i">X'Pert Data Collector</applicationSoftware>
					<instrumentControlSoftware version="2.1E">XPERT-PRO</instrumentControlSoftware>
					<instrumentID>0000000011071750</instrumentID>
				</source>
			</header>
			<scanAxisCenter>
				<position axis="2Theta" unit="deg">66.8283</position>
			</scanAxisCenter>
			<dataPoints>
				<positions axis="2Theta" unit="deg">
					<listPositions>65.87550446 65.88300542 65.89050642 65.89800744 65.90550850 65.91300959 65.92051070 65.92801186 65.93551304 65.94301425 65.95051549 65.95801677 65.96551807 65.97301940 65.98052076 65.98802215 65.99552357 66.00302502 66.01052650 66.01802800 66.02552953 66.03303109 66.04053268 66.04803429 66.05553593 66.06303760 66.07053929 66.07804101 66.08554276 66.09304453 66.10054633 66.10804815 66.11554999 66.12305186 66.13055376 66.13805567 66.14555761 66.15305958 66.16056157 66.16806358 66.17556561 66.18306767 66.19056975 66.19807185 66.20557397 66.21307611 66.22057828 66.22808046 66.23558267 66.24308489 66.25058714 66.25808940 66.26559169 66.27309399 66.28059632 66.28809866 66.29560102 66.30310340 66.31060580 66.31810821 66.32561065 66.33311310 66.34061556 66.34811805 66.35562055 66.36312306 66.37062559 66.37812814 66.38563070 66.39313328 66.40063588 66.40813848 66.41564111 66.42314374 66.43064639 66.43814906 66.44565174 66.45315443 66.46065713 66.46815985 66.47566257 66.48316531 66.49066807 66.49817083 66.50567361 66.51317639 66.52067919 66.52818200 66.53568481 66.54318764 66.55069048 66.55819333 66.56569618 66.57319905 66.58070192 66.58820481 66.59570770 66.60321060 66.61071350 66.61821642 66.62571934 66.63322227 66.64072520 66.64822814 66.65573109 66.66323405 66.67073700 66.67823997 66.68574294 66.69324591 66.70074889 66.70825188 66.71575486 66.72325786 66.73076085 66.73826385 66.74576685 66.75326986 66.76077286 66.76827587 66.77577888 66.78328190 66.79078491 66.79828793 66.80579095 66.81329396 66.82079698 66.82830000 66.83580302 66.84330604 66.85080905 66.85831207 66.86581509 66.87331810 66.88082112 66.88832413 66.89582714 66.90333014 66.91083315 66.91833615 66.92583915 66.93334214 66.94084514 66.94834812 66.95585111 66.96335409 66.97085706 66.97836003 66.98586300 66.99336595 67.00086891 67.00837186 67.01587480 67.02337773 67.03088066 67.03838358 67.04588650 67.05338940 67.06089230 67.06839519 67.07589808 67.08340095 67.09090382 67.09840667 67.10590952 67.11341236 67.12091519 67.12841800 67.13592081 67.14342361 67.15092639 67.15842917 67.16593193 67.17343469 67.18093743 67.18844015 67.19594287 67.20344557 67.21094826 67.21845094 67.22595361 67.23345626 67.24095889 67.24846152 67.25596412 67.26346672 67.27096930 67.27847186 67.28597441 67.29347694 67.30097945 67.30848195 67.31598444 67.32348690 67.33098935 67.33849179 67.34599420 67.35349660 67.36099898 67.36850134 67.37600368 67.38350601 67.39100831 67.39851060 67.40601286 67.41351511 67.42101733 67.42851954 67.43602172 67.44352389 67.45102603 67.45852815 67.46603025 67.47353233 67.48103439 67.48853642 67.49603843 67.50354042 67.51104239 67.51854433 67.52604624 67.53354814 67.54105001 67.54855185 67.55605367 67.56355547 67.57105724 67.57855899 67.58606071 67.59356240 67.60106407 67.60856571 67.61606732 67.62356891 67.63107047 67.63857200 67.64607350 67.65357498 67.66107643 67.66857785 67.67607924 67.68358060 67.69108193 67.69858323 67.70608451 67.71358575 67.72108696 67.72858814 67.73608930 67.74359041 67.75109150 67.75859256 67.76609358 67.77359458 67.78109554</listPositions>
				</positions>
				<positions axis="Omega" unit="deg">
					<commonPosition>32.1646</commonPosition>
				</positions>
				<positions axis="Phi" unit="deg">
					<commonPosition>-1.64</commonPosition>
				</positions>
				<positions axis="Psi" unit="deg">
					<commonPosition>0.12</commonPosition>
				</positions>
				<positions axis="X" unit="mm">
					<commonPosition>0.00</commonPosition>
				</positions>
				<positions axis="Y" unit="mm">
					<commonPosition>0.00</commonPosition>
				</positions>
				<positions axis="Z" unit="mm">
					<commonPosition>17.671</commonPosition>
				</positions>
				<commonCountingTime unit="seconds">2.00</commonCountingTime>
				<intensities unit="counts">0 1 0 0 1 1 0 0 1 0 2 3 1 0 1 2 1 1 1 0 2 1 2 1 0 1 1 4 2 0 0 4 0 0 0 3 1 0 0 0 2 0 2 1 1 0 2 0 0 1 2 1 1 2 2 1 1 3 1 1 3 0 1 0 1 2 1 0 0 0 1 0 0 1 1 1 1 0 1 4 0 0 2 0 1 0 0 1 1 0 1 1 2 0 4 1 1 0 2 4 1 5 1 2 2 2 3 0 2 1 3 1 0 2 1 3 1 0 0 1 1 1 3 3 1 1 1 2 0 2 1 4 1 1 2 2 3 1 1 0 2 2 1 1 1 1 1 5 0 0 1 2 0 1 1 3 0 1 0 0 0 1 2 0 1 1 0 2 1 0 3 4 0 2 1 0 1 0 0 2 3 2 1 0 2 3 2 2 0 1 1 2 1 1 0 0 1 1 2 2 1 2 1 1 1 2 0 0 3 1 1 0 0 1 1 0 2 2 2 1 2 1 1 2 1 3 1 4 2 4 0 2 0 1 0 5 0 1 1 2 1 2 1 2 1 1 2 1 1 1 0 1 1 2 3</intensities>
			</dataPoints>
		</scan>
		<scan appendNumber="0" mode="Continuous" scanAxis="2Theta" status="Completed">
			<header>
				<startTimeStamp>2012-06-15T21:37:42+02:00</startTimeStamp>
				<endTimeStamp>2012-06-15T21:37:45+02:00</endTimeStamp>
				<author>
					<name>Johannes Kepler Univ</name>
				</author>
				<source>
					<applicationSoftware version="2.2i">X'Pert Data Collector</applicationSoftware>
					<instrumentControlSoftware version="2.1E">XPERT-PRO</instrumentControlSoftware>
					<instrumentID>0000000011071750</instrumentID>
				</source>
			</header>
			<scanAxisCenter>
				<position axis="2Theta" unit="deg">66.8283</position>
			</scanAxisCenter>
			<dataPoints>
				<positions axis="2Theta" unit="deg">
					<listPositions>65.87550446 65.88300542 65.89050642 65.89800744 65.90550850 65.91300959 65.92051070 65.92801186 65.93551304 65.94301425 65.95051549 65.95801677 65.96551807 65.97301940 65.98052076 65.98802215 65.99552357 66.00302502 66.01052650 66.01802800 66.02552953 66.03303109 66.04053268 66.04803429 66.05553593 66.06303760 66.07053929 66.07804101 66.08554276 66.09304453 66.10054633 66.10804815 66.11554999 66.12305186 66.13055376 66.13805567 66.14555761 66.15305958 66.16056157 66.16806358 66.17556561 66.18306767 66.19056975 66.19807185 66.20557397 66.21307611 66.22057828 66.22808046 66.23558267 66.24308489 66.25058714 66.25808940 66.26559169 66.27309399 66.28059632 66.28809866 66.29560102 66.30310340 66.31060580 66.31810821 66.32561065 66.33311310 66.34061556 66.34811805 66.35562055 66.36312306 66.37062559 66.37812814 66.38563070 66.39313328 66.40063588 66.40813848 66.41564111 66.42314374 66.43064639 66.43814906 66.44565174 66.45315443 66.46065713 66.46815985 66.47566257 66.48316531 66.49066807 66.49817083 66.50567361 66.51317639 66.52067919 66.52818200 66.53568481 66.54318764 66.55069048 66.55819333 66.56569618 66.57319905 66.58070192 66.58820481 66.59570770 66.60321060 66.61071350 66.61821642 66.62571934 66.63322227 66.64072520 66.64822814 66.65573109 66.66323405 66.67073700 66.67823997 66.68574294 66.69324591 66.70074889 66.70825188 66.71575486 66.72325786 66.73076085 66.73826385 66.74576685 66.75326986 66.76077286 66.76827587 66.77577888 66.78328190 66.79078491 66.79828793 66.80579095 66.81329396 66.82079698 66.82830000 66.83580302 66.84330604 66.85080905 66.85831207 66.86581509 66.87331810 66.88082112 66.88832413 66.89582714 66.90333014 66.91083315 66.91833615 66.92583915 66.93334214 66.94084514 66.94834812 66.95585111 66.96335409 66.97085706 66.97836003 66.98586300 66.99336595 67.00086891 67.00837186 67.01587480 67.02337773 67.03088066 67.03838358 67.04588650 67.05338940 67.06089230 67.06839519 67.07589808 67.08340095 67.09090382 67.09840667 67.10590952 67.11341236 67.12091519 67.12841800 67.13592081 67.14342361 67.15092639 67.15842917 67.16593193 67.17343469 67.18093743 67.18844015 67.19594287 67.20344557 67.21094826 67.21845094 67.22595361 67.23345626 67.24095889 67.24846152 67.25596412 67.26346672 67.27096930 67.27847186 67.28597441 67.29347694 67.30097945 67.30848195 67.31598444 67.32348690 67.33098935 67.33849179 67.34599420 67.35349660 67.36099898 67.36850134 67.37600368 67.38350601 67.39100831 67.39851060 67.40601286 67.41351511 67.42101733 67.42851954 67.43602172 67.44352389 67.45102603 67.45852815 67.46603025 67.47353233 67.48103439 67.48853642 67.49603843 67.50354042 67.51104239 67.51854433 67.52604624 67.53354814 67.54105001 67.54855185 67.55605367 67.56355547 67.57105724 67.57855899 67.58606071 67.59356240 67.60106407 67.60856571 67.61606732 67.62356891 67.63107047 67.63857200 67.64607350 67.65357498 67.66107643 67.66857785 67.67607924 67.68358060 67.69108193 67.69858323 67.70608451 67.71358575 67.72108696 67.72858814 67.73608930 67.74359041 67.75109150 67.75859256 67.76609358 67.77359458 67.78109554</listPositions>
				</positions>
				<positions axis="Omega" unit="deg">
					<commonPosition>32.1696</commonPosition>
				</positions>
				<positions axis="Phi" unit="deg">
					<commonPosition>-1.64</commonPosition>
				</positions>
				<positions axis="Psi" unit="deg">
					<commonPosition>0.12</commonPosition>
				</positions>
				<positions axis="X" unit="mm">
					<commonPosition>0.00</commonPosition>
				</positions>
				<positions axis="Y" unit="mm">
					<commonPosition>0.00</commonPosition>
				</positions>
				<positions axis="Z" unit="mm">
					<commonPosition>17.671</commonPosition>
				</positions>
				<commonCountingTime unit="seconds">2.00</commonCountingTime>
				<intensities unit="counts">0 0 1 1 1 1 2 1 1 0 0 2 0 0 2 0 1 0 1 2 2 0 1 2 0 0 1 1 0 3 2 1 0 2 1 0 3 0 2 2 0 1 1 1 2 3 3 5 3 2 1 0 1 1 1 0 2 1 2 1 1 2 1 1 4 2 2 0 0 1 0 0 2 0 0 2 1 2 1 1 1 0 1 1 0 0 0 0 0 0 1 1 1 4 0 1 1 2 1 1 0 1 1 0 0 1 0 0 2 0 1 3 2 2 1 3 0 1 1 2 0 3 3 0 3 2 3 3 1 1 3 0 1 2 2 0 0 3 2 3 1 3 2 1 0 2 1 5 2 3 1 2 0 0 1 4 1 0 1 0 3 0 0 1 1 2 0 0 2 1 1 3 2 2 1 1 2 2 2 2 2 3 2 1 0 0 0 1 2 1 0 0 3 2 1 1 0 2 2 1 1 0 3 0 2 1 2 2 1 0 0 1 0 2 1 0 0 1 0 2 1 3 0 1 2 0 1 1 3 1 1 1 0 0 2 0 1 0 1 1 0 2 1 4 3 1 0 2 1 3 2 1 0 1 2</intensities>
			</dataPoints>
		</scan>
		<scan appendNumber="0" mode="Continuous" scanAxis="2Theta" status="Completed">
			<header>
				<startTimeStamp>2012-06-15T21:37:49+02:00</startTimeStamp>
				<endTimeStamp>2012-06-15T21:37:53+02:00</endTimeStamp>
				<author>
					<name>Johannes Kepler Univ</name>
				</author>
				<source>
					<applicationSoftware version="2.2i">X'Pert Data Collector</applicationSoftware>
					<instrumentControlSoftware version="2.1E">XPERT-PRO</instrumentControlSoftware>
					<instrumentID>0000000011071750</instrumentID>
				</source>
			</header>
			<scanAxisCenter>
				<position axis="2Theta" unit="deg">66.8283</position>
			</scanAxisCenter>
			<dataPoints>
				<positions axis="2Theta" unit="deg">
					<listPositions>65.87550446 65.88300542 65.89050642 65.89800744 65.90550850 65.91300959 65.92051070 65.92801186 65.93551304 65.94301425 65.95051549 65.95801677 65.96551807 65.97301940 65.98052076 65.98802215 65.99552357 66.00302502 66.01052650 66.01802800 66.02552953 66.03303109 66.04053268 66.04803429 66.05553593 66.06303760 66.07053929 66.07804101 66.08554276 66.09304453 66.10054633 66.10804815 66.11554999 66.12305186 66.13055376 66.13805567 66.14555761 66.15305958 66.16056157 66.16806358 66.17556561 66.18306767 66.19056975 66.19807185 66.20557397 66.21307611 66.22057828 66.22808046 66.23558267 66.24308489 66.25058714 66.25808940 66.26559169 66.27309399 66.28059632 66.28809866 66.29560102 66.30310340 66.31060580 66.31810821 66.32561065 66.33311310 66.34061556 66.34811805 66.35562055 66.36312306 66.37062559 66.37812814 66.38563070 66.39313328 66.40063588 66.40813848 66.41564111 66.42314374 66.43064639 66.43814906 66.44565174 66.45315443 66.46065713 66.46815985 66.47566257 66.48316531 66.49066807 66.49817083 66.50567361 66.51317639 66.52067919 66.52818200 66.53568481 66.54318764 66.55069048 66.55819333 66.56569618 66.57319905 66.58070192 66.58820481 66.59570770 66.60321060 66.61071350 66.61821642 66.62571934 66.63322227 66.64072520 66.64822814 66.65573109 66.66323405 66.67073700 66.67823997 66.68574294 66.69324591 66.70074889 66.70825188 66.71575486 66.72325786 66.73076085 66.73826385 66.74576685 66.75326986 66.76077286 66.76827587 66.77577888 66.78328190 66.79078491 66.79828793 66.80579095 66.81329396 66.82079698 66.82830000 66.83580302 66.84330604 66.85080905 66.85831207 66.86581509 66.87331810 66.88082112 66.88832413 66.89582714 66.90333014 66.91083315 66.91833615 66.92583915 66.93334214 66.94084514 66.94834812 66.95585111 66.96335409 66.97085706 66.97836003 66.98586300 66.99336595 67.00086891 67.00837186 67.01587480 67.02337773 67.03088066 67.03838358 67.04588650 67.05338940 67.06089230 67.06839519 67.07589808 67.08340095 67.09090382 67.09840667 67.10590952 67.11341236 67.12091519 67.12841800 67.13592081 67.14342361 67.15092639 67.15842917 67.16593193 67.17343469 67.18093743 67.18844015 67.19594287 67.20344557 67.21094826 67.21845094 67.22595361 67.23345626 67.24095889 67.24846152 67.25596412 67.26346672 67.27096930 67.27847186 67.28597441 67.29347694 67.30097945 67.30848195 67.31598444 67.32348690 67.33098935 67.33849179 67.34599420 67.35349660 67.36099898 67.36850134 67.37600368 67.38350601 67.39100831 67.39851060 67.40601286 67.41351511 67.42101733 67.42851954 67.43602172 67.44352389 67.45102603 67.45852815 67.46603025 67.47353233 67.48103439 67.48853642 67.49603843 67.50354042 67.51104239 67.51854433 67.52604624 67.53354814 67.54105001 67.54855185 67.55605367 67.56355547 67.57105724 67.57855899 67.58606071 67.59356240 67.60106407 67.60856571 67.61606732 67.62356891 67.63107047 67.63857200 67.64607350 67.65357498 67.66107643 67.66857785 67.67607924 67.68358060 67.69108193 67.69858323 67.70608451 67.71358575 67.72108696 67.72858814 67.73608930 67.74359041 67.75109150 67.75859256 67.76609358 67.77359458 67.78109554</listPositions>
				</positions>
				<positions axis="Omega" unit="deg">
					<commonPosition>32.1746</commonPosition>
				</positions>
				<positions axis="Phi" unit="deg">
					<commonPosition>-1.64</commonPosition>
				</positions>
				<positions axis="Psi" unit="deg">
					<commonPosition>0.12</commonPosition>
				</positions>
				<positions axis="X" unit="mm">
					<commonPosition>0.00</commonPosition>
				</positions>
				<positions axis="Y" unit="mm">
					<commonPosition>0.00</commonPosition>
				</positions>
				<positions axis="Z" unit="mm">
					<commonPosition>17.671</commonPosition>
				</positions>
				<commonCountingTime unit="seconds">2.00</commonCountingTime>
				<intensities unit="counts">2 1 1 1 0 4 0 0 0 0 2 1 1 1 2 0 1 1 0 1 1 0 0 0 1 0 0 1 4 0 1 0 1 1 3 0 1 2 0 1 1 1 0 1 1 4 0 1 2 0 2 2 0 0 0 2 0 0 0 2 0 1 2 2 1 1 0 2 4 1 1 2 0 2 1 1 2 0 0 0 0 0 1 4 1 1 2 2 0 0 2 1 0 1 2 2 0 2 1 0 2 0 0 1 0 1 2 0 0 1 0 0 1 2 2 1 1 2 2 2 0 1 0 2 3 0 2 2 3 1 2 1 1 0 1 1 2 1 2 0 0 3 2 0 1 2 0 0 3 0 0 1 0 0 1 1 1 3 0 3 1 2 1 1 0 2 1 1 0 1 1 2 1 2 1 2 3 3 1 1 3 0 1 1 2 0 1 1 1 0 0 0 0 1 4 1 2 2 1 3 1 2 2 1 2 0 3 1 1 1 1 1 0 0 0 0 3 0 5 1 4 2 0 0 3 0 2 3 2 1 2 1 2 2 2 1 1 1 3 1 0 5 0 1 2 4 2 1 1 2 2 1 3 0 1</intensities>
			</dataPoints>
		</scan>
		<scan appendNumber="0" mode="Continuous" scanAxis="2Theta" status="Completed">
			<header>
				<startTimeStamp>2012-06-15T21:37:57+02:00</startTimeStamp>
				<endTimeStamp>2012-06-15T21:38:01+02:00</endTimeStamp>
				<author>
					<name>Johannes Kepler Univ</name>
				</author>
				<source>
					<applicationSoftware version="2.2i">X'Pert Data Collector</applicationSoftware>
					<instrumentControlSoftware version="2.1E">XPERT-PRO</instrumentControlSoftware>
					<instrumentID>0000000011071750</instrumentID>
				</source>
			</header>
			<scanAxisCenter>
				<position axis="2Theta" unit="deg">66.8283</position>
			</scanAxisCenter>
			<dataPoints>
				<positions axis="2Theta" unit="deg">
					<listPositions>65.87550446 65.88300542 65.89050642 65.89800744 65.90550850 65.91300959 65.92051070 65.92801186 65.93551304 65.94301425 65.95051549 65.95801677 65.96551807 65.97301940 65.98052076 65.98802215 65.99552357 66.00302502 66.01052650 66.01802800 66.02552953 66.03303109 66.04053268 66.04803429 66.05553593 66.06303760 66.07053929 66.07804101 66.08554276 66.09304453 66.10054633 66.10804815 66.11554999 66.12305186 66.13055376 66.13805567 66.14555761 66.15305958 66.16056157 66.16806358 66.17556561 66.18306767 66.19056975 66.19807185 66.20557397 66.21307611 66.22057828 66.22808046 66.23558267 66.24308489 66.25058714 66.25808940 66.26559169 66.27309399 66.28059632 66.28809866 66.29560102 66.30310340 66.31060580 66.31810821 66.32561065 66.33311310 66.34061556 66.34811805 66.35562055 66.36312306 66.37062559 66.37812814 66.38563070 66.39313328 66.40063588 66.40813848 66.41564111 66.42314374 66.43064639 66.43814906 66.44565174 66.45315443 66.46065713 66.46815985 66.47566257 66.48316531 66.49066807 66.49817083 66.50567361 66.51317639 66.52067919 66.52818200 66.53568481 66.54318764 66.55069048 66.55819333 66.56569618 66.57319905 66.58070192 66.58820481 66.59570770 66.60321060 66.61071350 66.61821642 66.62571934 66.63322227 66.64072520 66.64822814 66.65573109 66.66323405 66.67073700 66.67823997 66.68574294 66.69324591 66.70074889 66.70825188 66.71575486 66.72325786 66.73076085 66.73826385 66.74576685 66.75326986 66.76077286 66.76827587 66.77577888 66.78328190 66.79078491 66.79828793 66.80579095 66.81329396 66.82079698 66.82830000 66.83580302 66.84330604 66.85080905 66.85831207 66.86581509 66.87331810 66.88082112 66.88832413 66.89582714 66.90333014 66.91083315 66.91833615 66.92583915 66.93334214 66.94084514 66.94834812 66.95585111 66.96335409 66.97085706 66.97836003 66.98586300 66.99336595 67.00086891 67.00837186 67.01587480 67.02337773 67.03088066 67.03838358 67.04588650 67.05338940 67.06089230 67.06839519 67.07589808 67.08340095 67.09090382 67.09840667 67.10590952 67.11341236 67.12091519 67.12841800 67.13592081 67.14342361 67.15092639 67.15842917 67.16593193 67.17343469 67.18093743 67.18844015 67.19594287 67.20344557 67.21094826 67.21845094 67.22595361 67.23345626 67.24095889 67.24846152 67.25596412 67.26346672 67.27096930 67.27847186 67.28597441 67.29347694 67.30097945 67.30848195 67.31598444 67.32348690 67.33098935 67.33849179 67.34599420 67.35349660 67.36099898 67.36850134 67.37600368 67.38350601 67.39100831 67.39851060 67.40601286 67.41351511 67.42101733 67.42851954 67.43602172 67.44352389 67.45102603 67.45852815 67.46603025 67.47353233 67.48103439 67.48853642 67.49603843 67.50354042 67.51104239 67.51854433 67.52604624 67.53354814 67.54105001 67.54855185 67.55605367 67.56355547 67.57105724 67.57855899 67.58606071 67.59356240 67.60106407 67.60856571 67.61606732 67.62356891 67.63107047 67.63857200 67.64607350 67.65357498 67.66107643 67.66857785 67.67607924 67.68358060 67.69108193 67.69858323 67.70608451 67.71358575 67.72108696 67.72858814 67.73608930 67.74359041 67.75109150 67.75859256 67.76609358 67.77359458 67.78109554</listPositions>
				</positions>
				<positions axis="Omega" unit="deg">
					<commonPosition>32.1796</commonPosition>
				</positions>
				<positions axis="Phi" unit="deg">
					<commonPosition>-1.64</commonPosition>
				</positions>
				<positions axis="Psi" unit="deg">
					<commonPosition>0.12</commonPosition>
				</positions>
				<positions axis="X" unit="mm">
					<commonPosition>0.00</commonPosition>
				</positions>
				<positions axis="Y" unit="mm">
					<commonPosition>0.00</commonPosition>
				</positions>
				<positions axis="Z" unit="mm">
					<commonPosition>17.671</commonPosition>
				</positions>
				<commonCountingTime unit="seconds">2.00</commonCountingTime>
				<intensities unit="counts">1 0 0 0 1 0 1 0 2 0 1 1 1 0 0 1 0 1 0 0 0 0 1 1 0 3 2 0 1 1 0 0 2 0 3 4 2 0 0 3 0 0 1 0 2 1 0 1 1 0 2 0 0 0 0 1 0 1 2 1 3 0 2 1 2 4 1 1 0 1 2 1 0 0 1 1 0 0 0 0 0 3 1 1 1 0 0 2 1 0 0 0 1 0 2 0 2 0 0 0 0 2 0 3 0 1 1 0 1 1 0 0 3 2 0 0 3 0 4 2 0 3 1 1 1 2 1 3 2 0 2 1 1 1 1 1 1 1 0 1 2 3 0 0 0 2 1 0 3 0 1 1 1 1 1 2 0 5 0 4 1 2 0 1 0 1 1 2 2 1 0 2 1 1 1 1 1 3 2 1 1 1 1 2 2 4 0 1 0 0 1 1 1 2 1 0 4 0 3 0 1 1 1 1 0 2 1 1 1 3 1 1 0 1 1 0 4 2 0 1 0 2 2 1 1 0 2 4 1 2 0 2 1 1 1 0 2 1 0 3 1 0 1 1 3 1 2 2 1 1 3 1 1 2 2</intensities>
			</dataPoints>
		</scan>
		<scan appendNumber="0" mode="Continuous" scanAxis="2Theta" status="Completed">
			<header>
				<startTimeStamp>2012-06-15T21:38:05+02:00</startTimeStamp>
				<endTimeStamp>2012-06-15T21:38:08+02:00</endTimeStamp>
				<author>
					<name>Johannes Kepler Univ</name>
				</author>
				<source>
					<applicationSoftware version="2.2i">X'Pert Data Collector</applicationSoftware>
					<instrumentControlSoftware version="2.1E">XPERT-PRO</instrumentControlSoftware>
					<instrumentID>0000000011071750</instrumentID>
				</source>
			</header>
			<scanAxisCenter>
				<position axis="2Theta" unit="deg">66.8283</position>
			</scanAxisCenter>
			<dataPoints>
				<positions axis="2Theta" unit="deg">
					<listPositions>65.87550446 65.88300542 65.89050642 65.89800744 65.90550850 65.91300959 65.92051070 65.92801186 65.93551304 65.94301425 65.95051549 65.95801677 65.96551807 65.97301940 65.98052076 65.98802215 65.99552357 66.00302502 66.01052650 66.01802800 66.02552953 66.03303109 66.04053268 66.04803429 66.05553593 66.06303760 66.07053929 66.07804101 66.08554276 66.09304453 66.10054633 66.10804815 66.11554999 66.12305186 66.13055376 66.13805567 66.14555761 66.15305958 66.16056157 66.16806358 66.17556561 66.18306767 66.19056975 66.19807185 66.20557397 66.21307611 66.22057828 66.22808046 66.23558267 66.24308489 66.25058714 66.25808940 66.26559169 66.27309399 66.28059632 66.28809866 66.29560102 66.30310340 66.31060580 66.31810821 66.32561065 66.33311310 66.34061556 66.34811805 66.35562055 66.36312306 66.37062559 66.37812814 66.38563070 66.39313328 66.40063588 66.40813848 66.41564111 66.42314374 66.43064639 66.43814906 66.44565174 66.45315443 66.46065713 66.46815985 66.47566257 66.48316531 66.49066807 66.49817083 66.50567361 66.51317639 66.52067919 66.52818200 66.53568481 66.54318764 66.55069048 66.55819333 66.56569618 66.57319905 66.58070192 66.58820481 66.59570770 66.60321060 66.61071350 66.61821642 66.62571934 66.63322227 66.64072520 66.64822814 66.65573109 66.66323405 66.67073700 66.67823997 66.68574294 66.69324591 66.70074889 66.70825188 66.71575486 66.72325786 66.73076085 66.73826385 66.74576685 66.75326986 66.76077286 66.76827587 66.77577888 66.78328190 66.79078491 66.79828793 66.80579095 66.81329396 66.82079698 66.82830000 66.83580302 66.84330604 66.85080905 66.85831207 66.86581509 66.87331810 66.88082112 66.88832413 66.89582714 66.90333014 66.91083315 66.91833615 66.92583915 66.93334214 66.94084514 66.94834812 66.95585111 66.96335409 66.97085706 66.97836003 66.98586300 66.99336595 67.00086891 67.00837186 67.01587480 67.02337773 67.03088066 67.03838358 67.04588650 67.05338940 67.06089230 67.06839519 67.07589808 67.08340095 67.09090382 67.09840667 67.10590952 67.11341236 67.12091519 67.12841800 67.13592081 67.14342361 67.15092639 67.15842917 67.16593193 67.17343469 67.18093743 67.18844015 67.19594287 67.20344557 67.21094826 67.21845094 67.22595361 67.23345626 67.24095889 67.24846152 67.25596412 67.26346672 67.27096930 67.27847186 67.28597441 67.29347694 67.30097945 67.30848195 67.31598444 67.32348690 67.33098935 67.33849179 67.34599420 67.35349660 67.36099898 67.36850134 67.37600368 67.38350601 67.39100831 67.39851060 67.40601286 67.41351511 67.42101733 67.42851954 67.43602172 67.44352389 67.45102603 67.45852815 67.46603025 67.47353233 67.48103439 67.48853642 67.49603843 67.50354042 67.51104239 67.51854433 67.52604624 67.53354814 67.54105001 67.54855185 67.55605367 67.56355547 67.57105724 67.57855899 67.58606071 67.59356240 67.60106407 67.60856571 67.61606732 67.62356891 67.63107047 67.63857200 67.64607350 67.65357498 67.66107643 67.66857785 67.67607924 67.68358060 67.69108193 67.69858323 67.70608451 67.71358575 67.72108696 67.72858814 67.73608930 67.74359041 67.75109150 67.75859256 67.76609358 67.77359458 67.78109554</listPositions>
				</positions>
				<positions axis="Omega" unit="deg">
					<commonPosition>32.1846</commonPosition>
				</positions>
				<positions axis="Phi" unit="deg">
					<commonPosition>-1.64</commonPosition>
				</positions>
				<positions axis="Psi" unit="deg">
					<commonPosition>0.12</commonPosition>
				</positions>
				<positions axis="X" unit="mm">
					<commonPosition>0.00</commonPosition>
				</positions>
				<positions axis="Y" unit="mm">
					<commonPosition>0.00</commonPosition>
				</positions>
				<positions axis="Z" unit="mm">
					<commonPosition>17.671</commonPosition>
				</positions>
				<commonCountingTime unit="seconds">2.00</commonCountingTime>
				<intensities unit="counts">0 0 0 0 0 0 1 0 1 1 0 2 1 1 0 1 2 0 0 2 2 2 0 1 0 0 0 2 0 1 1 3 0 1 1 1 0 2 1 1 1 0 1 0 0 1 3 1 1 2 0 3 2 0 0 0 3 0 1 4 0 1 2 1 1 1 0 0 0 0 1 2 1 3 1 1 2 1 0 0 2 0 0 1 1 1 3 3 1 1 1 0 1 1 1 0 1 0 1 0 0 3 2 0 0 0 2 2 4 2 1 0 1 1 2 2 1 3 4 1 3 1 3 1 1 1 0 1 1 3 0 1 3 0 1 3 1 0 1 0 2 1 1 2 0 1 1 0 1 1 0 4 1 1 1 1 1 3 0 1 2 2 2 2 2 0 0 1 1 0 0 0 3 1 0 0 3 1 1 2 2 2 1 4 2 2 0 0 1 1 1 2 0 1 3 0 1 1 0 2 0 1 0 0 2 1 1 1 0 0 1 2 0 1 2 0 0 1 1 1 1 1 1 1 1 2 2 3 1 5 2 0 1 2 2 5 1 4 0 1 1 1 2 1 1 0 0 0 3 1 0 0 2 1 1</intensities>
			</dataPoints>
		</scan>
		<scan appendNumber="0" mode="Continuous" scanAxis="2Theta" status="Completed">
			<header>
				<startTimeStamp>2012-06-15T21:38:12+02:00</startTimeStamp>
				<endTimeStamp>2012-06-15T21:38:16+02:00</endTimeStamp>
				<author>
					<name>Johannes Kepler Univ</name>
				</author>
				<source>
					<applicationSoftware version="2.2i">X'Pert Data Collector</applicationSoftware>
					<instrumentControlSoftware version="2.1E">XPERT-PRO</instrumentControlSoftware>
					<instrumentID>0000000011071750</instrumentID>
				</source>
			</header>
			<scanAxisCenter>
				<position axis="2Theta" unit="deg">66.8283</position>
			</scanAxisCenter>
			<dataPoints>
				<positions axis="2Theta" unit="deg">
[...]
					<name>Johannes Kepler Univ</name>
				</author>
				<source>
					<applicationSoftware version="2.2i">X'Pert Data Collector</applicationSoftware>
					<instrumentControlSoftware version="2.1E">XPERT-PRO</instrumentControlSoftware>
					<instrumentID>0000000011071750</instrumentID>
				</source>
			</header>
			<scanAxisCenter>
				<position axis="2Theta" unit="deg">66.8283</position>
			</scanAxisCenter>
			<dataPoints>
				<positions axis="2Theta" unit="deg">
					<listPositions>65.87550446 65.88300542 65.89050642 65.89800744 65.90550850 65.91300959 65.92051070 65.92801186 65.93551304 65.94301425 65.95051549 65.95801677 65.96551807 65.97301940 65.98052076 65.98802215 65.99552357 66.00302502 66.01052650 66.01802800 66.02552953 66.03303109 66.04053268 66.04803429 66.05553593 66.06303760 66.07053929 66.07804101 66.08554276 66.09304453 66.10054633 66.10804815 66.11554999 66.12305186 66.13055376 66.13805567 66.14555761 66.15305958 66.16056157 66.16806358 66.17556561 66.18306767 66.19056975 66.19807185 66.20557397 66.21307611 66.22057828 66.22808046 66.23558267 66.24308489 66.25058714 66.25808940 66.26559169 66.27309399 66.28059632 66.28809866 66.29560102 66.30310340 66.31060580 66.31810821 66.32561065 66.33311310 66.34061556 66.34811805 66.35562055 66.36312306 66.37062559 66.37812814 66.38563070 66.39313328 66.40063588 66.40813848 66.41564111 66.42314374 66.43064639 66.43814906 66.44565174 66.45315443 66.46065713 66.46815985 66.47566257 66.48316531 66.49066807 66.49817083 66.50567361 66.51317639 66.52067919 66.52818200 66.53568481 66.54318764 66.55069048 66.55819333 66.56569618 66.57319905 66.58070192 66.58820481 66.59570770 66.60321060 66.61071350 66.61821642 66.62571934 66.63322227 66.64072520 66.64822814 66.65573109 66.66323405 66.67073700 66.67823997 66.68574294 66.69324591 66.70074889 66.70825188 66.71575486 66.72325786 66.73076085 66.73826385 66.74576685 66.75326986 66.76077286 66.76827587 66.77577888 66.78328190 66.79078491 66.79828793 66.80579095 66.81329396 66.82079698 66.82830000 66.83580302 66.84330604 66.85080905 66.85831207 66.86581509 66.87331810 66.88082112 66.88832413 66.89582714 66.90333014 66.91083315 66.91833615 66.92583915 66.93334214 66.94084514 66.94834812 66.95585111 66.96335409 66.97085706 66.97836003 66.98586300 66.99336595 67.00086891 67.00837186 67.01587480 67.02337773 67.03088066 67.03838358 67.04588650 67.05338940 67.06089230 67.06839519 67.07589808 67.08340095 67.09090382 67.09840667 67.10590952 67.11341236 67.12091519 67.12841800 67.13592081 67.14342361 67.15092639 67.15842917 67.16593193 67.17343469 67.18093743 67.18844015 67.19594287 67.20344557 67.21094826 67.21845094 67.22595361 67.23345626 67.24095889 67.24846152 67.25596412 67.26346672 67.27096930 67.27847186 67.28597441 67.29347694 67.30097945 67.30848195 67.31598444 67.32348690 67.33098935 67.33849179 67.34599420 67.35349660 67.36099898 67.36850134 67.37600368 67.38350601 67.39100831 67.39851060 67.40601286 67.41351511 67.42101733 67.42851954 67.43602172 67.44352389 67.45102603 67.45852815 67.46603025 67.47353233 67.48103439 67.48853642 67.49603843 67.50354042 67.51104239 67.51854433 67.52604624 67.53354814 67.54105001 67.54855185 67.55605367 67.56355547 67.57105724 67.57855899 67.58606071 67.59356240 67.60106407 67.60856571 67.61606732 67.62356891 67.63107047 67.63857200 67.64607350 67.65357498 67.66107643 67.66857785 67.67607924 67.68358060 67.69108193 67.69858323 67.70608451 67.71358575 67.72108696 67.72858814 67.73608930 67.74359041 67.75109150 67.75859256 67.76609358 67.77359458 67.78109554</listPositions>
				</positions>
				<positions axis="Omega" unit="deg">
					<commonPosition>34.1396</commonPosition>
				</positions>
				<positions axis="Phi" unit="deg">
					<commonPosition>-1.64</commonPosition>
				</positions>
				<positions axis="Psi" unit="deg">
					<commonPosition>0.12</commonPosition>
				</positions>
				<positions axis="X" unit="mm">
					<commonPosition>0.00</commonPosition>
				</positions>
				<positions axis="Y" unit="mm">
					<commonPosition>0.00</commonPosition>
				</positions>
				<positions axis="Z" unit="mm">
					<commonPosition>17.671</commonPosition>
				</positions>
				<commonCountingTime unit="seconds">2.00</commonCountingTime>
				<intensities unit="counts">1 2 1 1 2 1 1 1 0 1 0 2 0 0 2 0 0 0 0 1 2 0 3 0 0 0 0 1 1 3 0 2 0 0 0 0 0 0 1 2 1 1 0 1 1 0 1 2 0 3 2 2 1 1 1 1 3 0 1 0 0 0 1 0 2 2 0 0 1 2 1 4 1 1 2 1 0 1 0 2 1 0 0 1 1 2 3 3 0 0 2 0 3 0 3 1 2 0 1 0 0 1 1 3 0 0 3 0 0 0 1 3 0 1 1 1 0 1 1 1 1 1 4 1 0 1 0 1 0 1 5 0 2 0 3 0 3 0 2 2 1 1 0 0 1 1 2 3 1 3 1 0 1 2 0 1 0 1 0 2 2 0 2 1 1 2 0 0 0 0 2 2 0 3 0 1 2 1 0 1 1 0 0 0 0 1 1 2 2 1 0 2 2 1 0 0 2 0 0 3 1 0 0 3 0 2 2 0 0 3 3 2 1 1 1 1 2 0 0 0 2 1 2 0 3 0 1 2 2 2 1 2 0 2 0 2 1 1 0 3 1 2 2 1 0 6 4 0 1 4 2 2 5 1 3</intensities>
			</dataPoints>
		</scan>
		<scan appendNumber="0" mode="Continuous" scanAxis="2Theta" status="Completed">
			<header>
				<startTimeStamp>2012-06-15T22:32:06+02:00</startTimeStamp>
				<endTimeStamp>2012-06-15T22:32:10+02:00</endTimeStamp>
				<author>
					<name>Johannes Kepler Univ</name>
				</author>
				<source>
					<applicationSoftware version="2.2i">X'Pert Data Collector</applicationSoftware>
					<instrumentControlSoftware version="2.1E">XPERT-PRO</instrumentControlSoftware>
					<instrumentID>0000000011071750</instrumentID>
				</source>
			</header>
			<scanAxisCenter>
				<position axis="2Theta" unit="deg">66.8283</position>
			</scanAxisCenter>
			<dataPoints>
				<positions axis="2Theta" unit="deg">
					<listPositions>65.87550446 65.88300542 65.89050642 65.89800744 65.90550850 65.91300959 65.92051070 65.92801186 65.93551304 65.94301425 65.95051549 65.95801677 65.96551807 65.97301940 65.98052076 65.98802215 65.99552357 66.00302502 66.01052650 66.01802800 66.02552953 66.03303109 66.04053268 66.04803429 66.05553593 66.06303760 66.07053929 66.07804101 66.08554276 66.09304453 66.10054633 66.10804815 66.11554999 66.12305186 66.13055376 66.13805567 66.14555761 66.15305958 66.16056157 66.16806358 66.17556561 66.18306767 66.19056975 66.19807185 66.20557397 66.21307611 66.22057828 66.22808046 66.23558267 66.24308489 66.25058714 66.25808940 66.26559169 66.27309399 66.28059632 66.28809866 66.29560102 66.30310340 66.31060580 66.31810821 66.32561065 66.33311310 66.34061556 66.34811805 66.35562055 66.36312306 66.37062559 66.37812814 66.38563070 66.39313328 66.40063588 66.40813848 66.41564111 66.42314374 66.43064639 66.43814906 66.44565174 66.45315443 66.46065713 66.46815985 66.47566257 66.48316531 66.49066807 66.49817083 66.50567361 66.51317639 66.52067919 66.52818200 66.53568481 66.54318764 66.55069048 66.55819333 66.56569618 66.57319905 66.58070192 66.58820481 66.59570770 66.60321060 66.61071350 66.61821642 66.62571934 66.63322227 66.64072520 66.64822814 66.65573109 66.66323405 66.67073700 66.67823997 66.68574294 66.69324591 66.70074889 66.70825188 66.71575486 66.72325786 66.73076085 66.73826385 66.74576685 66.75326986 66.76077286 66.76827587 66.77577888 66.78328190 66.79078491 66.79828793 66.80579095 66.81329396 66.82079698 66.82830000 66.83580302 66.84330604 66.85080905 66.85831207 66.86581509 66.87331810 66.88082112 66.88832413 66.89582714 66.90333014 66.91083315 66.91833615 66.92583915 66.93334214 66.94084514 66.94834812 66.95585111 66.96335409 66.97085706 66.97836003 66.98586300 66.99336595 67.00086891 67.00837186 67.01587480 67.02337773 67.03088066 67.03838358 67.04588650 67.05338940 67.06089230 67.06839519 67.07589808 67.08340095 67.09090382 67.09840667 67.10590952 67.11341236 67.12091519 67.12841800 67.13592081 67.14342361 67.15092639 67.15842917 67.16593193 67.17343469 67.18093743 67.18844015 67.19594287 67.20344557 67.21094826 67.21845094 67.22595361 67.23345626 67.24095889 67.24846152 67.25596412 67.26346672 67.27096930 67.27847186 67.28597441 67.29347694 67.30097945 67.30848195 67.31598444 67.32348690 67.33098935 67.33849179 67.34599420 67.35349660 67.36099898 67.36850134 67.37600368 67.38350601 67.39100831 67.39851060 67.40601286 67.41351511 67.42101733 67.42851954 67.43602172 67.44352389 67.45102603 67.45852815 67.46603025 67.47353233 67.48103439 67.48853642 67.49603843 67.50354042 67.51104239 67.51854433 67.52604624 67.53354814 67.54105001 67.54855185 67.55605367 67.56355547 67.57105724 67.57855899 67.58606071 67.59356240 67.60106407 67.60856571 67.61606732 67.62356891 67.63107047 67.63857200 67.64607350 67.65357498 67.66107643 67.66857785 67.67607924 67.68358060 67.69108193 67.69858323 67.70608451 67.71358575 67.72108696 67.72858814 67.73608930 67.74359041 67.75109150 67.75859256 67.76609358 67.77359458 67.78109554</listPositions>
				</positions>
				<positions axis="Omega" unit="deg">
					<commonPosition>34.1446</commonPosition>
				</positions>
				<positions axis="Phi" unit="deg">
					<commonPosition>-1.64</commonPosition>
				</positions>
				<positions axis="Psi" unit="deg">
					<commonPosition>0.12</commonPosition>
				</positions>
				<positions axis="X" unit="mm">
					<commonPosition>0.00</commonPosition>
				</positions>
				<positions axis="Y" unit="mm">
					<commonPosition>0.00</commonPosition>
				</positions>
				<positions axis="Z" unit="mm">
					<commonPosition>17.671</commonPosition>
				</positions>
				<commonCountingTime unit="seconds">2.00</commonCountingTime>
				<intensities unit="counts">1 1 0 1 2 0 0 2 0 0 3 1 0 0 0 0 0 1 1 0 0 1 0 3 0 0 0 0 1 1 2 1 1 0 4 1 2 1 0 1 1 0 1 0 2 2 0 0 0 2 2 0 1 0 1 0 2 0 0 0 0 0 2 0 0 0 0 0 0 0 1 0 1 0 0 0 1 4 1 0 1 0 0 2 1 0 2 3 1 0 2 3 0 1 2 3 3 0 0 1 1 0 0 1 0 1 0 1 0 1 1 3 0 0 0 1 1 0 1 2 1 1 1 1 1 1 0 1 1 1 1 1 0 0 1 1 1 1 2 3 2 0 0 1 2 0 1 0 1 1 2 2 1 1 0 1 0 0 3 1 0 1 1 0 1 3 0 0 3 1 0 2 0 3 1 0 1 0 3 0 2 2 1 1 0 0 0 1 2 4 1 1 0 0 2 1 0 3 1 2 2 0 2 2 2 2 3 2 3 2 2 1 3 0 1 3 1 1 3 0 0 2 0 1 1 2 1 0 2 3 0 2 0 0 1 0 1 1 1 2 1 2 2 2 1 0 0 0 0 2 0 3 2 1 0</intensities>
			</dataPoints>
		</scan>
		<scan appendNumber="0" mode="Continuous" scanAxis="2Theta" status="Completed">
			<header>
				<startTimeStamp>2012-06-15T22:32:15+02:00</startTimeStamp>
				<endTimeStamp>2012-06-15T22:32:19+02:00</endTimeStamp>
				<author>
					<name>Johannes Kepler Univ</name>
				</author>
				<source>
					<applicationSoftware version="2.2i">X'Pert Data Collector</applicationSoftware>
					<instrumentControlSoftware version="2.1E">XPERT-PRO</instrumentControlSoftware>
					<instrumentID>0000000011071750</instrumentID>
				</source>
			</header>
			<scanAxisCenter>
				<position axis="2Theta" unit="deg">66.8283</position>
			</scanAxisCenter>
			<dataPoints>
				<positions axis="2Theta" unit="deg">
					<listPositions>65.87550446 65.88300542 65.89050642 65.89800744 65.90550850 65.91300959 65.92051070 65.92801186 65.93551304 65.94301425 65.95051549 65.95801677 65.96551807 65.97301940 65.98052076 65.98802215 65.99552357 66.00302502 66.01052650 66.01802800 66.02552953 66.03303109 66.04053268 66.04803429 66.05553593 66.06303760 66.07053929 66.07804101 66.08554276 66.09304453 66.10054633 66.10804815 66.11554999 66.12305186 66.13055376 66.13805567 66.14555761 66.15305958 66.16056157 66.16806358 66.17556561 66.18306767 66.19056975 66.19807185 66.20557397 66.21307611 66.22057828 66.22808046 66.23558267 66.24308489 66.25058714 66.25808940 66.26559169 66.27309399 66.28059632 66.28809866 66.29560102 66.30310340 66.31060580 66.31810821 66.32561065 66.33311310 66.34061556 66.34811805 66.35562055 66.36312306 66.37062559 66.37812814 66.38563070 66.39313328 66.40063588 66.40813848 66.41564111 66.42314374 66.43064639 66.43814906 66.44565174 66.45315443 66.46065713 66.46815985 66.47566257 66.48316531 66.49066807 66.49817083 66.50567361 66.51317639 66.52067919 66.52818200 66.53568481 66.54318764 66.55069048 66.55819333 66.56569618 66.57319905 66.58070192 66.58820481 66.59570770 66.60321060 66.61071350 66.61821642 66.62571934 66.63322227 66.64072520 66.64822814 66.65573109 66.66323405 66.67073700 66.67823997 66.68574294 66.69324591 66.70074889 66.70825188 66.71575486 66.72325786 66.73076085 66.73826385 66.74576685 66.75326986 66.76077286 66.76827587 66.77577888 66.78328190 66.79078491 66.79828793 66.80579095 66.81329396 66.82079698 66.82830000 66.83580302 66.84330604 66.85080905 66.85831207 66.86581509 66.87331810 66.88082112 66.88832413 66.89582714 66.90333014 66.91083315 66.91833615 66.92583915 66.93334214 66.94084514 66.94834812 66.95585111 66.96335409 66.97085706 66.97836003 66.98586300 66.99336595 67.00086891 67.00837186 67.01587480 67.02337773 67.03088066 67.03838358 67.04588650 67.05338940 67.06089230 67.06839519 67.07589808 67.08340095 67.09090382 67.09840667 67.10590952 67.11341236 67.12091519 67.12841800 67.13592081 67.14342361 67.15092639 67.15842917 67.16593193 67.17343469 67.18093743 67.18844015 67.19594287 67.20344557 67.21094826 67.21845094 67.22595361 67.23345626 67.24095889 67.24846152 67.25596412 67.26346672 67.27096930 67.27847186 67.28597441 67.29347694 67.30097945 67.30848195 67.31598444 67.32348690 67.33098935 67.33849179 67.34599420 67.35349660 67.36099898 67.36850134 67.37600368 67.38350601 67.39100831 67.39851060 67.40601286 67.41351511 67.42101733 67.42851954 67.43602172 67.44352389 67.45102603 67.45852815 67.46603025 67.47353233 67.48103439 67.48853642 67.49603843 67.50354042 67.51104239 67.51854433 67.52604624 67.53354814 67.54105001 67.54855185 67.55605367 67.56355547 67.57105724 67.57855899 67.58606071 67.59356240 67.60106407 67.60856571 67.61606732 67.62356891 67.63107047 67.63857200 67.64607350 67.65357498 67.66107643 67.66857785 67.67607924 67.68358060 67.69108193 67.69858323 67.70608451 67.71358575 67.72108696 67.72858814 67.73608930 67.74359041 67.75109150 67.75859256 67.76609358 67.77359458 67.78109554</listPositions>
				</positions>
				<positions axis="Omega" unit="deg">
					<commonPosition>34.1496</commonPosition>
				</positions>
				<positions axis="Phi" unit="deg">
					<commonPosition>-1.64</commonPosition>
				</positions>
				<positions axis="Psi" unit="deg">
					<commonPosition>0.12</commonPosition>
				</positions>
				<positions axis="X" unit="mm">
					<commonPosition>0.00</commonPosition>
				</positions>
				<positions axis="Y" unit="mm">
					<commonPosition>0.00</commonPosition>
				</positions>
				<positions axis="Z" unit="mm">
					<commonPosition>17.671</commonPosition>
				</positions>
				<commonCountingTime unit="seconds">2.00</commonCountingTime>
				<intensities unit="counts">0 1 0 0 0 1 1 2 1 0 0 0 1 1 1 1 2 0 0 1 1 0 3 0 1 1 1 1 1 1 1 0 0 1 0 1 1 0 0 1 1 2 1 0 1 1 2 0 2 0 1 1 1 1 0 1 1 1 1 1 0 1 1 0 0 1 0 0 1 0 0 4 1 2 0 0 0 1 0 0 0 1 0 0 1 0 2 1 2 3 1 0 3 3 0 1 0 2 0 0 0 3 0 2 1 0 1 1 0 1 1 0 2 2 0 0 0 1 1 2 1 1 0 1 3 1 1 0 1 1 2 2 2 2 0 2 2 1 0 0 0 3 0 1 3 0 1 1 1 0 2 0 1 0 1 1 4 0 3 0 1 2 0 1 2 3 0 3 3 2 1 3 0 1 1 3 3 2 1 4 1 2 2 1 1 1 4 1 1 0 2 1 2 1 1 1 1 1 2 1 0 2 1 2 0 0 2 0 3 1 1 1 1 3 1 1 2 1 0 3 0 4 1 2 1 0 2 2 2 3 4 1 4 1 3 1 3 0 1 1 3 1 1 2 0 1 0 1 0 2 2 0 1 4 1</intensities>
			</dataPoints>
		</scan>
		<scan appendNumber="0" mode="Continuous" scanAxis="2Theta" status="Completed">
			<header>
				<startTimeStamp>2012-06-15T22:32:24+02:00</startTimeStamp>
				<endTimeStamp>2012-06-15T22:32:28+02:00</endTimeStamp>
				<author>
					<name>Johannes Kepler Univ</name>
				</author>
				<source>
					<applicationSoftware version="2.2i">X'Pert Data Collector</applicationSoftware>
					<instrumentControlSoftware version="2.1E">XPERT-PRO</instrumentControlSoftware>
					<instrumentID>0000000011071750</instrumentID>
				</source>
			</header>
			<scanAxisCenter>
				<position axis="2Theta" unit="deg">66.8283</position>
			</scanAxisCenter>
			<dataPoints>
				<positions axis="2Theta" unit="deg">
					<listPositions>65.87550446 65.88300542 65.89050642 65.89800744 65.90550850 65.91300959 65.92051070 65.92801186 65.93551304 65.94301425 65.95051549 65.95801677 65.96551807 65.97301940 65.98052076 65.98802215 65.99552357 66.00302502 66.01052650 66.01802800 66.02552953 66.03303109 66.04053268 66.04803429 66.05553593 66.06303760 66.07053929 66.07804101 66.08554276 66.09304453 66.10054633 66.10804815 66.11554999 66.12305186 66.13055376 66.13805567 66.14555761 66.15305958 66.16056157 66.16806358 66.17556561 66.18306767 66.19056975 66.19807185 66.20557397 66.21307611 66.22057828 66.22808046 66.23558267 66.24308489 66.25058714 66.25808940 66.26559169 66.27309399 66.28059632 66.28809866 66.29560102 66.30310340 66.31060580 66.31810821 66.32561065 66.33311310 66.34061556 66.34811805 66.35562055 66.36312306 66.37062559 66.37812814 66.38563070 66.39313328 66.40063588 66.40813848 66.41564111 66.42314374 66.43064639 66.43814906 66.44565174 66.45315443 66.46065713 66.46815985 66.47566257 66.48316531 66.49066807 66.49817083 66.50567361 66.51317639 66.52067919 66.52818200 66.53568481 66.54318764 66.55069048 66.55819333 66.56569618 66.57319905 66.58070192 66.58820481 66.59570770 66.60321060 66.61071350 66.61821642 66.62571934 66.63322227 66.64072520 66.64822814 66.65573109 66.66323405 66.67073700 66.67823997 66.68574294 66.69324591 66.70074889 66.70825188 66.71575486 66.72325786 66.73076085 66.73826385 66.74576685 66.75326986 66.76077286 66.76827587 66.77577888 66.78328190 66.79078491 66.79828793 66.80579095 66.81329396 66.82079698 66.82830000 66.83580302 66.84330604 66.85080905 66.85831207 66.86581509 66.87331810 66.88082112 66.88832413 66.89582714 66.90333014 66.91083315 66.91833615 66.92583915 66.93334214 66.94084514 66.94834812 66.95585111 66.96335409 66.97085706 66.97836003 66.98586300 66.99336595 67.00086891 67.00837186 67.01587480 67.02337773 67.03088066 67.03838358 67.04588650 67.05338940 67.06089230 67.06839519 67.07589808 67.08340095 67.09090382 67.09840667 67.10590952 67.11341236 67.12091519 67.12841800 67.13592081 67.14342361 67.15092639 67.15842917 67.16593193 67.17343469 67.18093743 67.18844015 67.19594287 67.20344557 67.21094826 67.21845094 67.22595361 67.23345626 67.24095889 67.24846152 67.25596412 67.26346672 67.27096930 67.27847186 67.28597441 67.29347694 67.30097945 67.30848195 67.31598444 67.32348690 67.33098935 67.33849179 67.34599420 67.35349660 67.36099898 67.36850134 67.37600368 67.38350601 67.39100831 67.39851060 67.40601286 67.41351511 67.42101733 67.42851954 67.43602172 67.44352389 67.45102603 67.45852815 67.46603025 67.47353233 67.48103439 67.48853642 67.49603843 67.50354042 67.51104239 67.51854433 67.52604624 67.53354814 67.54105001 67.54855185 67.55605367 67.56355547 67.57105724 67.57855899 67.58606071 67.59356240 67.60106407 67.60856571 67.61606732 67.62356891 67.63107047 67.63857200 67.64607350 67.65357498 67.66107643 67.66857785 67.67607924 67.68358060 67.69108193 67.69858323 67.70608451 67.71358575 67.72108696 67.72858814 67.73608930 67.74359041 67.75109150 67.75859256 67.76609358 67.77359458 67.78109554</listPositions>
				</positions>
				<positions axis="Omega" unit="deg">
					<commonPosition>34.1546</commonPosition>
				</positions>
				<positions axis="Phi" unit="deg">
					<commonPosition>-1.64</commonPosition>
				</positions>
				<positions axis="Psi" unit="deg">
					<commonPosition>0.12</commonPosition>
				</positions>
				<positions axis="X" unit="mm">
					<commonPosition>0.00</commonPosition>
				</positions>
				<positions axis="Y" unit="mm">
					<commonPosition>0.00</commonPosition>
				</positions>
				<positions axis="Z" unit="mm">
					<commonPosition>17.671</commonPosition>
				</positions>
				<commonCountingTime unit="seconds">2.00</commonCountingTime>
				<intensities unit="counts">0 1 0 0 3 0 0 2 0 0 2 1 1 0 0 0 1 2 1 1 0 1 1 1 1 0 1 0 2 0 0 0 1 0 1 0 0 1 0 3 1 2 2 1 1 1 1 0 0 0 0 0 0 0 2 0 0 1 3 1 0 1 1 0 0 1 1 1 0 1 1 1 0 0 1 0 0 1 2 0 0 0 2 0 1 0 2 2 0 0 1 0 0 0 0 0 2 2 0 0 0 1 2 1 0 0 0 2 0 1 1 0 0 1 2 1 1 1 1 1 0 1 0 0 3 0 1 1 1 4 3 0 0 2 1 0 2 1 0 2 0 3 1 0 0 2 1 1 4 2 2 2 1 1 2 2 2 1 0 0 2 3 0 1 1 1 2 1 0 2 1 1 1 0 0 1 2 1 0 1 0 3 2 1 1 0 0 3 1 2 2 1 2 0 3 0 1 2 0 2 1 0 1 3 2 1 2 1 1 0 3 4 0 0 2 3 0 1 2 1 1 3 1 1 0 2 1 3 1 2 1 2 2 3 2 1 2 0 1 3 3 1 2 5 2 2 3 1 2 0 0 0 4 5 1</intensities>
			</dataPoints>
		</scan>
	</xrdMeasurement>
</xrdMeasurements>