File: examples/data/rsm_3.xrdml
<?xml version="1.0" encoding="UTF-8"?>
<xrdMeasurements xmlns="http://www.xrdml.com/XRDMeasurement/1.3" xmlns:xsi="http://www.w3.org/2001/XMLSchema-instance" xsi:schemaLocation="http://www.xrdml.com/XRDMeasurement/1.3 http://www.xrdml.com/XRDMeasurement/1.3/XRDMeasurement.xsd" status="Completed">
	<comment>
		<entry>Configuration=Factory configuration, Owner=User-1, Creation date=6/4/2010 10:23:02 AM</entry>
		<entry>Goniometer=PW3050/65 (Theta/2Theta); Minimum step size 2Theta:0.0001; Minimum step size Omega:0.0001</entry>
		<entry>Sample stage=MRD XL Cradle; Minimum step size Phi:0.01; Minimum step size Psi:0.01; Minimum step size X:0.01; Minimum step size Y:0.01; Minimum step size Z:0.001</entry>
		<entry>Diffractometer system=XPERT-PRO</entry>
		<entry>Measurement program=GreenSi_map_2deg2s, Owner=tanja, Creation date=3/19/2012 10:07:21 AM</entry>
		<entry>Fine Calibration Offset for 2Theta = -0.0192 deg</entry>
		<entry>Fine Calibration Offset for Omega = 0.1691 deg</entry>
		<entry>Batch program=Rastelli_XRR_XRD_short_period_sample5, Owner=tanja, Creation date=6/15/2012 3:39:26 PM</entry>
	</comment>
	<sample type="To be analyzed">
		<id></id>
		<name></name>
		<preparedBy></preparedBy>
	</sample>
	<xrdMeasurement measurementType="Area measurement" status="Completed" measurementStepAxis="Omega" sampleMode="Reflection">
		<comment>
			<entry/>
		</comment>
		<usedWavelength intended="K-Alpha 1">
			<kAlpha1 unit="Angstrom">1.5405980</kAlpha1>
			<kAlpha2 unit="Angstrom">1.5444260</kAlpha2>
			<kBeta unit="Angstrom">1.3922500</kBeta>
			<ratioKAlpha2KAlpha1>0.5000</ratioKAlpha2KAlpha1>
		</usedWavelength>
		<incidentBeamPath>
			<radius unit="mm">420.00</radius>
			<xRayTube id="1010048" name="PW3373/10 Cu LFF DK394719">
				<tension unit="kV">45</tension>
				<current unit="mA">40</current>
				<anodeMaterial>Cu</anodeMaterial>
				<focus type="Line">
					<length unit="mm">12.0</length>
					<width unit="mm">0.4</width>
					<takeOffAngle unit="deg">3.7</takeOffAngle>
				</focus>
			</xRayTube>
			<xRayMirror id="27090001" name="Inc. Beam Cu W/Si (hybrid MRD)" hybrid="true">
				<crystal type="Graded" shape="Parabolic">W/Si</crystal>
				<acceptanceAngle unit="deg">0.8</acceptanceAngle>
				<length unit="mm">60.0</length>
			</xRayMirror>
			<monochromator id="23090002" name="Inc. Beam 2xGe220 Cu Asym. (hybrid)" hybrid="true">
				<crystal type="Asymmetric" shape="Flat">Ge</crystal>
				<numberOfReflections>2</numberOfReflections>
				<hkl>
					<h>2</h>
					<k>2</k>
					<l>0</l>
				</hkl>
			</monochromator>
			<divergenceSlit id="22010009" name="Slit Fixed 1/16Â°" xsi:type="fixedDivergenceSlitType">
				<distanceToSample unit="mm">320.00</distanceToSample>
				<height unit="mm">0.10</height>
			</divergenceSlit>
		</incidentBeamPath>
		<sampleOffset>
			<position axis="2Theta" unit="deg">0.0000</position>
			<position axis="Omega" unit="deg">0.0000</position>
		</sampleOffset>
		<diffractedBeamPath>
			<radius unit="mm">420.00</radius>
			<antiScatterSlit id="22090014" name="AS Slit 5.0 mm (PIXcel non-ambient &amp; MRD)" xsi:type="fixedAntiScatterSlitType">
				<height unit="mm">5.00</height>
			</antiScatterSlit>
			<detector id="7010015" name="PIXcel" xsi:type="rtmsDetectorType">
				<phd>
					<lowerLevel unit="%">25.5</lowerLevel>
					<upperLevel unit="%">100.0</upperLevel>
				</phd>
				<mode>Static</mode>
				<activeLength unit="deg">1.9131</activeLength>
			</detector>
		</diffractedBeamPath>
		<measurementStepAxisCenter>
			<position axis="Omega" unit="deg">32.2546</position>
		</measurementStepAxisCenter>
		<scan appendNumber="0" mode="Continuous" scanAxis="2Theta" status="Completed">
			<header>
				<startTimeStamp>2012-06-15T22:32:50+02:00</startTimeStamp>
				<endTimeStamp>2012-06-15T22:32:53+02:00</endTimeStamp>
				<author>
					<name>Johannes Kepler Univ</name>
				</author>
				<source>
					<applicationSoftware version="2.2i">X'Pert Data Collector</applicationSoftware>
					<instrumentControlSoftware version="2.1E">XPERT-PRO</instrumentControlSoftware>
					<instrumentID>0000000011071750</instrumentID>
				</source>
			</header>
			<scanAxisCenter>
				<position axis="2Theta" unit="deg">65.0283</position>
			</scanAxisCenter>
			<dataPoints>
				<positions axis="2Theta" unit="deg">
					<listPositions>64.07550446 64.08300542 64.09050642 64.09800744 64.10550850 64.11300959 64.12051070 64.12801186 64.13551304 64.14301425 64.15051549 64.15801677 64.16551807 64.17301940 64.18052076 64.18802215 64.19552357 64.20302502 64.21052650 64.21802800 64.22552953 64.23303109 64.24053268 64.24803429 64.25553593 64.26303760 64.27053929 64.27804101 64.28554276 64.29304453 64.30054633 64.30804815 64.31554999 64.32305186 64.33055376 64.33805567 64.34555761 64.35305958 64.36056157 64.36806358 64.37556561 64.38306767 64.39056975 64.39807185 64.40557397 64.41307611 64.42057828 64.42808046 64.43558267 64.44308489 64.45058714 64.45808940 64.46559169 64.47309399 64.48059632 64.48809866 64.49560102 64.50310340 64.51060580 64.51810821 64.52561065 64.53311310 64.54061556 64.54811805 64.55562055 64.56312306 64.57062559 64.57812814 64.58563070 64.59313328 64.60063588 64.60813848 64.61564111 64.62314374 64.63064639 64.63814906 64.64565174 64.65315443 64.66065713 64.66815985 64.67566257 64.68316531 64.69066807 64.69817083 64.70567361 64.71317639 64.72067919 64.72818200 64.73568481 64.74318764 64.75069048 64.75819333 64.76569618 64.77319905 64.78070192 64.78820481 64.79570770 64.80321060 64.81071350 64.81821642 64.82571934 64.83322227 64.84072520 64.84822814 64.85573109 64.86323405 64.87073700 64.87823997 64.88574294 64.89324591 64.90074889 64.90825188 64.91575486 64.92325786 64.93076085 64.93826385 64.94576685 64.95326986 64.96077286 64.96827587 64.97577888 64.98328190 64.99078491 64.99828793 65.00579095 65.01329396 65.02079698 65.02830000 65.03580302 65.04330604 65.05080905 65.05831207 65.06581509 65.07331810 65.08082112 65.08832413 65.09582714 65.10333014 65.11083315 65.11833615 65.12583915 65.13334214 65.14084514 65.14834812 65.15585111 65.16335409 65.17085706 65.17836003 65.18586300 65.19336595 65.20086891 65.20837186 65.21587480 65.22337773 65.23088066 65.23838358 65.24588650 65.25338940 65.26089230 65.26839519 65.27589808 65.28340095 65.29090382 65.29840667 65.30590952 65.31341236 65.32091519 65.32841800 65.33592081 65.34342361 65.35092639 65.35842917 65.36593193 65.37343469 65.38093743 65.38844015 65.39594287 65.40344557 65.41094826 65.41845094 65.42595361 65.43345626 65.44095889 65.44846152 65.45596412 65.46346672 65.47096930 65.47847186 65.48597441 65.49347694 65.50097945 65.50848195 65.51598444 65.52348690 65.53098935 65.53849179 65.54599420 65.55349660 65.56099898 65.56850134 65.57600368 65.58350601 65.59100831 65.59851060 65.60601286 65.61351511 65.62101733 65.62851954 65.63602172 65.64352389 65.65102603 65.65852815 65.66603025 65.67353233 65.68103439 65.68853642 65.69603843 65.70354042 65.71104239 65.71854433 65.72604624 65.73354814 65.74105001 65.74855185 65.75605367 65.76355547 65.77105724 65.77855899 65.78606071 65.79356240 65.80106407 65.80856571 65.81606732 65.82356891 65.83107047 65.83857200 65.84607350 65.85357498 65.86107643 65.86857785 65.87607924 65.88358060 65.89108193 65.89858323 65.90608451 65.91358575 65.92108696 65.92858814 65.93608930 65.94359041 65.95109150 65.95859256 65.96609358 65.97359458 65.98109554</listPositions>
				</positions>
				<positions axis="Omega" unit="deg">
					<commonPosition>31.2546</commonPosition>
				</positions>
				<positions axis="Phi" unit="deg">
					<commonPosition>-1.64</commonPosition>
				</positions>
				<positions axis="Psi" unit="deg">
					<commonPosition>0.12</commonPosition>
				</positions>
				<positions axis="X" unit="mm">
					<commonPosition>0.00</commonPosition>
				</positions>
				<positions axis="Y" unit="mm">
					<commonPosition>0.00</commonPosition>
				</positions>
				<positions axis="Z" unit="mm">
					<commonPosition>17.671</commonPosition>
				</positions>
				<commonCountingTime unit="seconds">2.00</commonCountingTime>
				<intensities unit="counts">4 1 0 0 0 0 1 1 2 0 1 0 0 1 0 1 2 0 0 0 1 2 0 1 0 0 1 0 0 0 0 0 0 3 0 1 0 1 0 0 1 0 0 0 1 1 0 0 1 1 0 1 1 0 1 0 0 0 5 0 0 0 0 0 2 1 0 3 0 2 0 1 2 0 3 0 0 1 2 1 0 1 2 0 3 1 1 0 0 1 0 1 2 0 2 2 3 1 1 2 1 2 0 2 0 1 0 2 2 0 0 0 0 3 0 1 1 1 1 1 1 3 0 0 1 0 0 0 0 1 0 0 0 1 0 2 2 1 1 0 3 2 1 0 0 2 2 0 3 1 1 0 0 2 1 0 1 0 0 0 0 0 1 0 0 0 2 0 0 1 1 1 1 0 1 0 0 0 1 1 1 0 0 2 0 0 0 0 1 1 1 0 0 0 2 1 1 0 1 2 0 1 0 1 0 1 1 0 0 1 0 0 1 3 0 1 1 1 1 3 1 0 3 0 0 2 1 0 0 0 1 0 0 1 0 2 0 1 1 0 0 1 4 1 2 0 2 2 0 0 1 0 0 1 0</intensities>
			</dataPoints>
		</scan>
		<scan appendNumber="0" mode="Continuous" scanAxis="2Theta" status="Completed">
			<header>
				<startTimeStamp>2012-06-15T22:32:57+02:00</startTimeStamp>
				<endTimeStamp>2012-06-15T22:33:01+02:00</endTimeStamp>
				<author>
					<name>Johannes Kepler Univ</name>
				</author>
				<source>
					<applicationSoftware version="2.2i">X'Pert Data Collector</applicationSoftware>
					<instrumentControlSoftware version="2.1E">XPERT-PRO</instrumentControlSoftware>
					<instrumentID>0000000011071750</instrumentID>
				</source>
			</header>
			<scanAxisCenter>
				<position axis="2Theta" unit="deg">65.0283</position>
			</scanAxisCenter>
			<dataPoints>
				<positions axis="2Theta" unit="deg">
					<listPositions>64.07550446 64.08300542 64.09050642 64.09800744 64.10550850 64.11300959 64.12051070 64.12801186 64.13551304 64.14301425 64.15051549 64.15801677 64.16551807 64.17301940 64.18052076 64.18802215 64.19552357 64.20302502 64.21052650 64.21802800 64.22552953 64.23303109 64.24053268 64.24803429 64.25553593 64.26303760 64.27053929 64.27804101 64.28554276 64.29304453 64.30054633 64.30804815 64.31554999 64.32305186 64.33055376 64.33805567 64.34555761 64.35305958 64.36056157 64.36806358 64.37556561 64.38306767 64.39056975 64.39807185 64.40557397 64.41307611 64.42057828 64.42808046 64.43558267 64.44308489 64.45058714 64.45808940 64.46559169 64.47309399 64.48059632 64.48809866 64.49560102 64.50310340 64.51060580 64.51810821 64.52561065 64.53311310 64.54061556 64.54811805 64.55562055 64.56312306 64.57062559 64.57812814 64.58563070 64.59313328 64.60063588 64.60813848 64.61564111 64.62314374 64.63064639 64.63814906 64.64565174 64.65315443 64.66065713 64.66815985 64.67566257 64.68316531 64.69066807 64.69817083 64.70567361 64.71317639 64.72067919 64.72818200 64.73568481 64.74318764 64.75069048 64.75819333 64.76569618 64.77319905 64.78070192 64.78820481 64.79570770 64.80321060 64.81071350 64.81821642 64.82571934 64.83322227 64.84072520 64.84822814 64.85573109 64.86323405 64.87073700 64.87823997 64.88574294 64.89324591 64.90074889 64.90825188 64.91575486 64.92325786 64.93076085 64.93826385 64.94576685 64.95326986 64.96077286 64.96827587 64.97577888 64.98328190 64.99078491 64.99828793 65.00579095 65.01329396 65.02079698 65.02830000 65.03580302 65.04330604 65.05080905 65.05831207 65.06581509 65.07331810 65.08082112 65.08832413 65.09582714 65.10333014 65.11083315 65.11833615 65.12583915 65.13334214 65.14084514 65.14834812 65.15585111 65.16335409 65.17085706 65.17836003 65.18586300 65.19336595 65.20086891 65.20837186 65.21587480 65.22337773 65.23088066 65.23838358 65.24588650 65.25338940 65.26089230 65.26839519 65.27589808 65.28340095 65.29090382 65.29840667 65.30590952 65.31341236 65.32091519 65.32841800 65.33592081 65.34342361 65.35092639 65.35842917 65.36593193 65.37343469 65.38093743 65.38844015 65.39594287 65.40344557 65.41094826 65.41845094 65.42595361 65.43345626 65.44095889 65.44846152 65.45596412 65.46346672 65.47096930 65.47847186 65.48597441 65.49347694 65.50097945 65.50848195 65.51598444 65.52348690 65.53098935 65.53849179 65.54599420 65.55349660 65.56099898 65.56850134 65.57600368 65.58350601 65.59100831 65.59851060 65.60601286 65.61351511 65.62101733 65.62851954 65.63602172 65.64352389 65.65102603 65.65852815 65.66603025 65.67353233 65.68103439 65.68853642 65.69603843 65.70354042 65.71104239 65.71854433 65.72604624 65.73354814 65.74105001 65.74855185 65.75605367 65.76355547 65.77105724 65.77855899 65.78606071 65.79356240 65.80106407 65.80856571 65.81606732 65.82356891 65.83107047 65.83857200 65.84607350 65.85357498 65.86107643 65.86857785 65.87607924 65.88358060 65.89108193 65.89858323 65.90608451 65.91358575 65.92108696 65.92858814 65.93608930 65.94359041 65.95109150 65.95859256 65.96609358 65.97359458 65.98109554</listPositions>
				</positions>
				<positions axis="Omega" unit="deg">
					<commonPosition>31.2596</commonPosition>
				</positions>
				<positions axis="Phi" unit="deg">
					<commonPosition>-1.64</commonPosition>
				</positions>
				<positions axis="Psi" unit="deg">
					<commonPosition>0.12</commonPosition>
				</positions>
				<positions axis="X" unit="mm">
					<commonPosition>0.00</commonPosition>
				</positions>
				<positions axis="Y" unit="mm">
					<commonPosition>0.00</commonPosition>
				</positions>
				<positions axis="Z" unit="mm">
					<commonPosition>17.671</commonPosition>
				</positions>
				<commonCountingTime unit="seconds">2.00</commonCountingTime>
				<intensities unit="counts">0 0 1 0 0 0 2 3 1 0 0 2 3 1 0 0 1 1 2 2 1 0 1 3 1 1 1 1 0 0 1 1 4 0 0 0 1 0 0 0 0 0 0 0 0 0 1 1 1 0 0 0 0 1 1 2 1 3 0 2 1 2 1 1 0 0 0 1 0 1 0 0 3 0 0 0 0 0 1 0 1 0 1 2 0 1 0 1 1 2 0 2 1 1 0 0 1 2 0 1 0 0 0 1 1 0 0 1 1 2 0 0 0 2 2 2 1 1 1 0 2 1 1 1 1 0 0 0 1 0 2 1 1 2 1 1 0 0 0 1 1 0 0 0 0 0 1 0 0 0 0 2 1 3 1 0 2 0 0 2 1 0 0 0 4 1 0 1 4 0 0 0 1 1 0 0 1 0 1 0 0 0 0 1 0 1 1 0 0 0 2 0 3 3 0 0 2 1 0 2 1 0 1 0 2 2 0 0 1 1 4 0 0 0 1 1 1 0 1 0 0 0 0 1 0 1 1 0 0 1 1 1 0 1 0 1 1 2 2 1 1 0 1 0 0 0 1 0 0 1 1 1 0 2 0</intensities>
			</dataPoints>
		</scan>
		<scan appendNumber="0" mode="Continuous" scanAxis="2Theta" status="Completed">
			<header>
				<startTimeStamp>2012-06-15T22:33:05+02:00</startTimeStamp>
				<endTimeStamp>2012-06-15T22:33:09+02:00</endTimeStamp>
				<author>
					<name>Johannes Kepler Univ</name>
				</author>
				<source>
					<applicationSoftware version="2.2i">X'Pert Data Collector</applicationSoftware>
					<instrumentControlSoftware version="2.1E">XPERT-PRO</instrumentControlSoftware>
					<instrumentID>0000000011071750</instrumentID>
				</source>
			</header>
			<scanAxisCenter>
				<position axis="2Theta" unit="deg">65.0283</position>
			</scanAxisCenter>
			<dataPoints>
				<positions axis="2Theta" unit="deg">
					<listPositions>64.07550446 64.08300542 64.09050642 64.09800744 64.10550850 64.11300959 64.12051070 64.12801186 64.13551304 64.14301425 64.15051549 64.15801677 64.16551807 64.17301940 64.18052076 64.18802215 64.19552357 64.20302502 64.21052650 64.21802800 64.22552953 64.23303109 64.24053268 64.24803429 64.25553593 64.26303760 64.27053929 64.27804101 64.28554276 64.29304453 64.30054633 64.30804815 64.31554999 64.32305186 64.33055376 64.33805567 64.34555761 64.35305958 64.36056157 64.36806358 64.37556561 64.38306767 64.39056975 64.39807185 64.40557397 64.41307611 64.42057828 64.42808046 64.43558267 64.44308489 64.45058714 64.45808940 64.46559169 64.47309399 64.48059632 64.48809866 64.49560102 64.50310340 64.51060580 64.51810821 64.52561065 64.53311310 64.54061556 64.54811805 64.55562055 64.56312306 64.57062559 64.57812814 64.58563070 64.59313328 64.60063588 64.60813848 64.61564111 64.62314374 64.63064639 64.63814906 64.64565174 64.65315443 64.66065713 64.66815985 64.67566257 64.68316531 64.69066807 64.69817083 64.70567361 64.71317639 64.72067919 64.72818200 64.73568481 64.74318764 64.75069048 64.75819333 64.76569618 64.77319905 64.78070192 64.78820481 64.79570770 64.80321060 64.81071350 64.81821642 64.82571934 64.83322227 64.84072520 64.84822814 64.85573109 64.86323405 64.87073700 64.87823997 64.88574294 64.89324591 64.90074889 64.90825188 64.91575486 64.92325786 64.93076085 64.93826385 64.94576685 64.95326986 64.96077286 64.96827587 64.97577888 64.98328190 64.99078491 64.99828793 65.00579095 65.01329396 65.02079698 65.02830000 65.03580302 65.04330604 65.05080905 65.05831207 65.06581509 65.07331810 65.08082112 65.08832413 65.09582714 65.10333014 65.11083315 65.11833615 65.12583915 65.13334214 65.14084514 65.14834812 65.15585111 65.16335409 65.17085706 65.17836003 65.18586300 65.19336595 65.20086891 65.20837186 65.21587480 65.22337773 65.23088066 65.23838358 65.24588650 65.25338940 65.26089230 65.26839519 65.27589808 65.28340095 65.29090382 65.29840667 65.30590952 65.31341236 65.32091519 65.32841800 65.33592081 65.34342361 65.35092639 65.35842917 65.36593193 65.37343469 65.38093743 65.38844015 65.39594287 65.40344557 65.41094826 65.41845094 65.42595361 65.43345626 65.44095889 65.44846152 65.45596412 65.46346672 65.47096930 65.47847186 65.48597441 65.49347694 65.50097945 65.50848195 65.51598444 65.52348690 65.53098935 65.53849179 65.54599420 65.55349660 65.56099898 65.56850134 65.57600368 65.58350601 65.59100831 65.59851060 65.60601286 65.61351511 65.62101733 65.62851954 65.63602172 65.64352389 65.65102603 65.65852815 65.66603025 65.67353233 65.68103439 65.68853642 65.69603843 65.70354042 65.71104239 65.71854433 65.72604624 65.73354814 65.74105001 65.74855185 65.75605367 65.76355547 65.77105724 65.77855899 65.78606071 65.79356240 65.80106407 65.80856571 65.81606732 65.82356891 65.83107047 65.83857200 65.84607350 65.85357498 65.86107643 65.86857785 65.87607924 65.88358060 65.89108193 65.89858323 65.90608451 65.91358575 65.92108696 65.92858814 65.93608930 65.94359041 65.95109150 65.95859256 65.96609358 65.97359458 65.98109554</listPositions>
				</positions>
				<positions axis="Omega" unit="deg">
					<commonPosition>31.2646</commonPosition>
				</positions>
				<positions axis="Phi" unit="deg">
					<commonPosition>-1.64</commonPosition>
				</positions>
				<positions axis="Psi" unit="deg">
					<commonPosition>0.12</commonPosition>
				</positions>
				<positions axis="X" unit="mm">
					<commonPosition>0.00</commonPosition>
				</positions>
				<positions axis="Y" unit="mm">
					<commonPosition>0.00</commonPosition>
				</positions>
				<positions axis="Z" unit="mm">
					<commonPosition>17.671</commonPosition>
				</positions>
				<commonCountingTime unit="seconds">2.00</commonCountingTime>
				<intensities unit="counts">1 3 1 0 2 1 0 2 1 1 0 0 0 0 1 0 0 1 0 2 0 2 0 1 2 1 1 0 2 1 0 1 1 2 0 1 1 2 0 1 2 0 2 0 0 1 0 0 1 2 0 0 0 1 0 0 1 1 2 0 0 1 0 1 1 2 1 1 1 0 2 0 3 0 0 1 2 0 0 0 0 1 0 0 3 1 0 2 0 1 1 0 0 1 1 0 2 2 0 2 0 1 2 1 0 0 3 1 0 0 0 1 1 0 0 1 1 0 0 3 1 2 2 0 0 0 1 0 0 0 2 1 0 1 0 0 0 1 2 1 0 0 1 0 3 4 3 0 1 2 1 0 2 0 0 0 1 1 1 2 1 1 1 0 2 1 0 0 0 1 0 0 0 3 1 0 2 1 0 2 0 0 0 0 0 2 1 0 0 1 1 0 0 0 1 1 1 0 0 1 1 2 0 0 1 2 0 1 0 3 0 0 0 0 1 0 0 1 1 0 1 1 2 0 2 2 0 0 0 2 0 0 0 0 0 0 0 1 2 1 1 1 2 0 0 0 1 0 0 0 1 0 1 0 0</intensities>
			</dataPoints>
		</scan>
		<scan appendNumber="0" mode="Continuous" scanAxis="2Theta" status="Completed">
			<header>
				<startTimeStamp>2012-06-15T22:33:13+02:00</startTimeStamp>
				<endTimeStamp>2012-06-15T22:33:17+02:00</endTimeStamp>
				<author>
					<name>Johannes Kepler Univ</name>
				</author>
				<source>
					<applicationSoftware version="2.2i">X'Pert Data Collector</applicationSoftware>
					<instrumentControlSoftware version="2.1E">XPERT-PRO</instrumentControlSoftware>
					<instrumentID>0000000011071750</instrumentID>
				</source>
			</header>
			<scanAxisCenter>
				<position axis="2Theta" unit="deg">65.0283</position>
			</scanAxisCenter>
			<dataPoints>
				<positions axis="2Theta" unit="deg">
					<listPositions>64.07550446 64.08300542 64.09050642 64.09800744 64.10550850 64.11300959 64.12051070 64.12801186 64.13551304 64.14301425 64.15051549 64.15801677 64.16551807 64.17301940 64.18052076 64.18802215 64.19552357 64.20302502 64.21052650 64.21802800 64.22552953 64.23303109 64.24053268 64.24803429 64.25553593 64.26303760 64.27053929 64.27804101 64.28554276 64.29304453 64.30054633 64.30804815 64.31554999 64.32305186 64.33055376 64.33805567 64.34555761 64.35305958 64.36056157 64.36806358 64.37556561 64.38306767 64.39056975 64.39807185 64.40557397 64.41307611 64.42057828 64.42808046 64.43558267 64.44308489 64.45058714 64.45808940 64.46559169 64.47309399 64.48059632 64.48809866 64.49560102 64.50310340 64.51060580 64.51810821 64.52561065 64.53311310 64.54061556 64.54811805 64.55562055 64.56312306 64.57062559 64.57812814 64.58563070 64.59313328 64.60063588 64.60813848 64.61564111 64.62314374 64.63064639 64.63814906 64.64565174 64.65315443 64.66065713 64.66815985 64.67566257 64.68316531 64.69066807 64.69817083 64.70567361 64.71317639 64.72067919 64.72818200 64.73568481 64.74318764 64.75069048 64.75819333 64.76569618 64.77319905 64.78070192 64.78820481 64.79570770 64.80321060 64.81071350 64.81821642 64.82571934 64.83322227 64.84072520 64.84822814 64.85573109 64.86323405 64.87073700 64.87823997 64.88574294 64.89324591 64.90074889 64.90825188 64.91575486 64.92325786 64.93076085 64.93826385 64.94576685 64.95326986 64.96077286 64.96827587 64.97577888 64.98328190 64.99078491 64.99828793 65.00579095 65.01329396 65.02079698 65.02830000 65.03580302 65.04330604 65.05080905 65.05831207 65.06581509 65.07331810 65.08082112 65.08832413 65.09582714 65.10333014 65.11083315 65.11833615 65.12583915 65.13334214 65.14084514 65.14834812 65.15585111 65.16335409 65.17085706 65.17836003 65.18586300 65.19336595 65.20086891 65.20837186 65.21587480 65.22337773 65.23088066 65.23838358 65.24588650 65.25338940 65.26089230 65.26839519 65.27589808 65.28340095 65.29090382 65.29840667 65.30590952 65.31341236 65.32091519 65.32841800 65.33592081 65.34342361 65.35092639 65.35842917 65.36593193 65.37343469 65.38093743 65.38844015 65.39594287 65.40344557 65.41094826 65.41845094 65.42595361 65.43345626 65.44095889 65.44846152 65.45596412 65.46346672 65.47096930 65.47847186 65.48597441 65.49347694 65.50097945 65.50848195 65.51598444 65.52348690 65.53098935 65.53849179 65.54599420 65.55349660 65.56099898 65.56850134 65.57600368 65.58350601 65.59100831 65.59851060 65.60601286 65.61351511 65.62101733 65.62851954 65.63602172 65.64352389 65.65102603 65.65852815 65.66603025 65.67353233 65.68103439 65.68853642 65.69603843 65.70354042 65.71104239 65.71854433 65.72604624 65.73354814 65.74105001 65.74855185 65.75605367 65.76355547 65.77105724 65.77855899 65.78606071 65.79356240 65.80106407 65.80856571 65.81606732 65.82356891 65.83107047 65.83857200 65.84607350 65.85357498 65.86107643 65.86857785 65.87607924 65.88358060 65.89108193 65.89858323 65.90608451 65.91358575 65.92108696 65.92858814 65.93608930 65.94359041 65.95109150 65.95859256 65.96609358 65.97359458 65.98109554</listPositions>
				</positions>
				<positions axis="Omega" unit="deg">
					<commonPosition>31.2696</commonPosition>
				</positions>
				<positions axis="Phi" unit="deg">
					<commonPosition>-1.64</commonPosition>
				</positions>
				<positions axis="Psi" unit="deg">
					<commonPosition>0.12</commonPosition>
				</positions>
				<positions axis="X" unit="mm">
					<commonPosition>0.00</commonPosition>
				</positions>
				<positions axis="Y" unit="mm">
					<commonPosition>0.00</commonPosition>
				</positions>
				<positions axis="Z" unit="mm">
					<commonPosition>17.671</commonPosition>
				</positions>
				<commonCountingTime unit="seconds">2.00</commonCountingTime>
				<intensities unit="counts">1 1 3 0 1 2 0 0 0 0 1 0 1 1 0 1 2 1 0 0 1 1 0 1 1 1 2 0 2 0 0 0 0 1 0 2 0 2 1 0 1 0 2 0 0 2 0 2 1 0 0 1 0 1 0 1 1 0 1 2 1 0 0 1 1 1 0 1 0 0 1 1 0 0 3 1 1 2 0 1 0 1 1 0 0 3 2 1 0 0 0 1 0 1 1 0 1 0 2 2 1 1 1 1 1 1 2 0 1 0 2 3 1 0 0 1 0 0 1 0 2 1 1 0 1 0 1 1 3 1 1 1 1 1 2 0 1 3 3 0 1 0 0 1 0 0 0 1 0 2 0 2 0 0 0 1 0 1 3 3 0 0 0 1 1 0 0 0 0 0 1 1 1 1 2 1 1 1 0 1 0 0 1 0 4 1 1 0 1 0 2 0 0 2 1 2 1 0 1 0 1 1 0 0 0 1 0 1 1 1 0 1 0 1 1 2 1 1 1 3 0 0 2 1 1 0 0 1 0 1 3 1 0 0 1 1 0 0 1 0 0 1 2 1 0 0 1 0 0 0 0 1 2 0 0</intensities>
			</dataPoints>
		</scan>
		<scan appendNumber="0" mode="Continuous" scanAxis="2Theta" status="Completed">
			<header>
				<startTimeStamp>2012-06-15T22:33:21+02:00</startTimeStamp>
				<endTimeStamp>2012-06-15T22:33:25+02:00</endTimeStamp>
				<author>
					<name>Johannes Kepler Univ</name>
				</author>
				<source>
					<applicationSoftware version="2.2i">X'Pert Data Collector</applicationSoftware>
					<instrumentControlSoftware version="2.1E">XPERT-PRO</instrumentControlSoftware>
					<instrumentID>0000000011071750</instrumentID>
				</source>
			</header>
			<scanAxisCenter>
				<position axis="2Theta" unit="deg">65.0283</position>
			</scanAxisCenter>
			<dataPoints>
				<positions axis="2Theta" unit="deg">
					<listPositions>64.07550446 64.08300542 64.09050642 64.09800744 64.10550850 64.11300959 64.12051070 64.12801186 64.13551304 64.14301425 64.15051549 64.15801677 64.16551807 64.17301940 64.18052076 64.18802215 64.19552357 64.20302502 64.21052650 64.21802800 64.22552953 64.23303109 64.24053268 64.24803429 64.25553593 64.26303760 64.27053929 64.27804101 64.28554276 64.29304453 64.30054633 64.30804815 64.31554999 64.32305186 64.33055376 64.33805567 64.34555761 64.35305958 64.36056157 64.36806358 64.37556561 64.38306767 64.39056975 64.39807185 64.40557397 64.41307611 64.42057828 64.42808046 64.43558267 64.44308489 64.45058714 64.45808940 64.46559169 64.47309399 64.48059632 64.48809866 64.49560102 64.50310340 64.51060580 64.51810821 64.52561065 64.53311310 64.54061556 64.54811805 64.55562055 64.56312306 64.57062559 64.57812814 64.58563070 64.59313328 64.60063588 64.60813848 64.61564111 64.62314374 64.63064639 64.63814906 64.64565174 64.65315443 64.66065713 64.66815985 64.67566257 64.68316531 64.69066807 64.69817083 64.70567361 64.71317639 64.72067919 64.72818200 64.73568481 64.74318764 64.75069048 64.75819333 64.76569618 64.77319905 64.78070192 64.78820481 64.79570770 64.80321060 64.81071350 64.81821642 64.82571934 64.83322227 64.84072520 64.84822814 64.85573109 64.86323405 64.87073700 64.87823997 64.88574294 64.89324591 64.90074889 64.90825188 64.91575486 64.92325786 64.93076085 64.93826385 64.94576685 64.95326986 64.96077286 64.96827587 64.97577888 64.98328190 64.99078491 64.99828793 65.00579095 65.01329396 65.02079698 65.02830000 65.03580302 65.04330604 65.05080905 65.05831207 65.06581509 65.07331810 65.08082112 65.08832413 65.09582714 65.10333014 65.11083315 65.11833615 65.12583915 65.13334214 65.14084514 65.14834812 65.15585111 65.16335409 65.17085706 65.17836003 65.18586300 65.19336595 65.20086891 65.20837186 65.21587480 65.22337773 65.23088066 65.23838358 65.24588650 65.25338940 65.26089230 65.26839519 65.27589808 65.28340095 65.29090382 65.29840667 65.30590952 65.31341236 65.32091519 65.32841800 65.33592081 65.34342361 65.35092639 65.35842917 65.36593193 65.37343469 65.38093743 65.38844015 65.39594287 65.40344557 65.41094826 65.41845094 65.42595361 65.43345626 65.44095889 65.44846152 65.45596412 65.46346672 65.47096930 65.47847186 65.48597441 65.49347694 65.50097945 65.50848195 65.51598444 65.52348690 65.53098935 65.53849179 65.54599420 65.55349660 65.56099898 65.56850134 65.57600368 65.58350601 65.59100831 65.59851060 65.60601286 65.61351511 65.62101733 65.62851954 65.63602172 65.64352389 65.65102603 65.65852815 65.66603025 65.67353233 65.68103439 65.68853642 65.69603843 65.70354042 65.71104239 65.71854433 65.72604624 65.73354814 65.74105001 65.74855185 65.75605367 65.76355547 65.77105724 65.77855899 65.78606071 65.79356240 65.80106407 65.80856571 65.81606732 65.82356891 65.83107047 65.83857200 65.84607350 65.85357498 65.86107643 65.86857785 65.87607924 65.88358060 65.89108193 65.89858323 65.90608451 65.91358575 65.92108696 65.92858814 65.93608930 65.94359041 65.95109150 65.95859256 65.96609358 65.97359458 65.98109554</listPositions>
				</positions>
				<positions axis="Omega" unit="deg">
					<commonPosition>31.2746</commonPosition>
				</positions>
				<positions axis="Phi" unit="deg">
					<commonPosition>-1.64</commonPosition>
				</positions>
				<positions axis="Psi" unit="deg">
					<commonPosition>0.12</commonPosition>
				</positions>
				<positions axis="X" unit="mm">
					<commonPosition>0.00</commonPosition>
				</positions>
				<positions axis="Y" unit="mm">
					<commonPosition>0.00</commonPosition>
				</positions>
				<positions axis="Z" unit="mm">
					<commonPosition>17.671</commonPosition>
				</positions>
				<commonCountingTime unit="seconds">2.00</commonCountingTime>
				<intensities unit="counts">0 1 1 0 3 0 1 1 1 0 0 0 0 0 2 4 0 1 1 1 2 2 2 2 1 0 2 1 0 2 0 1 2 0 0 2 1 0 1 1 1 1 0 4 2 0 1 2 0 1 3 0 2 1 1 0 2 0 1 1 1 2 0 0 1 0 0 1 0 1 1 1 1 1 0 2 1 1 1 2 1 0 0 0 1 0 0 1 2 0 2 0 1 1 3 0 1 0 0 2 1 0 3 1 0 0 1 0 1 2 1 0 1 3 2 2 0 1 0 0 0 2 1 0 1 0 1 0 2 0 0 0 1 2 1 2 3 0 0 0 0 0 1 0 0 1 1 1 1 1 0 0 0 0 1 1 0 0 0 0 2 0 1 4 1 0 0 0 0 2 2 0 0 1 1 3 1 2 1 1 0 1 0 0 1 1 0 2 0 0 0 2 0 0 2 1 2 0 2 0 1 1 0 1 0 1 2 2 3 0 1 1 0 1 1 2 1 1 0 2 1 2 1 0 0 0 0 2 1 0 0 0 2 0 0 0 1 1 0 1 3 0 0 2 0 1 3 0 2 0 1 0 1 1 1</intensities>
			</dataPoints>
		</scan>
		<scan appendNumber="0" mode="Continuous" scanAxis="2Theta" status="Completed">
			<header>
				<startTimeStamp>2012-06-15T22:33:29+02:00</startTimeStamp>
				<endTimeStamp>2012-06-15T22:33:33+02:00</endTimeStamp>
				<author>
					<name>Johannes Kepler Univ</name>
				</author>
				<source>
					<applicationSoftware version="2.2i">X'Pert Data Collector</applicationSoftware>
					<instrumentControlSoftware version="2.1E">XPERT-PRO</instrumentControlSoftware>
					<instrumentID>0000000011071750</instrumentID>
				</source>
			</header>
			<scanAxisCenter>
				<position axis="2Theta" unit="deg">65.0283</position>
			</scanAxisCenter>
			<dataPoints>
				<positions axis="2Theta" unit="deg">
					<listPositions>64.07550446 64.08300542 64.09050642 64.09800744 64.10550850 64.11300959 64.12051070 64.12801186 64.13551304 64.14301425 64.15051549 64.15801677 64.16551807 64.17301940 64.18052076 64.18802215 64.19552357 64.20302502 64.21052650 64.21802800 64.22552953 64.23303109 64.24053268 64.24803429 64.25553593 64.26303760 64.27053929 64.27804101 64.28554276 64.29304453 64.30054633 64.30804815 64.31554999 64.32305186 64.33055376 64.33805567 64.34555761 64.35305958 64.36056157 64.36806358 64.37556561 64.38306767 64.39056975 64.39807185 64.40557397 64.41307611 64.42057828 64.42808046 64.43558267 64.44308489 64.45058714 64.45808940 64.46559169 64.47309399 64.48059632 64.48809866 64.49560102 64.50310340 64.51060580 64.51810821 64.52561065 64.53311310 64.54061556 64.54811805 64.55562055 64.56312306 64.57062559 64.57812814 64.58563070 64.59313328 64.60063588 64.60813848 64.61564111 64.62314374 64.63064639 64.63814906 64.64565174 64.65315443 64.66065713 64.66815985 64.67566257 64.68316531 64.69066807 64.69817083 64.70567361 64.71317639 64.72067919 64.72818200 64.73568481 64.74318764 64.75069048 64.75819333 64.76569618 64.77319905 64.78070192 64.78820481 64.79570770 64.80321060 64.81071350 64.81821642 64.82571934 64.83322227 64.84072520 64.84822814 64.85573109 64.86323405 64.87073700 64.87823997 64.88574294 64.89324591 64.90074889 64.90825188 64.91575486 64.92325786 64.93076085 64.93826385 64.94576685 64.95326986 64.96077286 64.96827587 64.97577888 64.98328190 64.99078491 64.99828793 65.00579095 65.01329396 65.02079698 65.02830000 65.03580302 65.04330604 65.05080905 65.05831207 65.06581509 65.07331810 65.08082112 65.08832413 65.09582714 65.10333014 65.11083315 65.11833615 65.12583915 65.13334214 65.14084514 65.14834812 65.15585111 65.16335409 65.17085706 65.17836003 65.18586300 65.19336595 65.20086891 65.20837186 65.21587480 65.22337773 65.23088066 65.23838358 65.24588650 65.25338940 65.26089230 65.26839519 65.27589808 65.28340095 65.29090382 65.29840667 65.30590952 65.31341236 65.32091519 65.32841800 65.33592081 65.34342361 65.35092639 65.35842917 65.36593193 65.37343469 65.38093743 65.38844015 65.39594287 65.40344557 65.41094826 65.41845094 65.42595361 65.43345626 65.44095889 65.44846152 65.45596412 65.46346672 65.47096930 65.47847186 65.48597441 65.49347694 65.50097945 65.50848195 65.51598444 65.52348690 65.53098935 65.53849179 65.54599420 65.55349660 65.56099898 65.56850134 65.57600368 65.58350601 65.59100831 65.59851060 65.60601286 65.61351511 65.62101733 65.62851954 65.63602172 65.64352389 65.65102603 65.65852815 65.66603025 65.67353233 65.68103439 65.68853642 65.69603843 65.70354042 65.71104239 65.71854433 65.72604624 65.73354814 65.74105001 65.74855185 65.75605367 65.76355547 65.77105724 65.77855899 65.78606071 65.79356240 65.80106407 65.80856571 65.81606732 65.82356891 65.83107047 65.83857200 65.84607350 65.85357498 65.86107643 65.86857785 65.87607924 65.88358060 65.89108193 65.89858323 65.90608451 65.91358575 65.92108696 65.92858814 65.93608930 65.94359041 65.95109150 65.95859256 65.96609358 65.97359458 65.98109554</listPositions>
				</positions>
				<positions axis="Omega" unit="deg">
					<commonPosition>31.2796</commonPosition>
				</positions>
				<positions axis="Phi" unit="deg">
					<commonPosition>-1.64</commonPosition>
				</positions>
				<positions axis="Psi" unit="deg">
					<commonPosition>0.12</commonPosition>
				</positions>
				<positions axis="X" unit="mm">
					<commonPosition>0.00</commonPosition>
				</positions>
				<positions axis="Y" unit="mm">
					<commonPosition>0.00</commonPosition>
				</positions>
				<positions axis="Z" unit="mm">
					<commonPosition>17.671</commonPosition>
				</positions>
				<commonCountingTime unit="seconds">2.00</commonCountingTime>
				<intensities unit="counts">0 0 0 0 0 0 2 3 0 1 1 2 3 0 1 1 0 1 1 0 0 3 1 0 0 0 1 0 2 0 0 2 0 3 1 1 0 0 1 1 1 0 0 0 1 2 1 1 2 1 0 1 0 0 3 0 0 0 1 0 3 1 0 0 1 0 1 0 0 2 0 1 0 0 1 0 2 1 0 0 1 0 0 0 0 0 1 2 1 0 2 2 1 3 2 1 0 1 1 2 1 1 2 2 0 3 3 1 1 1 0 0 0 3 0 1 0 1 0 1 0 0 0 0 0 0 1 0 0 0 0 0 2 0 0 0 0 1 2 0 1 0 0 0 0 4 1 3 0 0 1 0 1 0 0 1 1 3 3 1 0 0 0 1 2 1 2 1 0 0 1 2 1 1 0 0 0 0 0 0 1 0 1 0 1 2 3 3 0 1 1 0 0 0 4 1 1 2 1 0 1 0 0 0 2 2 1 1 0 2 0 0 0 2 2 1 1 0 1 3 0 1 1 1 0 0 1 0 1 0 0 0 1 1 3 0 0 0 1 1 1 0 0 0 0 1 1 0 1 1 3 2 2 2 0</intensities>
			</dataPoints>
		</scan>
		<scan appendNumber="0" mode="Continuous" scanAxis="2Theta" status="Completed">
			<header>
				<startTimeStamp>2012-06-15T22:33:37+02:00</startTimeStamp>
				<endTimeStamp>2012-06-15T22:33:40+02:00</endTimeStamp>
				<author>
					<name>Johannes Kepler Univ</name>
				</author>
				<source>
					<applicationSoftware version="2.2i">X'Pert Data Collector</applicationSoftware>
					<instrumentControlSoftware version="2.1E">XPERT-PRO</instrumentControlSoftware>
					<instrumentID>0000000011071750</instrumentID>
				</source>
			</header>
			<scanAxisCenter>
				<position axis="2Theta" unit="deg">65.0283</position>
			</scanAxisCenter>
			<dataPoints>
				<positions axis="2Theta" unit="deg">
					<listPositions>64.07550446 64.08300542 64.09050642 64.09800744 64.10550850 64.11300959 64.12051070 64.12801186 64.13551304 64.14301425 64.15051549 64.15801677 64.16551807 64.17301940 64.18052076 64.18802215 64.19552357 64.20302502 64.21052650 64.21802800 64.22552953 64.23303109 64.24053268 64.24803429 64.25553593 64.26303760 64.27053929 64.27804101 64.28554276 64.29304453 64.30054633 64.30804815 64.31554999 64.32305186 64.33055376 64.33805567 64.34555761 64.35305958 64.36056157 64.36806358 64.37556561 64.38306767 64.39056975 64.39807185 64.40557397 64.41307611 64.42057828 64.42808046 64.43558267 64.44308489 64.45058714 64.45808940 64.46559169 64.47309399 64.48059632 64.48809866 64.49560102 64.50310340 64.51060580 64.51810821 64.52561065 64.53311310 64.54061556 64.54811805 64.55562055 64.56312306 64.57062559 64.57812814 64.58563070 64.59313328 64.60063588 64.60813848 64.61564111 64.62314374 64.63064639 64.63814906 64.64565174 64.65315443 64.66065713 64.66815985 64.67566257 64.68316531 64.69066807 64.69817083 64.70567361 64.71317639 64.72067919 64.72818200 64.73568481 64.74318764 64.75069048 64.75819333 64.76569618 64.77319905 64.78070192 64.78820481 64.79570770 64.80321060 64.81071350 64.81821642 64.82571934 64.83322227 64.84072520 64.84822814 64.85573109 64.86323405 64.87073700 64.87823997 64.88574294 64.89324591 64.90074889 64.90825188 64.91575486 64.92325786 64.93076085 64.93826385 64.94576685 64.95326986 64.96077286 64.96827587 64.97577888 64.98328190 64.99078491 64.99828793 65.00579095 65.01329396 65.02079698 65.02830000 65.03580302 65.04330604 65.05080905 65.05831207 65.06581509 65.07331810 65.08082112 65.08832413 65.09582714 65.10333014 65.11083315 65.11833615 65.12583915 65.13334214 65.14084514 65.14834812 65.15585111 65.16335409 65.17085706 65.17836003 65.18586300 65.19336595 65.20086891 65.20837186 65.21587480 65.22337773 65.23088066 65.23838358 65.24588650 65.25338940 65.26089230 65.26839519 65.27589808 65.28340095 65.29090382 65.29840667 65.30590952 65.31341236 65.32091519 65.32841800 65.33592081 65.34342361 65.35092639 65.35842917 65.36593193 65.37343469 65.38093743 65.38844015 65.39594287 65.40344557 65.41094826 65.41845094 65.42595361 65.43345626 65.44095889 65.44846152 65.45596412 65.46346672 65.47096930 65.47847186 65.48597441 65.49347694 65.50097945 65.50848195 65.51598444 65.52348690 65.53098935 65.53849179 65.54599420 65.55349660 65.56099898 65.56850134 65.57600368 65.58350601 65.59100831 65.59851060 65.60601286 65.61351511 65.62101733 65.62851954 65.63602172 65.64352389 65.65102603 65.65852815 65.66603025 65.67353233 65.68103439 65.68853642 65.69603843 65.70354042 65.71104239 65.71854433 65.72604624 65.73354814 65.74105001 65.74855185 65.75605367 65.76355547 65.77105724 65.77855899 65.78606071 65.79356240 65.80106407 65.80856571 65.81606732 65.82356891 65.83107047 65.83857200 65.84607350 65.85357498 65.86107643 65.86857785 65.87607924 65.88358060 65.89108193 65.89858323 65.90608451 65.91358575 65.92108696 65.92858814 65.93608930 65.94359041 65.95109150 65.95859256 65.96609358 65.97359458 65.98109554</listPositions>
				</positions>
				<positions axis="Omega" unit="deg">
					<commonPosition>31.2846</commonPosition>
				</positions>
				<positions axis="Phi" unit="deg">
					<commonPosition>-1.64</commonPosition>
				</positions>
				<positions axis="Psi" unit="deg">
					<commonPosition>0.12</commonPosition>
				</positions>
				<positions axis="X" unit="mm">
					<commonPosition>0.00</commonPosition>
				</positions>
				<positions axis="Y" unit="mm">
					<commonPosition>0.00</commonPosition>
				</positions>
				<positions axis="Z" unit="mm">
					<commonPosition>17.671</commonPosition>
				</positions>
				<commonCountingTime unit="seconds">2.00</commonCountingTime>
				<intensities unit="counts">1 0 0 0 2 0 2 0 0 1 1 0 0 1 0 1 1 0 0 2 2 0 0 0 0 0 1 1 0 1 2 2 1 1 1 1 1 0 1 0 2 0 2 1 0 0 1 0 1 1 2 3 1 0 2 1 0 3 1 3 0 1 1 1 1 1 0 0 4 3 1 1 0 0 0 1 0 0 0 0 3 0 2 1 0 1 2 1 1 0 2 1 1 0 1 0 1 2 1 1 1 1 1 1 0 0 3 1 0 1 1 0 1 1 0 1 1 3 5 1 2 0 0 1 3 2 2 0 0 0 2 1 0 0 1 1 1 2 0 0 1 0 0 3 0 1 0 0 0 1 0 0 1 0 0 2 1 1 0 2 4 1 1 0 0 2 0 0 0 0 1 0 0 0 1 0 1 1 0 0 1 2 1 2 0 1 1 0 1 0 0 0 1 2 1 0 0 2 1 0 0 1 0 1 2 2 1 0 0 2 2 1 0 0 0 1 0 0 1 1 0 1 0 1 2 1 1 2 0 1 4 0 0 1 1 0 0 1 1 0 1 1 2 1 0 2 1 3 0 1 1 1 1 1 1</intensities>
			</dataPoints>
		</scan>
		<scan appendNumber="0" mode="Continuous" scanAxis="2Theta" status="Completed">
			<header>
				<startTimeStamp>2012-06-15T22:33:44+02:00</startTimeStamp>
				<endTimeStamp>2012-06-15T22:33:48+02:00</endTimeStamp>
				<author>
					<name>Johannes Kepler Univ</name>
				</author>
				<source>
					<applicationSoftware version="2.2i">X'Pert Data Collector</applicationSoftware>
					<instrumentControlSoftware version="2.1E">XPERT-PRO</instrumentControlSoftware>
					<instrumentID>0000000011071750</instrumentID>
				</source>
			</header>
			<scanAxisCenter>
				<position axis="2Theta" unit="deg">65.0283</position>
			</scanAxisCenter>
			<dataPoints>
				<positions axis="2Theta" unit="deg">
[...]
					<name>Johannes Kepler Univ</name>
				</author>
				<source>
					<applicationSoftware version="2.2i">X'Pert Data Collector</applicationSoftware>
					<instrumentControlSoftware version="2.1E">XPERT-PRO</instrumentControlSoftware>
					<instrumentID>0000000011071750</instrumentID>
				</source>
			</header>
			<scanAxisCenter>
				<position axis="2Theta" unit="deg">65.0283</position>
			</scanAxisCenter>
			<dataPoints>
				<positions axis="2Theta" unit="deg">
					<listPositions>64.07550446 64.08300542 64.09050642 64.09800744 64.10550850 64.11300959 64.12051070 64.12801186 64.13551304 64.14301425 64.15051549 64.15801677 64.16551807 64.17301940 64.18052076 64.18802215 64.19552357 64.20302502 64.21052650 64.21802800 64.22552953 64.23303109 64.24053268 64.24803429 64.25553593 64.26303760 64.27053929 64.27804101 64.28554276 64.29304453 64.30054633 64.30804815 64.31554999 64.32305186 64.33055376 64.33805567 64.34555761 64.35305958 64.36056157 64.36806358 64.37556561 64.38306767 64.39056975 64.39807185 64.40557397 64.41307611 64.42057828 64.42808046 64.43558267 64.44308489 64.45058714 64.45808940 64.46559169 64.47309399 64.48059632 64.48809866 64.49560102 64.50310340 64.51060580 64.51810821 64.52561065 64.53311310 64.54061556 64.54811805 64.55562055 64.56312306 64.57062559 64.57812814 64.58563070 64.59313328 64.60063588 64.60813848 64.61564111 64.62314374 64.63064639 64.63814906 64.64565174 64.65315443 64.66065713 64.66815985 64.67566257 64.68316531 64.69066807 64.69817083 64.70567361 64.71317639 64.72067919 64.72818200 64.73568481 64.74318764 64.75069048 64.75819333 64.76569618 64.77319905 64.78070192 64.78820481 64.79570770 64.80321060 64.81071350 64.81821642 64.82571934 64.83322227 64.84072520 64.84822814 64.85573109 64.86323405 64.87073700 64.87823997 64.88574294 64.89324591 64.90074889 64.90825188 64.91575486 64.92325786 64.93076085 64.93826385 64.94576685 64.95326986 64.96077286 64.96827587 64.97577888 64.98328190 64.99078491 64.99828793 65.00579095 65.01329396 65.02079698 65.02830000 65.03580302 65.04330604 65.05080905 65.05831207 65.06581509 65.07331810 65.08082112 65.08832413 65.09582714 65.10333014 65.11083315 65.11833615 65.12583915 65.13334214 65.14084514 65.14834812 65.15585111 65.16335409 65.17085706 65.17836003 65.18586300 65.19336595 65.20086891 65.20837186 65.21587480 65.22337773 65.23088066 65.23838358 65.24588650 65.25338940 65.26089230 65.26839519 65.27589808 65.28340095 65.29090382 65.29840667 65.30590952 65.31341236 65.32091519 65.32841800 65.33592081 65.34342361 65.35092639 65.35842917 65.36593193 65.37343469 65.38093743 65.38844015 65.39594287 65.40344557 65.41094826 65.41845094 65.42595361 65.43345626 65.44095889 65.44846152 65.45596412 65.46346672 65.47096930 65.47847186 65.48597441 65.49347694 65.50097945 65.50848195 65.51598444 65.52348690 65.53098935 65.53849179 65.54599420 65.55349660 65.56099898 65.56850134 65.57600368 65.58350601 65.59100831 65.59851060 65.60601286 65.61351511 65.62101733 65.62851954 65.63602172 65.64352389 65.65102603 65.65852815 65.66603025 65.67353233 65.68103439 65.68853642 65.69603843 65.70354042 65.71104239 65.71854433 65.72604624 65.73354814 65.74105001 65.74855185 65.75605367 65.76355547 65.77105724 65.77855899 65.78606071 65.79356240 65.80106407 65.80856571 65.81606732 65.82356891 65.83107047 65.83857200 65.84607350 65.85357498 65.86107643 65.86857785 65.87607924 65.88358060 65.89108193 65.89858323 65.90608451 65.91358575 65.92108696 65.92858814 65.93608930 65.94359041 65.95109150 65.95859256 65.96609358 65.97359458 65.98109554</listPositions>
				</positions>
				<positions axis="Omega" unit="deg">
					<commonPosition>33.2396</commonPosition>
				</positions>
				<positions axis="Phi" unit="deg">
					<commonPosition>-1.64</commonPosition>
				</positions>
				<positions axis="Psi" unit="deg">
					<commonPosition>0.12</commonPosition>
				</positions>
				<positions axis="X" unit="mm">
					<commonPosition>0.00</commonPosition>
				</positions>
				<positions axis="Y" unit="mm">
					<commonPosition>0.00</commonPosition>
				</positions>
				<positions axis="Z" unit="mm">
					<commonPosition>17.671</commonPosition>
				</positions>
				<commonCountingTime unit="seconds">2.00</commonCountingTime>
				<intensities unit="counts">2 0 0 2 1 1 1 2 0 1 1 2 2 2 1 1 1 2 1 0 1 0 0 1 3 0 1 2 0 1 1 1 1 2 2 1 1 1 1 0 2 1 1 0 3 1 0 2 3 0 0 3 2 2 0 0 1 0 3 0 1 0 1 1 0 0 0 0 0 1 0 0 0 0 1 0 1 1 0 1 0 1 1 1 1 2 1 1 3 1 1 0 2 0 0 0 0 2 0 1 2 1 1 0 1 2 0 0 0 0 1 1 2 0 0 1 1 3 2 1 2 0 2 1 1 0 0 2 0 0 0 0 0 0 0 0 0 2 2 0 0 1 2 4 0 1 0 2 1 1 0 0 2 0 0 2 2 1 0 1 0 0 2 2 1 0 0 1 2 0 2 1 0 0 0 1 2 0 0 2 0 0 3 0 0 1 0 0 1 1 1 4 0 1 1 0 0 0 0 0 1 0 0 2 0 1 1 0 1 1 1 2 1 1 1 0 0 0 1 1 1 2 0 1 1 0 0 0 1 2 0 2 0 2 1 0 1 1 1 1 0 1 0 2 0 1 1 0 0 0 1 2 0 0 1</intensities>
			</dataPoints>
		</scan>
		<scan appendNumber="0" mode="Continuous" scanAxis="2Theta" status="Completed">
			<header>
				<startTimeStamp>2012-06-15T23:29:20+02:00</startTimeStamp>
				<endTimeStamp>2012-06-15T23:29:23+02:00</endTimeStamp>
				<author>
					<name>Johannes Kepler Univ</name>
				</author>
				<source>
					<applicationSoftware version="2.2i">X'Pert Data Collector</applicationSoftware>
					<instrumentControlSoftware version="2.1E">XPERT-PRO</instrumentControlSoftware>
					<instrumentID>0000000011071750</instrumentID>
				</source>
			</header>
			<scanAxisCenter>
				<position axis="2Theta" unit="deg">65.0283</position>
			</scanAxisCenter>
			<dataPoints>
				<positions axis="2Theta" unit="deg">
					<listPositions>64.07550446 64.08300542 64.09050642 64.09800744 64.10550850 64.11300959 64.12051070 64.12801186 64.13551304 64.14301425 64.15051549 64.15801677 64.16551807 64.17301940 64.18052076 64.18802215 64.19552357 64.20302502 64.21052650 64.21802800 64.22552953 64.23303109 64.24053268 64.24803429 64.25553593 64.26303760 64.27053929 64.27804101 64.28554276 64.29304453 64.30054633 64.30804815 64.31554999 64.32305186 64.33055376 64.33805567 64.34555761 64.35305958 64.36056157 64.36806358 64.37556561 64.38306767 64.39056975 64.39807185 64.40557397 64.41307611 64.42057828 64.42808046 64.43558267 64.44308489 64.45058714 64.45808940 64.46559169 64.47309399 64.48059632 64.48809866 64.49560102 64.50310340 64.51060580 64.51810821 64.52561065 64.53311310 64.54061556 64.54811805 64.55562055 64.56312306 64.57062559 64.57812814 64.58563070 64.59313328 64.60063588 64.60813848 64.61564111 64.62314374 64.63064639 64.63814906 64.64565174 64.65315443 64.66065713 64.66815985 64.67566257 64.68316531 64.69066807 64.69817083 64.70567361 64.71317639 64.72067919 64.72818200 64.73568481 64.74318764 64.75069048 64.75819333 64.76569618 64.77319905 64.78070192 64.78820481 64.79570770 64.80321060 64.81071350 64.81821642 64.82571934 64.83322227 64.84072520 64.84822814 64.85573109 64.86323405 64.87073700 64.87823997 64.88574294 64.89324591 64.90074889 64.90825188 64.91575486 64.92325786 64.93076085 64.93826385 64.94576685 64.95326986 64.96077286 64.96827587 64.97577888 64.98328190 64.99078491 64.99828793 65.00579095 65.01329396 65.02079698 65.02830000 65.03580302 65.04330604 65.05080905 65.05831207 65.06581509 65.07331810 65.08082112 65.08832413 65.09582714 65.10333014 65.11083315 65.11833615 65.12583915 65.13334214 65.14084514 65.14834812 65.15585111 65.16335409 65.17085706 65.17836003 65.18586300 65.19336595 65.20086891 65.20837186 65.21587480 65.22337773 65.23088066 65.23838358 65.24588650 65.25338940 65.26089230 65.26839519 65.27589808 65.28340095 65.29090382 65.29840667 65.30590952 65.31341236 65.32091519 65.32841800 65.33592081 65.34342361 65.35092639 65.35842917 65.36593193 65.37343469 65.38093743 65.38844015 65.39594287 65.40344557 65.41094826 65.41845094 65.42595361 65.43345626 65.44095889 65.44846152 65.45596412 65.46346672 65.47096930 65.47847186 65.48597441 65.49347694 65.50097945 65.50848195 65.51598444 65.52348690 65.53098935 65.53849179 65.54599420 65.55349660 65.56099898 65.56850134 65.57600368 65.58350601 65.59100831 65.59851060 65.60601286 65.61351511 65.62101733 65.62851954 65.63602172 65.64352389 65.65102603 65.65852815 65.66603025 65.67353233 65.68103439 65.68853642 65.69603843 65.70354042 65.71104239 65.71854433 65.72604624 65.73354814 65.74105001 65.74855185 65.75605367 65.76355547 65.77105724 65.77855899 65.78606071 65.79356240 65.80106407 65.80856571 65.81606732 65.82356891 65.83107047 65.83857200 65.84607350 65.85357498 65.86107643 65.86857785 65.87607924 65.88358060 65.89108193 65.89858323 65.90608451 65.91358575 65.92108696 65.92858814 65.93608930 65.94359041 65.95109150 65.95859256 65.96609358 65.97359458 65.98109554</listPositions>
				</positions>
				<positions axis="Omega" unit="deg">
					<commonPosition>33.2446</commonPosition>
				</positions>
				<positions axis="Phi" unit="deg">
					<commonPosition>-1.64</commonPosition>
				</positions>
				<positions axis="Psi" unit="deg">
					<commonPosition>0.12</commonPosition>
				</positions>
				<positions axis="X" unit="mm">
					<commonPosition>0.00</commonPosition>
				</positions>
				<positions axis="Y" unit="mm">
					<commonPosition>0.00</commonPosition>
				</positions>
				<positions axis="Z" unit="mm">
					<commonPosition>17.671</commonPosition>
				</positions>
				<commonCountingTime unit="seconds">2.00</commonCountingTime>
				<intensities unit="counts">0 0 0 1 1 1 2 1 1 1 0 0 0 1 0 1 0 1 0 2 0 0 0 1 0 0 0 0 1 1 2 2 3 0 2 0 2 0 3 0 0 0 0 1 1 0 0 0 0 1 0 0 2 0 1 0 0 0 1 3 0 0 0 1 1 0 1 0 0 0 0 1 0 2 0 1 2 0 2 0 0 0 2 2 1 1 1 1 4 1 0 0 0 1 0 0 0 0 0 1 1 0 0 1 1 0 0 0 0 0 1 0 0 1 0 0 0 2 1 1 1 0 1 1 1 0 0 1 1 1 0 1 1 0 2 1 1 0 0 0 0 0 1 0 0 0 1 0 1 2 2 2 1 1 0 0 1 1 0 0 0 1 0 1 1 0 0 1 2 0 1 1 0 0 3 2 0 0 1 1 2 3 0 0 0 0 2 1 1 0 1 0 1 0 0 1 1 3 0 1 1 0 0 0 0 1 0 1 0 0 0 1 0 0 0 1 0 2 1 0 1 0 0 0 0 2 2 3 0 0 0 1 0 1 0 0 1 2 1 0 2 1 1 0 1 2 0 2 0 1 1 0 2 3 1</intensities>
			</dataPoints>
		</scan>
		<scan appendNumber="0" mode="Continuous" scanAxis="2Theta" status="Completed">
			<header>
				<startTimeStamp>2012-06-15T23:29:29+02:00</startTimeStamp>
				<endTimeStamp>2012-06-15T23:29:33+02:00</endTimeStamp>
				<author>
					<name>Johannes Kepler Univ</name>
				</author>
				<source>
					<applicationSoftware version="2.2i">X'Pert Data Collector</applicationSoftware>
					<instrumentControlSoftware version="2.1E">XPERT-PRO</instrumentControlSoftware>
					<instrumentID>0000000011071750</instrumentID>
				</source>
			</header>
			<scanAxisCenter>
				<position axis="2Theta" unit="deg">65.0283</position>
			</scanAxisCenter>
			<dataPoints>
				<positions axis="2Theta" unit="deg">
					<listPositions>64.07550446 64.08300542 64.09050642 64.09800744 64.10550850 64.11300959 64.12051070 64.12801186 64.13551304 64.14301425 64.15051549 64.15801677 64.16551807 64.17301940 64.18052076 64.18802215 64.19552357 64.20302502 64.21052650 64.21802800 64.22552953 64.23303109 64.24053268 64.24803429 64.25553593 64.26303760 64.27053929 64.27804101 64.28554276 64.29304453 64.30054633 64.30804815 64.31554999 64.32305186 64.33055376 64.33805567 64.34555761 64.35305958 64.36056157 64.36806358 64.37556561 64.38306767 64.39056975 64.39807185 64.40557397 64.41307611 64.42057828 64.42808046 64.43558267 64.44308489 64.45058714 64.45808940 64.46559169 64.47309399 64.48059632 64.48809866 64.49560102 64.50310340 64.51060580 64.51810821 64.52561065 64.53311310 64.54061556 64.54811805 64.55562055 64.56312306 64.57062559 64.57812814 64.58563070 64.59313328 64.60063588 64.60813848 64.61564111 64.62314374 64.63064639 64.63814906 64.64565174 64.65315443 64.66065713 64.66815985 64.67566257 64.68316531 64.69066807 64.69817083 64.70567361 64.71317639 64.72067919 64.72818200 64.73568481 64.74318764 64.75069048 64.75819333 64.76569618 64.77319905 64.78070192 64.78820481 64.79570770 64.80321060 64.81071350 64.81821642 64.82571934 64.83322227 64.84072520 64.84822814 64.85573109 64.86323405 64.87073700 64.87823997 64.88574294 64.89324591 64.90074889 64.90825188 64.91575486 64.92325786 64.93076085 64.93826385 64.94576685 64.95326986 64.96077286 64.96827587 64.97577888 64.98328190 64.99078491 64.99828793 65.00579095 65.01329396 65.02079698 65.02830000 65.03580302 65.04330604 65.05080905 65.05831207 65.06581509 65.07331810 65.08082112 65.08832413 65.09582714 65.10333014 65.11083315 65.11833615 65.12583915 65.13334214 65.14084514 65.14834812 65.15585111 65.16335409 65.17085706 65.17836003 65.18586300 65.19336595 65.20086891 65.20837186 65.21587480 65.22337773 65.23088066 65.23838358 65.24588650 65.25338940 65.26089230 65.26839519 65.27589808 65.28340095 65.29090382 65.29840667 65.30590952 65.31341236 65.32091519 65.32841800 65.33592081 65.34342361 65.35092639 65.35842917 65.36593193 65.37343469 65.38093743 65.38844015 65.39594287 65.40344557 65.41094826 65.41845094 65.42595361 65.43345626 65.44095889 65.44846152 65.45596412 65.46346672 65.47096930 65.47847186 65.48597441 65.49347694 65.50097945 65.50848195 65.51598444 65.52348690 65.53098935 65.53849179 65.54599420 65.55349660 65.56099898 65.56850134 65.57600368 65.58350601 65.59100831 65.59851060 65.60601286 65.61351511 65.62101733 65.62851954 65.63602172 65.64352389 65.65102603 65.65852815 65.66603025 65.67353233 65.68103439 65.68853642 65.69603843 65.70354042 65.71104239 65.71854433 65.72604624 65.73354814 65.74105001 65.74855185 65.75605367 65.76355547 65.77105724 65.77855899 65.78606071 65.79356240 65.80106407 65.80856571 65.81606732 65.82356891 65.83107047 65.83857200 65.84607350 65.85357498 65.86107643 65.86857785 65.87607924 65.88358060 65.89108193 65.89858323 65.90608451 65.91358575 65.92108696 65.92858814 65.93608930 65.94359041 65.95109150 65.95859256 65.96609358 65.97359458 65.98109554</listPositions>
				</positions>
				<positions axis="Omega" unit="deg">
					<commonPosition>33.2496</commonPosition>
				</positions>
				<positions axis="Phi" unit="deg">
					<commonPosition>-1.64</commonPosition>
				</positions>
				<positions axis="Psi" unit="deg">
					<commonPosition>0.12</commonPosition>
				</positions>
				<positions axis="X" unit="mm">
					<commonPosition>0.00</commonPosition>
				</positions>
				<positions axis="Y" unit="mm">
					<commonPosition>0.00</commonPosition>
				</positions>
				<positions axis="Z" unit="mm">
					<commonPosition>17.671</commonPosition>
				</positions>
				<commonCountingTime unit="seconds">2.00</commonCountingTime>
				<intensities unit="counts">2 0 1 2 1 0 0 1 1 1 0 0 1 0 1 0 1 0 1 3 0 1 2 3 0 2 1 1 1 1 3 1 0 0 1 0 1 2 3 0 0 1 0 0 1 2 1 0 2 1 1 1 0 2 2 0 0 0 0 0 0 0 1 1 0 1 1 0 0 1 0 0 0 0 1 1 0 1 1 0 2 1 0 2 0 0 1 1 0 1 0 0 1 3 1 2 2 1 0 0 2 1 1 0 1 1 0 0 0 0 0 1 0 0 0 0 2 2 2 1 3 0 0 1 1 2 1 2 2 1 1 3 0 1 1 1 2 3 0 0 4 0 1 1 0 1 1 0 0 1 1 0 0 1 3 0 2 0 1 1 2 0 1 0 1 1 2 1 1 2 2 0 1 2 2 0 0 0 1 2 1 0 0 1 0 1 0 2 1 2 0 1 1 0 1 2 0 2 2 2 0 0 0 4 1 0 0 4 2 0 1 0 1 0 1 2 3 1 1 0 0 0 0 1 0 1 1 1 0 0 1 2 0 0 3 0 2 0 0 1 0 0 0 1 0 2 2 1 0 0 3 0 1 0 0</intensities>
			</dataPoints>
		</scan>
		<scan appendNumber="0" mode="Continuous" scanAxis="2Theta" status="Completed">
			<header>
				<startTimeStamp>2012-06-15T23:29:39+02:00</startTimeStamp>
				<endTimeStamp>2012-06-15T23:29:42+02:00</endTimeStamp>
				<author>
					<name>Johannes Kepler Univ</name>
				</author>
				<source>
					<applicationSoftware version="2.2i">X'Pert Data Collector</applicationSoftware>
					<instrumentControlSoftware version="2.1E">XPERT-PRO</instrumentControlSoftware>
					<instrumentID>0000000011071750</instrumentID>
				</source>
			</header>
			<scanAxisCenter>
				<position axis="2Theta" unit="deg">65.0283</position>
			</scanAxisCenter>
			<dataPoints>
				<positions axis="2Theta" unit="deg">
					<listPositions>64.07550446 64.08300542 64.09050642 64.09800744 64.10550850 64.11300959 64.12051070 64.12801186 64.13551304 64.14301425 64.15051549 64.15801677 64.16551807 64.17301940 64.18052076 64.18802215 64.19552357 64.20302502 64.21052650 64.21802800 64.22552953 64.23303109 64.24053268 64.24803429 64.25553593 64.26303760 64.27053929 64.27804101 64.28554276 64.29304453 64.30054633 64.30804815 64.31554999 64.32305186 64.33055376 64.33805567 64.34555761 64.35305958 64.36056157 64.36806358 64.37556561 64.38306767 64.39056975 64.39807185 64.40557397 64.41307611 64.42057828 64.42808046 64.43558267 64.44308489 64.45058714 64.45808940 64.46559169 64.47309399 64.48059632 64.48809866 64.49560102 64.50310340 64.51060580 64.51810821 64.52561065 64.53311310 64.54061556 64.54811805 64.55562055 64.56312306 64.57062559 64.57812814 64.58563070 64.59313328 64.60063588 64.60813848 64.61564111 64.62314374 64.63064639 64.63814906 64.64565174 64.65315443 64.66065713 64.66815985 64.67566257 64.68316531 64.69066807 64.69817083 64.70567361 64.71317639 64.72067919 64.72818200 64.73568481 64.74318764 64.75069048 64.75819333 64.76569618 64.77319905 64.78070192 64.78820481 64.79570770 64.80321060 64.81071350 64.81821642 64.82571934 64.83322227 64.84072520 64.84822814 64.85573109 64.86323405 64.87073700 64.87823997 64.88574294 64.89324591 64.90074889 64.90825188 64.91575486 64.92325786 64.93076085 64.93826385 64.94576685 64.95326986 64.96077286 64.96827587 64.97577888 64.98328190 64.99078491 64.99828793 65.00579095 65.01329396 65.02079698 65.02830000 65.03580302 65.04330604 65.05080905 65.05831207 65.06581509 65.07331810 65.08082112 65.08832413 65.09582714 65.10333014 65.11083315 65.11833615 65.12583915 65.13334214 65.14084514 65.14834812 65.15585111 65.16335409 65.17085706 65.17836003 65.18586300 65.19336595 65.20086891 65.20837186 65.21587480 65.22337773 65.23088066 65.23838358 65.24588650 65.25338940 65.26089230 65.26839519 65.27589808 65.28340095 65.29090382 65.29840667 65.30590952 65.31341236 65.32091519 65.32841800 65.33592081 65.34342361 65.35092639 65.35842917 65.36593193 65.37343469 65.38093743 65.38844015 65.39594287 65.40344557 65.41094826 65.41845094 65.42595361 65.43345626 65.44095889 65.44846152 65.45596412 65.46346672 65.47096930 65.47847186 65.48597441 65.49347694 65.50097945 65.50848195 65.51598444 65.52348690 65.53098935 65.53849179 65.54599420 65.55349660 65.56099898 65.56850134 65.57600368 65.58350601 65.59100831 65.59851060 65.60601286 65.61351511 65.62101733 65.62851954 65.63602172 65.64352389 65.65102603 65.65852815 65.66603025 65.67353233 65.68103439 65.68853642 65.69603843 65.70354042 65.71104239 65.71854433 65.72604624 65.73354814 65.74105001 65.74855185 65.75605367 65.76355547 65.77105724 65.77855899 65.78606071 65.79356240 65.80106407 65.80856571 65.81606732 65.82356891 65.83107047 65.83857200 65.84607350 65.85357498 65.86107643 65.86857785 65.87607924 65.88358060 65.89108193 65.89858323 65.90608451 65.91358575 65.92108696 65.92858814 65.93608930 65.94359041 65.95109150 65.95859256 65.96609358 65.97359458 65.98109554</listPositions>
				</positions>
				<positions axis="Omega" unit="deg">
					<commonPosition>33.2546</commonPosition>
				</positions>
				<positions axis="Phi" unit="deg">
					<commonPosition>-1.64</commonPosition>
				</positions>
				<positions axis="Psi" unit="deg">
					<commonPosition>0.12</commonPosition>
				</positions>
				<positions axis="X" unit="mm">
					<commonPosition>0.00</commonPosition>
				</positions>
				<positions axis="Y" unit="mm">
					<commonPosition>0.00</commonPosition>
				</positions>
				<positions axis="Z" unit="mm">
					<commonPosition>17.671</commonPosition>
				</positions>
				<commonCountingTime unit="seconds">2.00</commonCountingTime>
				<intensities unit="counts">0 1 0 0 2 0 0 1 2 0 1 1 1 0 0 0 1 0 1 1 1 1 2 0 0 1 0 1 0 1 0 0 1 2 0 0 1 0 2 2 2 0 2 0 1 2 3 1 2 2 0 0 0 1 1 4 2 0 4 2 0 0 0 0 0 1 0 2 0 0 1 2 1 2 0 0 1 0 1 0 0 1 1 0 0 0 0 1 1 3 1 0 1 0 1 1 1 1 1 0 1 0 2 1 1 0 0 2 1 1 1 1 1 1 0 2 1 0 0 1 1 0 1 2 1 1 0 3 1 1 0 0 1 1 3 1 0 0 0 0 0 0 0 1 0 0 0 0 1 2 0 1 2 0 1 0 0 0 2 1 0 0 2 0 0 2 1 0 1 1 0 0 1 1 3 0 1 1 0 0 0 0 1 1 0 1 0 1 0 0 1 1 1 1 1 0 2 1 2 0 0 0 2 1 1 1 1 1 0 1 1 0 0 0 0 0 0 2 0 0 0 2 1 0 1 2 0 1 0 0 0 1 3 0 0 0 2 1 2 2 2 0 1 1 0 1 1 2 2 0 2 1 0 1 0</intensities>
			</dataPoints>
		</scan>
	</xrdMeasurement>
</xrdMeasurements>